Workbook

Sheet ECHANTILLONS
A1: Trypanosoma brucei gambiense inhibition ELISA (iELISA)
A3: Formulaire d'identification des échantillons
A6: Date de preparation
A7: Operateur
A8: Numéro du lot iELISA | C8: 3915223
A9: N de seriés d'échantillons
A10: Étude/origin
A14: N° échantillon dans la microplaque | B14: Numéro labo | C14: Code-barres KPS | D14: Commentaire (en cas de problème ou irregularité)
A15: S1 | B15: 177 | C15: 2501248
A16: S2 | B16: 178 | C16: 2501295
A17: S3 | B17: 179 | C17: 2501225
A18: S4 | B18: 180 | C18: 2501292
A19: S5 | B19: 181 | C19: 2501913
A20: S6 | B20: 182 | C20: 2501960
A21: S7 | B21: 183 | C21: 2501955
A22: S8 | B22: 184 | C22: 2501968
A23: S9 | B23: 185 | C23: 2501922
A24: S10 | B24: 186 | C24: 2501925
A25: S11 | B25: 187 | C25: 2402967
A26: S12 | B26: 188 | C26: 2501927
... A58: S44 | B58: 220 | C58: 2500093

Sheet 450-600 nm
A1: T.b. gambiense iELISA (apDIA)
A3: Résultats brutes
A5: Date | C5: =IF(ECHANTILLONS!C6="","",ECHANTILLONS!C6) | F5: Etude | G5: =IF(ECHANTILLONS!C10="","",ECHANTILLONS!C10) | H5: =IF(ECHANTILLONS!F6="","",ECHANTILLONS!F6)
A6: Opérateur | C6: =IF(ECHANTILLONS!C7="","",ECHANTILLONS!C7)
A7: N° du Lot | C7: =IF(ECHANTILLONS!C8="","",ECHANTILLONS!C8) -> 3915223
A8: N° de la plaque | C8: =IF(ECHANTILLONS!C9="","",ECHANTILLONS!C9)
A9: Filtre (nm) | C9: 450-600 nm
B12: 1 | C12: 2 | D12: 3 | E12: 4 | F12: 5 | G12: 6 | H12: 7 | I12: 8 | J12: 9 | K12: 10 | L12: 11 | M12: 12
A13: A | B13: 0.927 | C13: 0.796 | D13: 0.268 | E13: 0.264 | F13: 0.831 | G13: 0.817 | H13: 2.072 | I13: 2.133 | J13: 0.673 | K13: 0.72 | L13: 2.265 | M13: 2.475
A14: B | B14: 0.919 | C14: 0.67 | D14: 0.81 | E14: 0.705 | F14: 0.716 | G14: 0.622 | H14: 1.913 | I14: 1.782 | J14: 1.955 | K14: 2.164 | L14: 2.089 | M14: 2.323
A15: C | B15: 0.903 | C15: 0.756 | D15: 0.818 | E15: 0.696 | F15: 0.783 | G15: 0.745 | H15: 2.056 | I15: 1.952 | J15: 1.85 | K15: 2.061 | L15: 1.926 | M15: 2.275
A16: D | B16: 0.962 | C16: 0.804 | D16: 0.878 | E16: 0.799 | F16: 0.75 | G16: 0.731 | H16: 1.99 | I16: 1.92 | J16: 1.953 | K16: 2.131 | L16: 2.161 | M16: 2.338
A17: E | B17: 0.845 | C17: 0.765 | D17: 0.714 | E17: 0.86 | F17: 0.739 | G17: 0.721 | H17: 1.803 | I17: 1.891 | J17: 1.901 | K17: 1.999 | L17: 2.064 | M17: 2.292
A18: F | B18: 1.015 | C18: 0.895 | D18: 0.95 | E18: 0.896 | F18: 0.486 | G18: 0.931 | H18: 2.307 | I18: 2.066 | J18: 2.16 | K18: 2.346 | L18: 1.431 | M18: 2.539
A19: G | B19: 0.852 | C19: 0.994 | D19: 0.939 | E19: 0.985 | F19: 1.036 | G19: 1.068 | H19: 2.48 | I19: 2.322 | J19: 2.501 | K19: 2.678 | L19: 2.513 | M19: 2.838
A20: H | B20: 0.82 | C20: 0.894 | D20: 1.006 | E20: 0.89 | F20: 1.063 | G20: 1.044 | H20: 2.458 | I20: 2.618 | J20: 2.691 | K20: 2.301 | L20: 2.468 | M20: 2.668
B22: LiTat 1.3 | H22: LiTat 1.5
B23: Moyenne contrôle nég LiTat 1.3 | D23: Moyenne contrôle pos LiTat 1.3 | F23: PI CP LiTat 1.3 | H23: Moyenne contrôle nég LiTat 1.5 | J23: Moyenne contrôle pos LiTat 1.5 | L23: PI C pos LiTat 1.5
B24: =(B13+C13)/2 -> 0.8615 | D24: =(D13+E13)/2 -> 0.266 | F24: =100-(D24/B24*100) -> 69.123622 | H24: =(H13+I13)/2 -> 2.1025 | J24: =(J13+K13)/2 -> 0.6965 | L24: =100-(J24/H24*100) -> 66.872771
B26: 1 | C26: 2 | D26: 3 | E26: 4 | F26: 5 | G26: 6 | H26: 7 | I26: 8 | J26: 9 | K26: 10 | L26: 11 | M26: 12
A27: A | F27: =IF(F13="","",100-F13/$B$24*100) -> 3.5403366 | G27: =IF(G13="","",100-G13/$B$24*100) -> 5.1654092 | L27: =IF(L13="","",100-L13/$H$24*100) -> -7.7288942 | M27: =IF(M13="","",100-M13/$H$24*100) -> -17.717004
A28: B | B28: =IF(B14="","",100-B14/$B$24*100) -> -6.6744051 | C28: =IF(C14="","",100-C14/$B$24*100) -> 22.228671 | D28: =IF(D14="","",100-D14/$B$24*100) -> 5.9779454 | E28: =IF(E14="","",100-E14/$B$24*100) -> 18.16599 | F28: =IF(F14="","",100-F14/$B$24*100) -> 16.889147 | G28: =IF(G14="","",100-G14/$B$24*100) -> 27.800348 | H28: =IF(H14="","",100-H14/$H$24*100) -> 9.0130797 | I28: =IF(I14="","",100-I14/$H$24*100) -> 15.243757 | J28: =IF(J14="","",100-J14/$H$24*100) -> 7.0154578 | K28: =IF(K14="","",100-K14/$H$24*100) -> -2.9250892 | L28: =IF(L14="","",100-L14/$H$24*100) -> 0.64209275 | M28: =IF(M14="","",100-M14/$H$24*100) -> -10.487515
A29: C | B29: =IF(B15="","",100-B15/$B$24*100) -> -4.8171793 | C29: =IF(C15="","",100-C15/$B$24*100) -> 12.246082 | D29: =IF(D15="","",100-D15/$B$24*100) -> 5.0493326 | E29: =IF(E15="","",100-E15/$B$24*100) -> 19.210679 | F29: =IF(F15="","",100-F15/$B$24*100) -> 9.1120139 | G29: =IF(G15="","",100-G15/$B$24*100) -> 13.522925 | H29: =IF(H15="","",100-H15/$H$24*100) -> 2.2116528 | I29: =IF(I15="","",100-I15/$H$24*100) -> 7.1581451 | J29: =IF(J15="","",100-J15/$H$24*100) -> 12.009512 | K29: =IF(K15="","",100-K15/$H$24*100) -> 1.9738407 | L29: =IF(L15="","",100-L15/$H$24*100) -> 8.3947681 | M29: =IF(M15="","",100-M15/$H$24*100) -> -8.2045184
A30: D | B30: =IF(B16="","",100-B16/$B$24*100) -> -11.665699 | C30: =IF(C16="","",100-C16/$B$24*100) -> 6.6744051 | D30: =IF(D16="","",100-D16/$B$24*100) -> -1.9152641 | E30: =IF(E16="","",100-E16/$B$24*100) -> 7.2547882 | F30: =IF(F16="","",100-F16/$B$24*100) -> 12.942542 | G30: =IF(G16="","",100-G16/$B$24*100) -> 15.147998 | H30: =IF(H16="","",100-H16/$H$24*100) -> 5.3507729 | I30: =IF(I16="","",100-I16/$H$24*100) -> 8.6801427 | J30: =IF(J16="","",100-J16/$H$24*100) -> 7.1105826 | K30: =IF(K16="","",100-K16/$H$24*100) -> -1.3555291 | L30: =IF(L16="","",100-L16/$H$24*100) -> -2.7824019 | M30: =IF(M16="","",100-M16/$H$24*100) -> -11.200951
A31: E | B31: =IF(B17="","",100-B17/$B$24*100) -> 1.9152641 | C31: =IF(C17="","",100-C17/$B$24*100) -> 11.201393 | D31: =IF(D17="","",100-D17/$B$24*100) -> 17.1213 | E31: =IF(E17="","",100-E17/$B$24*100) -> 0.17411492 | F31: =IF(F17="","",100-F17/$B$24*100) -> 14.219385 | G31: =IF(G17="","",100-G17/$B$24*100) -> 16.308764 | H31: =IF(H17="","",100-H17/$H$24*100) -> 14.244946 | I31: =IF(I17="","",100-I17/$H$24*100) -> 10.059453 | J31: =IF(J17="","",100-J17/$H$24*100) -> 9.5838288 | K31: =IF(K17="","",100-K17/$H$24*100) -> 4.9227111 | L31: =IF(L17="","",100-L17/$H$24*100) -> 1.8311534 | M31: =IF(M17="","",100-M17/$H$24*100) -> -9.0130797
A32: F | B32: =IF(B18="","",100-B18/$B$24*100) -> -17.81776 | C32: =IF(C18="","",100-C18/$B$24*100) -> -3.8885665 | D32: =IF(D18="","",100-D18/$B$24*100) -> -10.27278 | E32: =IF(E18="","",100-E18/$B$24*100) -> -4.0046431 | F32: =IF(F18="","",100-F18/$B$24*100) -> 43.586767 | G32: =IF(G18="","",100-G18/$B$24*100) -> -8.0673244 | H32: =IF(H18="","",100-H18/$H$24*100) -> -9.7265161 | I32: =IF(I18="","",100-I18/$H$24*100) -> 1.7360285 | J32: =IF(J18="","",100-J18/$H$24*100) -> -2.7348395 | K32: =IF(K18="","",100-K18/$H$24*100) -> -11.581451 | L32: =IF(L18="","",100-L18/$H$24*100) -> 31.938169 | M32: =IF(M18="","",100-M18/$H$24*100) -> -20.760999
A33: G | B33: =IF(B19="","",100-B19/$B$24*100) -> 1.1027278 | C33: =IF(C19="","",100-C19/$B$24*100) -> -15.380151 | D33: =IF(D19="","",100-D19/$B$24*100) -> -8.9959373 | E33: =IF(E19="","",100-E19/$B$24*100) -> -14.335461 | F33: =IF(F19="","",100-F19/$B$24*100) -> -20.255369 | G33: =IF(G19="","",100-G19/$B$24*100) -> -23.96982 | H33: =IF(H19="","",100-H19/$H$24*100) -> -17.954816 | I33: =IF(I19="","",100-I19/$H$24*100) -> -10.439952 | J33: =IF(J19="","",100-J19/$H$24*100) -> -18.953627 | K33: =IF(K19="","",100-K19/$H$24*100) -> -27.372176 | L33: =IF(L19="","",100-L19/$H$24*100) -> -19.524376 | M33: =IF(M19="","",100-M19/$H$24*100) -> -34.982164
A34: H | B34: =IF(B20="","",100-B20/$B$24*100) -> 4.8171793 | C34: =IF(C20="","",100-C20/$B$24*100) -> -3.7724898 | D34: =IF(D20="","",100-D20/$B$24*100) -> -16.77307 | E34: =IF(E20="","",100-E20/$B$24*100) -> -3.3081834 | F34: =IF(F20="","",100-F20/$B$24*100) -> -23.389437 | G34: =IF(G20="","",100-G20/$B$24*100) -> -21.183981 | H34: =IF(H20="","",100-H20/$H$24*100) -> -16.908442 | I34: =IF(I20="","",100-I20/$H$24*100) -> -24.51843 | J34: =IF(J20="","",100-J20/$H$24*100) -> -27.990488 | K34: =IF(K20="","",100-K20/$H$24*100) -> -9.4411415 | L34: =IF(L20="","",100-L20/$H$24*100) -> -17.384067 | M34: =IF(M20="","",100-M20/$H$24*100) -> -26.896552

Sheet Résultats
A1: T.b. gambiense iELISA (apDIA)
A3: Formulaire des résultats
A5: Date de préparation | C5: =IF(ECHANTILLONS!C6="","",ECHANTILLONS!C6) | F5: Cut off | G5: 30
A6: Opérateur | C6: =IF(ECHANTILLONS!C7="","",ECHANTILLONS!C7)
A7: N° du lot du kit | C7: =IF(ECHANTILLONS!C8="","",ECHANTILLONS!C8) -> 3915223
A8: N° de la plaque | C8: =IF(ECHANTILLONS!C9="","",ECHANTILLONS!C9)
A9: Etude/origine | C9: =IF(ECHANTILLONS!C10="","",ECHANTILLONS!C10)
D12: LiTat 1.3 | F12: LiTat 1.5 | H12: Résultat final
B13: Numéro labo | C13: Code-barres KPS | D13: Pourcentage d'inhibition | E13: Résultat | F13: Pourcentage d'inhibition | G13: Résultat | I13: Commentaire (en cas de problème ou irrégularité) | J13: Validation (Echec/Valide)
A14: S1 | B14: 177 | C14: 2501248 | D14: =IF('450-600 nm'!F27="","",'450-600 nm'!F27) -> 3.5403366 | E14: =IF(D14="","",IF(D14>=$G$5,"POS","NEG")) -> NEG | F14: =IF('450-600 nm'!L27="","",'450-600 nm'!L27) -> -7.7288942 | G14: =IF(F14="","",IF(F14>=$G$5,"POS","NEG")) -> NEG | H14: =IF(AND(E14="NEG",G14="NEG"),"N",IF(E14="POS","P",IF(G14="POS","P",""))) -> N | I14: =IF(ECHANTILLONS!D15="","",ECHANTILLONS!D15) | J14: Validation (Echec/Valide)
A15: S2 | B15: 178 | C15: 2501295 | D15: =IF('450-600 nm'!G27="","",'450-600 nm'!G27) -> 5.1654092 | E15: =IF(D15="","",IF(D15>=$G$5,"POS","NEG")) -> NEG | F15: =IF('450-600 nm'!M27="","",'450-600 nm'!M27) -> -17.717004 | G15: =IF(F15="","",IF(F15>=$G$5,"POS","NEG")) -> NEG | H15: =IF(AND(E15="NEG",G15="NEG"),"N",IF(E15="POS","P",IF(G15="POS","P",""))) -> N | I15: =IF(ECHANTILLONS!D16="","",ECHANTILLONS!D16) | J15: Validation (Echec/Valide)
A16: S3 | B16: 179 | C16: 2501225 | D16: =IF('450-600 nm'!B28="","",'450-600 nm'!B28) -> -6.6744051 | E16: =IF(D16="","",IF(D16>=$G$5,"POS","NEG")) -> NEG | F16: =IF('450-600 nm'!H28="","",'450-600 nm'!H28) -> 9.0130797 | G16: =IF(F16="","",IF(F16>=$G$5,"POS","NEG")) -> NEG | H16: =IF(AND(E16="NEG",G16="NEG"),"N",IF(E16="POS","P",IF(G16="POS","P",""))) -> N | I16: =IF(ECHANTILLONS!D17="","",ECHANTILLONS!D17) | J16: Validation (Echec/Valide)
A17: S4 | B17: 180 | C17: 2501292 | D17: =IF('450-600 nm'!C28="","",'450-600 nm'!C28) -> 22.228671 | E17: =IF(D17="","",IF(D17>=$G$5,"POS","NEG")) -> NEG | F17: =IF('450-600 nm'!I28="","",'450-600 nm'!I28) -> 15.243757 | G17: =IF(F17="","",IF(F17>=$G$5,"POS","NEG")) -> NEG | H17: =IF(AND(E17="NEG",G17="NEG"),"N",IF(E17="POS","P",IF(G17="POS","P",""))) -> N | I17: =IF(ECHANTILLONS!D18="","",ECHANTILLONS!D18) | J17: Validation (Echec/Valide)
A18: S5 | B18: 181 | C18: 2501913 | D18: =IF('450-600 nm'!D28="","",'450-600 nm'!D28) -> 5.9779454 | E18: =IF(D18="","",IF(D18>=$G$5,"POS","NEG")) -> NEG | F18: =IF('450-600 nm'!J28="","",'450-600 nm'!J28) -> 7.0154578 | G18: =IF(F18="","",IF(F18>=$G$5,"POS","NEG")) -> NEG | H18: =IF(AND(E18="NEG",G18="NEG"),"N",IF(E18="POS","P",IF(G18="POS","P",""))) -> N | I18: =IF(ECHANTILLONS!D19="","",ECHANTILLONS!D19) | J18: Validation (Echec/Valide)
A19: S6 | B19: 182 | C19: 2501960 | D19: =IF('450-600 nm'!E28="","",'450-600 nm'!E28) -> 18.16599 | E19: =IF(D19="","",IF(D19>=$G$5,"POS","NEG")) -> NEG | F19: =IF('450-600 nm'!K28="","",'450-600 nm'!K28) -> -2.9250892 | G19: =IF(F19="","",IF(F19>=$G$5,"POS","NEG")) -> NEG | H19: =IF(AND(E19="NEG",G19="NEG"),"N",IF(E19="POS","P",IF(G19="POS","P",""))) -> N | I19: =IF(ECHANTILLONS!D20="","",ECHANTILLONS!D20) | J19: Validation (Echec/Valide)
A20: S7 | B20: 183 | C20: 2501955 | D20: =IF('450-600 nm'!F28="","",'450-600 nm'!F28) -> 16.889147 | E20: =IF(D20="","",IF(D20>=$G$5,"POS","NEG")) -> NEG | F20: =IF('450-600 nm'!L28="","",'450-600 nm'!L28) -> 0.64209275 | G20: =IF(F20="","",IF(F20>=$G$5,"POS","NEG")) -> NEG | H20: =IF(AND(E20="NEG",G20="NEG"),"N",IF(E20="POS","P",IF(G20="POS","P",""))) -> N | I20: =IF(ECHANTILLONS!D21="","",ECHANTILLONS!D21) | J20: Validation (Echec/Valide)
A21: S8 | B21: 184 | C21: 2501968 | D21: =IF('450-600 nm'!G28="","",'450-600 nm'!G28) -> 27.800348 | E21: =IF(D21="","",IF(D21>=$G$5,"POS","NEG")) -> NEG | F21: =IF('450-600 nm'!M28="","",'450-600 nm'!M28) -> -10.487515 | G21: =IF(F21="","",IF(F21>=$G$5,"POS","NEG")) -> NEG | H21: =IF(AND(E21="NEG",G21="NEG"),"N",IF(E21="POS","P",IF(G21="POS","P",""))) -> N | I21: =IF(ECHANTILLONS!D22="","",ECHANTILLONS!D22) | J21: Validation (Echec/Valide)
A22: S9 | B22: 185 | C22: 2501922 | D22: =IF('450-600 nm'!B29="","",'450-600 nm'!B29) -> -4.8171793 | E22: =IF(D22="","",IF(D22>=$G$5,"POS","NEG")) -> NEG | F22: =IF('450-600 nm'!H29="","",'450-600 nm'!H29) -> 2.2116528 | G22: =IF(F22="","",IF(F22>=$G$5,"POS","NEG")) -> NEG | H22: =IF(AND(E22="NEG",G22="NEG"),"N",IF(E22="POS","P",IF(G22="POS","P",""))) -> N | I22: =IF(ECHANTILLONS!D23="","",ECHANTILLONS!D23) | J22: Validation (Echec/Valide)
A23: S10 | B23: 186 | C23: 2501925 | D23: =IF('450-600 nm'!C29="","",'450-600 nm'!C29) -> 12.246082 | E23: =IF(D23="","",IF(D23>=$G$5,"POS","NEG")) -> NEG | F23: =IF('450-600 nm'!I29="","",'450-600 nm'!I29) -> 7.1581451 | G23: =IF(F23="","",IF(F23>=$G$5,"POS","NEG")) -> NEG | H23: =IF(AND(E23="NEG",G23="NEG"),"N",IF(E23="POS","P",IF(G23="POS","P",""))) -> N | I23: =IF(ECHANTILLONS!D24="","",ECHANTILLONS!D24) | J23: Validation (Echec/Valide)
A24: S11 | B24: 187 | C24: 2402967 | D24: =IF('450-600 nm'!D29="","",'450-600 nm'!D29) -> 5.0493326 | E24: =IF(D24="","",IF(D24>=$G$5,"POS","NEG")) -> NEG | F24: =IF('450-600 nm'!J29="","",'450-600 nm'!J29) -> 12.009512 | G24: =IF(F24="","",IF(F24>=$G$5,"POS","NEG")) -> NEG | H24: =IF(AND(E24="NEG",G24="NEG"),"N",IF(E24="POS","P",IF(G24="POS","P",""))) -> N | I24: =IF(ECHANTILLONS!D25="","",ECHANTILLONS!D25) | J24: Validation (Echec/Valide)
A25: S12 | B25: 188 | C25: 2501927 | D25: =IF('450-600 nm'!E29="","",'450-600 nm'!E29) -> 19.210679 | E25: =IF(D25="","",IF(D25>=$G$5,"POS","NEG")) -> NEG | F25: =IF('450-600 nm'!K29="","",'450-600 nm'!K29) -> 1.9738407 | G25: =IF(F25="","",IF(F25>=$G$5,"POS","NEG")) -> NEG | H25: =IF(AND(E25="NEG",G25="NEG"),"N",IF(E25="POS","P",IF(G25="POS","P",""))) -> N | I25: =IF(ECHANTILLONS!D26="","",ECHANTILLONS!D26) | J25: Validation (Echec/Valide)
A26: S13 | B26: 189 | C26: 2400333 | D26: =IF('450-600 nm'!F29="","",'450-600 nm'!F29) -> 9.1120139 | E26: =IF(D26="","",IF(D26>=$G$5,"POS","NEG")) -> NEG | F26: =IF('450-600 nm'!L29="","",'450-600 nm'!L29) -> 8.3947681 | G26: =IF(F26="","",IF(F26>=$G$5,"POS","NEG")) -> NEG | H26: =IF(AND(E26="NEG",G26="NEG"),"N",IF(E26="POS","P",IF(G26="POS","P",""))) -> N | I26: =IF(ECHANTILLONS!D27="","",ECHANTILLONS!D27) | J26: Validation (Echec/Valide)
A27: S14 | B27: 190 | C27: 2502158 | D27: =IF('450-600 nm'!G29="","",'450-600 nm'!G29) -> 13.522925 | E27: =IF(D27="","",IF(D27>=$G$5,"POS","NEG")) -> NEG | F27: =IF('450-600 nm'!M29="","",'450-600 nm'!M29) -> -8.2045184 | G27: =IF(F27="","",IF(F27>=$G$5,"POS","NEG")) -> NEG | H27: =IF(AND(E27="NEG",G27="NEG"),"N",IF(E27="POS","P",IF(G27="POS","P",""))) -> N | I27: =IF(ECHANTILLONS!D28="","",ECHANTILLONS!D28) | J27: Validation (Echec/Valide)
A28: S15 | B28: 191 | C28: 2501888 | D28: =IF('450-600 nm'!B30="","",'450-600 nm'!B30) -> -11.665699 | E28: =IF(D28="","",IF(D28>=$G$5,"POS","NEG")) -> NEG | F28: =IF('450-600 nm'!H30="","",'450-600 nm'!H30) -> 5.3507729 | G28: =IF(F28="","",IF(F28>=$G$5,"POS","NEG")) -> NEG | H28: =IF(AND(E28="NEG",G28="NEG"),"N",IF(E28="POS","P",IF(G28="POS","P",""))) -> N | I28: =IF(ECHANTILLONS!D29="","",ECHANTILLONS!D29) | J28: Validation (Echec/Valide)
A29: S16 | B29: 192 | C29: 2501897 | D29: =IF('450-600 nm'!C30="","",'450-600 nm'!C30) -> 6.6744051 | E29: =IF(D29="","",IF(D29>=$G$5,"POS","NEG")) -> NEG | F29: =IF('450-600 nm'!I30="","",'450-600 nm'!I30) -> 8.6801427 | G29: =IF(F29="","",IF(F29>=$G$5,"POS","NEG")) -> NEG | H29: =IF(AND(E29="NEG",G29="NEG"),"N",IF(E29="POS","P",IF(G29="POS","P",""))) -> N | I29: =IF(ECHANTILLONS!D30="","",ECHANTILLONS!D30) | J29: Validation (Echec/Valide)
A30: S17 | B30: 193 | C30: 2402279 | D30: =IF('450-600 nm'!D30="","",'450-600 nm'!D30) -> -1.9152641 | E30: =IF(D30="","",IF(D30>=$G$5,"POS","NEG")) -> NEG | F30: =IF('450-600 nm'!J30="","",'450-600 nm'!J30) -> 7.1105826 | G30: =IF(F30="","",IF(F30>=$G$5,"POS","NEG")) -> NEG | H30: =IF(AND(E30="NEG",G30="NEG"),"N",IF(E30="POS","P",IF(G30="POS","P",""))) -> N | I30: =IF(ECHANTILLONS!D31="","",ECHANTILLONS!D31) | J30: Validation (Echec/Valide)
A31: S18 | B31: 194 | C31: 2402278 | D31: =IF('450-600 nm'!E30="","",'450-600 nm'!E30) -> 7.2547882 | E31: =IF(D31="","",IF(D31>=$G$5,"POS","NEG")) -> NEG | F31: =IF('450-600 nm'!K30="","",'450-600 nm'!K30) -> -1.3555291 | G31: =IF(F31="","",IF(F31>=$G$5,"POS","NEG")) -> NEG | H31: =IF(AND(E31="NEG",G31="NEG"),"N",IF(E31="POS","P",IF(G31="POS","P",""))) -> N | I31: =IF(ECHANTILLONS!D32="","",ECHANTILLONS!D32) | J31: Validation (Echec/Valide)
A32: S19 | B32: 195 | C32: 2402282 | D32: =IF('450-600 nm'!F30="","",'450-600 nm'!F30) -> 12.942542 | E32: =IF(D32="","",IF(D32>=$G$5,"POS","NEG")) -> NEG | F32: =IF('450-600 nm'!L30="","",'450-600 nm'!L30) -> -2.7824019 | G32: =IF(F32="","",IF(F32>=$G$5,"POS","NEG")) -> NEG | H32: =IF(AND(E32="NEG",G32="NEG"),"N",IF(E32="POS","P",IF(G32="POS","P",""))) -> N | I32: =IF(ECHANTILLONS!D33="","",ECHANTILLONS!D33) | J32: Validation (Echec/Valide)
A33: S20 | B33: 196 | C33: 2402288 | D33: =IF('450-600 nm'!G30="","",'450-600 nm'!G30) -> 15.147998 | E33: =IF(D33="","",IF(D33>=$G$5,"POS","NEG")) -> NEG | F33: =IF('450-600 nm'!M30="","",'450-600 nm'!M30) -> -11.200951 | G33: =IF(F33="","",IF(F33>=$G$5,"POS","NEG")) -> NEG | H33: =IF(AND(E33="NEG",G33="NEG"),"N",IF(E33="POS","P",IF(G33="POS","P",""))) -> N | I33: =IF(ECHANTILLONS!D34="","",ECHANTILLONS!D34) | J33: Validation (Echec/Valide)
A34: S21 | B34: 197 | C34: 2402777 | D34: =IF('450-600 nm'!B31="","",'450-600 nm'!B31) -> 1.9152641 | E34: =IF(D34="","",IF(D34>=$G$5,"POS","NEG")) -> NEG | F34: =IF('450-600 nm'!H31="","",'450-600 nm'!H31) -> 14.244946 | G34: =IF(F34="","",IF(F34>=$G$5,"POS","NEG")) -> NEG | H34: =IF(AND(E34="NEG",G34="NEG"),"N",IF(E34="POS","P",IF(G34="POS","P",""))) -> N | I34: =IF(ECHANTILLONS!D35="","",ECHANTILLONS!D35) | J34: Validation (Echec/Valide)
A35: S22 | B35: 198 | C35: 2500026 | D35: =IF('450-600 nm'!C31="","",'450-600 nm'!C31) -> 11.201393 | E35: =IF(D35="","",IF(D35>=$G$5,"POS","NEG")) -> NEG | F35: =IF('450-600 nm'!I31="","",'450-600 nm'!I31) -> 10.059453 | G35: =IF(F35="","",IF(F35>=$G$5,"POS","NEG")) -> NEG | H35: =IF(AND(E35="NEG",G35="NEG"),"N",IF(E35="POS","P",IF(G35="POS","P",""))) -> N | I35: =IF(ECHANTILLONS!D36="","",ECHANTILLONS!D36) | J35: Validation (Echec/Valide)
A36: S23 | B36: 199 | C36: 2400839 | D36: =IF('450-600 nm'!D31="","",'450-600 nm'!D31) -> 17.1213 | E36: =IF(D36="","",IF(D36>=$G$5,"POS","NEG")) -> NEG | F36: =IF('450-600 nm'!J31="","",'450-600 nm'!J31) -> 9.5838288 | G36: =IF(F36="","",IF(F36>=$G$5,"POS","NEG")) -> NEG | H36: =IF(AND(E36="NEG",G36="NEG"),"N",IF(E36="POS","P",IF(G36="POS","P",""))) -> N | I36: =IF(ECHANTILLONS!D37="","",ECHANTILLONS!D37) | J36: Validation (Echec/Valide)
A37: S24 | B37: 200 | C37: 2400825 | D37: =IF('450-600 nm'!E31="","",'450-600 nm'!E31) -> 0.17411492 | E37: =IF(D37="","",IF(D37>=$G$5,"POS","NEG")) -> NEG | F37: =IF('450-600 nm'!K31="","",'450-600 nm'!K31) -> 4.9227111 | G37: =IF(F37="","",IF(F37>=$G$5,"POS","NEG")) -> NEG | H37: =IF(AND(E37="NEG",G37="NEG"),"N",IF(E37="POS","P",IF(G37="POS","P",""))) -> N | I37: =IF(ECHANTILLONS!D38="","",ECHANTILLONS!D38) | J37: Validation (Echec/Valide)
A38: S25 | B38: 201 | C38: 2501972 | D38: =IF('450-600 nm'!F31="","",'450-600 nm'!F31) -> 14.219385 | E38: =IF(D38="","",IF(D38>=$G$5,"POS","NEG")) -> NEG | F38: =IF('450-600 nm'!L31="","",'450-600 nm'!L31) -> 1.8311534 | G38: =IF(F38="","",IF(F38>=$G$5,"POS","NEG")) -> NEG | H38: =IF(AND(E38="NEG",G38="NEG"),"N",IF(E38="POS","P",IF(G38="POS","P",""))) -> N | I38: =IF(ECHANTILLONS!D39="","",ECHANTILLONS!D39) | J38: Validation (Echec/Valide)
A39: S26 | B39: 202 | C39: 2501321 | D39: =IF('450-600 nm'!G31="","",'450-600 nm'!G31) -> 16.308764 | E39: =IF(D39="","",IF(D39>=$G$5,"POS","NEG")) -> NEG | F39: =IF('450-600 nm'!M31="","",'450-600 nm'!M31) -> -9.0130797 | G39: =IF(F39="","",IF(F39>=$G$5,"POS","NEG")) -> NEG | H39: =IF(AND(E39="NEG",G39="NEG"),"N",IF(E39="POS","P",IF(G39="POS","P",""))) -> N | I39: =IF(ECHANTILLONS!D40="","",ECHANTILLONS!D40) | J39: Validation (Echec/Valide)
A40: S27 | B40: 203 | C40: 2501176 | D40: =IF('450-600 nm'!B32="","",'450-600 nm'!B32) -> -17.81776 | E40: =IF(D40="","",IF(D40>=$G$5,"POS","NEG")) -> NEG | F40: =IF('450-600 nm'!H32="","",'450-600 nm'!H32) -> -9.7265161 | G40: =IF(F40="","",IF(F40>=$G$5,"POS","NEG")) -> NEG | H40: =IF(AND(E40="NEG",G40="NEG"),"N",IF(E40="POS","P",IF(G40="POS","P",""))) -> N | I40: =IF(ECHANTILLONS!D41="","",ECHANTILLONS!D41) | J40: Validation (Echec/Valide)
A41: S28 | B41: 204 | C41: 2501168 | D41: =IF('450-600 nm'!C32="","",'450-600 nm'!C32) -> -3.8885665 | E41: =IF(D41="","",IF(D41>=$G$5,"POS","NEG")) -> NEG | F41: =IF('450-600 nm'!I32="","",'450-600 nm'!I32) -> 1.7360285 | G41: =IF(F41="","",IF(F41>=$G$5,"POS","NEG")) -> NEG | H41: =IF(AND(E41="NEG",G41="NEG"),"N",IF(E41="POS","P",IF(G41="POS","P",""))) -> N | I41: =IF(ECHANTILLONS!D42="","",ECHANTILLONS!D42) | J41: Validation (Echec/Valide)
A42: S29 | B42: 205 | C42: 2501886 | D42: =IF('450-600 nm'!D32="","",'450-600 nm'!D32) -> -10.27278 | E42: =IF(D42="","",IF(D42>=$G$5,"POS","NEG")) -> NEG | F42: =IF('450-600 nm'!J32="","",'450-600 nm'!J32) -> -2.7348395 | G42: =IF(F42="","",IF(F42>=$G$5,"POS","NEG")) -> NEG | H42: =IF(AND(E42="NEG",G42="NEG"),"N",IF(E42="POS","P",IF(G42="POS","P",""))) -> N | I42: =IF(ECHANTILLONS!D43="","",ECHANTILLONS!D43) | J42: Validation (Echec/Valide)
A43: S30 | B43: 206 | C43: 2501885 | D43: =IF('450-600 nm'!E32="","",'450-600 nm'!E32) -> -4.0046431 | E43: =IF(D43="","",IF(D43>=$G$5,"POS","NEG")) -> NEG | F43: =IF('450-600 nm'!K32="","",'450-600 nm'!K32) -> -11.581451 | G43: =IF(F43="","",IF(F43>=$G$5,"POS","NEG")) -> NEG | H43: =IF(AND(E43="NEG",G43="NEG"),"N",IF(E43="POS","P",IF(G43="POS","P",""))) -> N | I43: =IF(ECHANTILLONS!D44="","",ECHANTILLONS!D44) | J43: Validation (Echec/Valide)
A44: S31 | B44: 207 | C44: 2501901 | D44: =IF('450-600 nm'!F32="","",'450-600 nm'!F32) -> 43.586767 | E44: =IF(D44="","",IF(D44>=$G$5,"POS","NEG")) -> POS | F44: =IF('450-600 nm'!L32="","",'450-600 nm'!L32) -> 31.938169 | G44: =IF(F44="","",IF(F44>=$G$5,"POS","NEG")) -> POS | H44: =IF(AND(E44="NEG",G44="NEG"),"N",IF(E44="POS","P",IF(G44="POS","P",""))) -> P | I44: =IF(ECHANTILLONS!D45="","",ECHANTILLONS!D45) | J44: Validation (Echec/Valide)
...
