Workbook

Sheet ECHANTILLONS
A1: Trypanosoma brucei gambiense inhibition ELISA (iELISA)
A3: Formulaire d'identification des échantillons
A6: Date de preparation
A7: Operateur
A8: Numéro du lot iELISA | C8: 3915223
A9: N de seriés d'échantillons
A10: Étude/origin
A14: N° échantillon dans la microplaque | B14: Numéro labo | C14: Code-barres KPS | D14: Commentaire (en cas de problème ou irregularité)
A15: S1 | B15: 838 | C15: 2502341
A16: S2 | B16: 839 | C16: 2502347
A17: S3 | B17: 840 | C17: 2503040
A18: S4 | B18: 841 | C18: 2503063
A19: S5 | B19: 842 | C19: 2500826
A20: S6 | B20: 843 | C20: 2502295
A21: S7 | B21: 844 | C21: 2500856
A22: S8 | B22: 845 | C22: 2502227
A23: S9 | B23: 846 | C23: 2502291
A24: S10 | B24: 847 | C24: 2502289
A25: S11 | B25: 848 | C25: 2500876
A26: S12 | B26: 849 | C26: 2502361
... A58: S44 | B58: 881 | C58: 2502085

Sheet 450-600 nm
A1: T.b. gambiense iELISA (apDIA)
A3: Résultats brutes
A5: Date | C5: =IF(ECHANTILLONS!C6="","",ECHANTILLONS!C6) | F5: Etude | G5: =IF(ECHANTILLONS!C10="","",ECHANTILLONS!C10) | H5: =IF(ECHANTILLONS!F6="","",ECHANTILLONS!F6)
A6: Opérateur | C6: =IF(ECHANTILLONS!C7="","",ECHANTILLONS!C7)
A7: N° du Lot | C7: =IF(ECHANTILLONS!C8="","",ECHANTILLONS!C8) -> 3915223
A8: N° de la plaque | C8: =IF(ECHANTILLONS!C9="","",ECHANTILLONS!C9)
A9: Filtre (nm) | C9: 450-600 nm
B12: 1 | C12: 2 | D12: 3 | E12: 4 | F12: 5 | G12: 6 | H12: 7 | I12: 8 | J12: 9 | K12: 10 | L12: 11 | M12: 12
A13: A | B13: 0.672 | C13: 0.738 | D13: 0.283 | E13: 0.272 | F13: 0.897 | G13: 0.853 | H13: 1.734 | I13: 1.759 | J13: 0.663 | K13: 0.672 | L13: 1.935 | M13: 1.98
A14: B | B14: 0.771 | C14: 0.73 | D14: 0.666 | E14: 0.674 | F14: 0.73 | G14: 0.764 | H14: 1.576 | I14: 1.538 | J14: 1.588 | K14: 1.523 | L14: 1.712 | M14: 1.868
A15: C | B15: 0.612 | C15: 0.632 | D15: 0.676 | E15: 0.693 | F15: 0.742 | G15: 0.736 | H15: 1.479 | I15: 1.364 | J15: 1.466 | K15: 1.599 | L15: 1.86 | M15: 1.855
A16: D | B16: 0.662 | C16: 0.505 | D16: 0.713 | E16: 0.659 | F16: 0.7 | G16: 0.654 | H16: 1.49 | I16: 1.253 | J16: 1.266 | K16: 1.367 | L16: 1.926 | M16: 1.863
A17: E | B17: 0.656 | C17: 0.651 | D17: 0.653 | E17: 0.69 | F17: 0.613 | G17: 0.612 | H17: 1.307 | I17: 1.437 | J17: 1.331 | K17: 1.372 | L17: 1.415 | M17: 1.111
A18: F | B18: 0.771 | C18: 0.812 | D18: 0.828 | E18: 0.808 | F18: 0.781 | G18: 0.801 | H18: 1.48 | I18: 1.411 | J18: 1.43 | K18: 1.527 | L18: 1.502 | M18: 1.456
A19: G | B19: 0.716 | C19: 0.844 | D19: 0.856 | E19: 0.855 | F19: 0.987 | G19: 0.856 | H19: 1.678 | I19: 1.615 | J19: 1.609 | K19: 1.765 | L19: 1.74 | M19: 1.187
A20: H | B20: 0.694 | C20: 0.849 | D20: 0.836 | E20: 0.887 | F20: 0.98 | G20: 1.048 | H20: 1.831 | I20: 1.969 | J20: 1.788 | K20: 2.015 | L20: 1.801 | M20: 1.881
B22: LiTat 1.3 | H22: LiTat 1.5
B23: Moyenne contrôle nég LiTat 1.3 | D23: Moyenne contrôle pos LiTat 1.3 | F23: PI CP LiTat 1.3 | H23: Moyenne contrôle nég LiTat 1.5 | J23: Moyenne contrôle pos LiTat 1.5 | L23: PI C pos LiTat 1.5
B24: =(B13+C13)/2 -> 0.705 | D24: =(D13+E13)/2 -> 0.2775 | F24: =100-(D24/B24*100) -> 60.638298 | H24: =(H13+I13)/2 -> 1.7465 | J24: =(J13+K13)/2 -> 0.6675 | L24: =100-(J24/H24*100) -> 61.780704
B26: 1 | C26: 2 | D26: 3 | E26: 4 | F26: 5 | G26: 6 | H26: 7 | I26: 8 | J26: 9 | K26: 10 | L26: 11 | M26: 12
A27: A | F27: =IF(F13="","",100-F13/$B$24*100) -> -27.234043 | G27: =IF(G13="","",100-G13/$B$24*100) -> -20.992908 | L27: =IF(L13="","",100-L13/$H$24*100) -> -10.793015 | M27: =IF(M13="","",100-M13/$H$24*100) -> -13.369596
A28: B | B28: =IF(B14="","",100-B14/$B$24*100) -> -9.3617021 | C28: =IF(C14="","",100-C14/$B$24*100) -> -3.5460993 | D28: =IF(D14="","",100-D14/$B$24*100) -> 5.5319149 | E28: =IF(E14="","",100-E14/$B$24*100) -> 4.3971631 | F28: =IF(F14="","",100-F14/$B$24*100) -> -3.5460993 | G28: =IF(G14="","",100-G14/$B$24*100) -> -8.3687943 | H28: =IF(H14="","",100-H14/$H$24*100) -> 9.7623819 | I28: =IF(I14="","",100-I14/$H$24*100) -> 11.938162 | J28: =IF(J14="","",100-J14/$H$24*100) -> 9.0752934 | K28: =IF(K14="","",100-K14/$H$24*100) -> 12.797023 | L28: =IF(L14="","",100-L14/$H$24*100) -> 1.9753793 | M28: =IF(M14="","",100-M14/$H$24*100) -> -6.9567707
A29: C | B29: =IF(B15="","",100-B15/$B$24*100) -> 13.191489 | C29: =IF(C15="","",100-C15/$B$24*100) -> 10.35461 | D29: =IF(D15="","",100-D15/$B$24*100) -> 4.1134752 | E29: =IF(E15="","",100-E15/$B$24*100) -> 1.7021277 | F29: =IF(F15="","",100-F15/$B$24*100) -> -5.248227 | G29: =IF(G15="","",100-G15/$B$24*100) -> -4.3971631 | H29: =IF(H15="","",100-H15/$H$24*100) -> 15.316347 | I29: =IF(I15="","",100-I15/$H$24*100) -> 21.900945 | J29: =IF(J15="","",100-J15/$H$24*100) -> 16.060693 | K29: =IF(K15="","",100-K15/$H$24*100) -> 8.4454624 | L29: =IF(L15="","",100-L15/$H$24*100) -> -6.4987117 | M29: =IF(M15="","",100-M15/$H$24*100) -> -6.2124248
A30: D | B30: =IF(B16="","",100-B16/$B$24*100) -> 6.0992908 | C30: =IF(C16="","",100-C16/$B$24*100) -> 28.368794 | D30: =IF(D16="","",100-D16/$B$24*100) -> -1.1347518 | E30: =IF(E16="","",100-E16/$B$24*100) -> 6.5248227 | F30: =IF(F16="","",100-F16/$B$24*100) -> 0.70921986 | G30: =IF(G16="","",100-G16/$B$24*100) -> 7.2340426 | H30: =IF(H16="","",100-H16/$H$24*100) -> 14.686516 | I30: =IF(I16="","",100-I16/$H$24*100) -> 28.256513 | J30: =IF(J16="","",100-J16/$H$24*100) -> 27.512167 | K30: =IF(K16="","",100-K16/$H$24*100) -> 21.729173 | L30: =IF(L16="","",100-L16/$H$24*100) -> -10.277698 | M30: =IF(M16="","",100-M16/$H$24*100) -> -6.6704838
A31: E | B31: =IF(B17="","",100-B17/$B$24*100) -> 6.9503546 | C31: =IF(C17="","",100-C17/$B$24*100) -> 7.6595745 | D31: =IF(D17="","",100-D17/$B$24*100) -> 7.3758865 | E31: =IF(E17="","",100-E17/$B$24*100) -> 2.1276596 | F31: =IF(F17="","",100-F17/$B$24*100) -> 13.049645 | G31: =IF(G17="","",100-G17/$B$24*100) -> 13.191489 | H31: =IF(H17="","",100-H17/$H$24*100) -> 25.164615 | I31: =IF(I17="","",100-I17/$H$24*100) -> 17.721157 | J31: =IF(J17="","",100-J17/$H$24*100) -> 23.790438 | K31: =IF(K17="","",100-K17/$H$24*100) -> 21.442886 | L31: =IF(L17="","",100-L17/$H$24*100) -> 18.980819 | M31: =IF(M17="","",100-M17/$H$24*100) -> 36.38706
A32: F | B32: =IF(B18="","",100-B18/$B$24*100) -> -9.3617021 | C32: =IF(C18="","",100-C18/$B$24*100) -> -15.177305 | D32: =IF(D18="","",100-D18/$B$24*100) -> -17.446809 | E32: =IF(E18="","",100-E18/$B$24*100) -> -14.609929 | F32: =IF(F18="","",100-F18/$B$24*100) -> -10.780142 | G32: =IF(G18="","",100-G18/$B$24*100) -> -13.617021 | H32: =IF(H18="","",100-H18/$H$24*100) -> 15.25909 | I32: =IF(I18="","",100-I18/$H$24*100) -> 19.209848 | J32: =IF(J18="","",100-J18/$H$24*100) -> 18.121958 | K32: =IF(K18="","",100-K18/$H$24*100) -> 12.567993 | L32: =IF(L18="","",100-L18/$H$24*100) -> 13.999427 | M32: =IF(M18="","",100-M18/$H$24*100) -> 16.633267
A33: G | B33: =IF(B19="","",100-B19/$B$24*100) -> -1.5602837 | C33: =IF(C19="","",100-C19/$B$24*100) -> -19.716312 | D33: =IF(D19="","",100-D19/$B$24*100) -> -21.41844 | E33: =IF(E19="","",100-E19/$B$24*100) -> -21.276596 | F33: =IF(F19="","",100-F19/$B$24*100) -> -40 | G33: =IF(G19="","",100-G19/$B$24*100) -> -21.41844 | H33: =IF(H19="","",100-H19/$H$24*100) -> 3.92213 | I33: =IF(I19="","",100-I19/$H$24*100) -> 7.5293444 | J33: =IF(J19="","",100-J19/$H$24*100) -> 7.8728886 | K33: =IF(K19="","",100-K19/$H$24*100) -> -1.0592614 | L33: =IF(L19="","",100-L19/$H$24*100) -> 0.37217292 | M33: =IF(M19="","",100-M19/$H$24*100) -> 32.0355
A34: H | B34: =IF(B20="","",100-B20/$B$24*100) -> 1.5602837 | C34: =IF(C20="","",100-C20/$B$24*100) -> -20.425532 | D34: =IF(D20="","",100-D20/$B$24*100) -> -18.58156 | E34: =IF(E20="","",100-E20/$B$24*100) -> -25.815603 | F34: =IF(F20="","",100-F20/$B$24*100) -> -39.007092 | G34: =IF(G20="","",100-G20/$B$24*100) -> -48.652482 | H34: =IF(H20="","",100-H20/$H$24*100) -> -4.8382479 | I34: =IF(I20="","",100-I20/$H$24*100) -> -12.739765 | J34: =IF(J20="","",100-J20/$H$24*100) -> -2.3761809 | K34: =IF(K20="","",100-K20/$H$24*100) -> -15.373604 | L34: =IF(L20="","",100-L20/$H$24*100) -> -3.1205268 | M34: =IF(M20="","",100-M20/$H$24*100) -> -7.7011165

Sheet Résultats
A1: T.b. gambiense iELISA (apDIA)
A3: Formulaire des résultats
A5: Date de préparation | C5: =IF(ECHANTILLONS!C6="","",ECHANTILLONS!C6) | F5: Cut off | G5: 30
A6: Opérateur | C6: =IF(ECHANTILLONS!C7="","",ECHANTILLONS!C7)
A7: N° du lot du kit | C7: =IF(ECHANTILLONS!C8="","",ECHANTILLONS!C8) -> 3915223
A8: N° de la plaque | C8: =IF(ECHANTILLONS!C9="","",ECHANTILLONS!C9)
A9: Etude/origine | C9: =IF(ECHANTILLONS!C10="","",ECHANTILLONS!C10)
D12: LiTat 1.3 | F12: LiTat 1.5 | H12: Résultat final
B13: Numéro labo | C13: Code-barres KPS | D13: Pourcentage d'inhibition | E13: Résultat | F13: Pourcentage d'inhibition | G13: Résultat | I13: Commentaire (en cas de problème ou irrégularité) | J13: Validation (Echec/Valide)
A14: S1 | B14: =IF(ECHANTILLONS!B15="","",ECHANTILLONS!B15) -> 838 | C14: =IF(ECHANTILLONS!C15="","",ECHANTILLONS!C15) -> 2502341 | D14: =IF('450-600 nm'!F27="","",'450-600 nm'!F27) -> -27.234043 | E14: =IF(D14="","",IF(D14>=$G$5,"POS","NEG")) -> NEG | F14: =IF('450-600 nm'!L27="","",'450-600 nm'!L27) -> -10.793015 | G14: =IF(F14="","",IF(F14>=$G$5,"POS","NEG")) -> NEG | H14: =IF(AND(E14="NEG",G14="NEG"),"N",IF(E14="POS","P",IF(G14="POS","P",""))) -> N | I14: =IF(ECHANTILLONS!D15="","",ECHANTILLONS!D15)
A15: S2 | B15: =IF(ECHANTILLONS!B16="","",ECHANTILLONS!B16) -> 839 | C15: =IF(ECHANTILLONS!C16="","",ECHANTILLONS!C16) -> 2502347 | D15: =IF('450-600 nm'!G27="","",'450-600 nm'!G27) -> -20.992908 | E15: =IF(D15="","",IF(D15>=$G$5,"POS","NEG")) -> NEG | F15: =IF('450-600 nm'!M27="","",'450-600 nm'!M27) -> -13.369596 | G15: =IF(F15="","",IF(F15>=$G$5,"POS","NEG")) -> NEG | H15: =IF(AND(E15="NEG",G15="NEG"),"N",IF(E15="POS","P",IF(G15="POS","P",""))) -> N | I15: =IF(ECHANTILLONS!D16="","",ECHANTILLONS!D16)
A16: S3 | B16: =IF(ECHANTILLONS!B17="","",ECHANTILLONS!B17) -> 840 | C16: =IF(ECHANTILLONS!C17="","",ECHANTILLONS!C17) -> 2503040 | D16: =IF('450-600 nm'!B28="","",'450-600 nm'!B28) -> -9.3617021 | E16: =IF(D16="","",IF(D16>=$G$5,"POS","NEG")) -> NEG | F16: =IF('450-600 nm'!H28="","",'450-600 nm'!H28) -> 9.7623819 | G16: =IF(F16="","",IF(F16>=$G$5,"POS","NEG")) -> NEG | H16: =IF(AND(E16="NEG",G16="NEG"),"N",IF(E16="POS","P",IF(G16="POS","P",""))) -> N | I16: =IF(ECHANTILLONS!D17="","",ECHANTILLONS!D17)
A17: S4 | B17: =IF(ECHANTILLONS!B18="","",ECHANTILLONS!B18) -> 841 | C17: =IF(ECHANTILLONS!C18="","",ECHANTILLONS!C18) -> 2503063 | D17: =IF('450-600 nm'!C28="","",'450-600 nm'!C28) -> -3.5460993 | E17: =IF(D17="","",IF(D17>=$G$5,"POS","NEG")) -> NEG | F17: =IF('450-600 nm'!I28="","",'450-600 nm'!I28) -> 11.938162 | G17: =IF(F17="","",IF(F17>=$G$5,"POS","NEG")) -> NEG | H17: =IF(AND(E17="NEG",G17="NEG"),"N",IF(E17="POS","P",IF(G17="POS","P",""))) -> N | I17: =IF(ECHANTILLONS!D18="","",ECHANTILLONS!D18)
A18: S5 | B18: =IF(ECHANTILLONS!B19="","",ECHANTILLONS!B19) -> 842 | C18: =IF(ECHANTILLONS!C19="","",ECHANTILLONS!C19) -> 2500826 | D18: =IF('450-600 nm'!D28="","",'450-600 nm'!D28) -> 5.5319149 | E18: =IF(D18="","",IF(D18>=$G$5,"POS","NEG")) -> NEG | F18: =IF('450-600 nm'!J28="","",'450-600 nm'!J28) -> 9.0752934 | G18: =IF(F18="","",IF(F18>=$G$5,"POS","NEG")) -> NEG | H18: =IF(AND(E18="NEG",G18="NEG"),"N",IF(E18="POS","P",IF(G18="POS","P",""))) -> N | I18: =IF(ECHANTILLONS!D19="","",ECHANTILLONS!D19)
A19: S6 | B19: =IF(ECHANTILLONS!B20="","",ECHANTILLONS!B20) -> 843 | C19: =IF(ECHANTILLONS!C20="","",ECHANTILLONS!C20) -> 2502295 | D19: =IF('450-600 nm'!E28="","",'450-600 nm'!E28) -> 4.3971631 | E19: =IF(D19="","",IF(D19>=$G$5,"POS","NEG")) -> NEG | F19: =IF('450-600 nm'!K28="","",'450-600 nm'!K28) -> 12.797023 | G19: =IF(F19="","",IF(F19>=$G$5,"POS","NEG")) -> NEG | H19: =IF(AND(E19="NEG",G19="NEG"),"N",IF(E19="POS","P",IF(G19="POS","P",""))) -> N | I19: =IF(ECHANTILLONS!D20="","",ECHANTILLONS!D20)
A20: S7 | B20: =IF(ECHANTILLONS!B21="","",ECHANTILLONS!B21) -> 844 | C20: =IF(ECHANTILLONS!C21="","",ECHANTILLONS!C21) -> 2500856 | D20: =IF('450-600 nm'!F28="","",'450-600 nm'!F28) -> -3.5460993 | E20: =IF(D20="","",IF(D20>=$G$5,"POS","NEG")) -> NEG | F20: =IF('450-600 nm'!L28="","",'450-600 nm'!L28) -> 1.9753793 | G20: =IF(F20="","",IF(F20>=$G$5,"POS","NEG")) -> NEG | H20: =IF(AND(E20="NEG",G20="NEG"),"N",IF(E20="POS","P",IF(G20="POS","P",""))) -> N | I20: =IF(ECHANTILLONS!D21="","",ECHANTILLONS!D21)
A21: S8 | B21: =IF(ECHANTILLONS!B22="","",ECHANTILLONS!B22) -> 845 | C21: =IF(ECHANTILLONS!C22="","",ECHANTILLONS!C22) -> 2502227 | D21: =IF('450-600 nm'!G28="","",'450-600 nm'!G28) -> -8.3687943 | E21: =IF(D21="","",IF(D21>=$G$5,"POS","NEG")) -> NEG | F21: =IF('450-600 nm'!M28="","",'450-600 nm'!M28) -> -6.9567707 | G21: =IF(F21="","",IF(F21>=$G$5,"POS","NEG")) -> NEG | H21: =IF(AND(E21="NEG",G21="NEG"),"N",IF(E21="POS","P",IF(G21="POS","P",""))) -> N | I21: =IF(ECHANTILLONS!D22="","",ECHANTILLONS!D22)
A22: S9 | B22: =IF(ECHANTILLONS!B23="","",ECHANTILLONS!B23) -> 846 | C22: =IF(ECHANTILLONS!C23="","",ECHANTILLONS!C23) -> 2502291 | D22: =IF('450-600 nm'!B29="","",'450-600 nm'!B29) -> 13.191489 | E22: =IF(D22="","",IF(D22>=$G$5,"POS","NEG")) -> NEG | F22: =IF('450-600 nm'!H29="","",'450-600 nm'!H29) -> 15.316347 | G22: =IF(F22="","",IF(F22>=$G$5,"POS","NEG")) -> NEG | H22: =IF(AND(E22="NEG",G22="NEG"),"N",IF(E22="POS","P",IF(G22="POS","P",""))) -> N | I22: =IF(ECHANTILLONS!D23="","",ECHANTILLONS!D23)
A23: S10 | B23: =IF(ECHANTILLONS!B24="","",ECHANTILLONS!B24) -> 847 | C23: =IF(ECHANTILLONS!C24="","",ECHANTILLONS!C24) -> 2502289 | D23: =IF('450-600 nm'!C29="","",'450-600 nm'!C29) -> 10.35461 | E23: =IF(D23="","",IF(D23>=$G$5,"POS","NEG")) -> NEG | F23: =IF('450-600 nm'!I29="","",'450-600 nm'!I29) -> 21.900945 | G23: =IF(F23="","",IF(F23>=$G$5,"POS","NEG")) -> NEG | H23: =IF(AND(E23="NEG",G23="NEG"),"N",IF(E23="POS","P",IF(G23="POS","P",""))) -> N | I23: =IF(ECHANTILLONS!D24="","",ECHANTILLONS!D24)
A24: S11 | B24: =IF(ECHANTILLONS!B25="","",ECHANTILLONS!B25) -> 848 | C24: =IF(ECHANTILLONS!C25="","",ECHANTILLONS!C25) -> 2500876 | D24: =IF('450-600 nm'!D29="","",'450-600 nm'!D29) -> 4.1134752 | E24: =IF(D24="","",IF(D24>=$G$5,"POS","NEG")) -> NEG | F24: =IF('450-600 nm'!J29="","",'450-600 nm'!J29) -> 16.060693 | G24: =IF(F24="","",IF(F24>=$G$5,"POS","NEG")) -> NEG | H24: =IF(AND(E24="NEG",G24="NEG"),"N",IF(E24="POS","P",IF(G24="POS","P",""))) -> N | I24: =IF(ECHANTILLONS!D25="","",ECHANTILLONS!D25)
A25: S12 | B25: =IF(ECHANTILLONS!B26="","",ECHANTILLONS!B26) -> 849 | C25: =IF(ECHANTILLONS!C26="","",ECHANTILLONS!C26) -> 2502361 | D25: =IF('450-600 nm'!E29="","",'450-600 nm'!E29) -> 1.7021277 | E25: =IF(D25="","",IF(D25>=$G$5,"POS","NEG")) -> NEG | F25: =IF('450-600 nm'!K29="","",'450-600 nm'!K29) -> 8.4454624 | G25: =IF(F25="","",IF(F25>=$G$5,"POS","NEG")) -> NEG | H25: =IF(AND(E25="NEG",G25="NEG"),"N",IF(E25="POS","P",IF(G25="POS","P",""))) -> N | I25: =IF(ECHANTILLONS!D26="","",ECHANTILLONS!D26)
A26: S13 | B26: =IF(ECHANTILLONS!B27="","",ECHANTILLONS!B27) -> 850 | C26: =IF(ECHANTILLONS!C27="","",ECHANTILLONS!C27) -> 2502677 | D26: =IF('450-600 nm'!F29="","",'450-600 nm'!F29) -> -5.248227 | E26: =IF(D26="","",IF(D26>=$G$5,"POS","NEG")) -> NEG | F26: =IF('450-600 nm'!L29="","",'450-600 nm'!L29) -> -6.4987117 | G26: =IF(F26="","",IF(F26>=$G$5,"POS","NEG")) -> NEG | H26: =IF(AND(E26="NEG",G26="NEG"),"N",IF(E26="POS","P",IF(G26="POS","P",""))) -> N | I26: =IF(ECHANTILLONS!D27="","",ECHANTILLONS!D27)
A27: S14 | B27: =IF(ECHANTILLONS!B28="","",ECHANTILLONS!B28) -> 851 | C27: =IF(ECHANTILLONS!C28="","",ECHANTILLONS!C28) -> 2503082 | D27: =IF('450-600 nm'!G29="","",'450-600 nm'!G29) -> -4.3971631 | E27: =IF(D27="","",IF(D27>=$G$5,"POS","NEG")) -> NEG | F27: =IF('450-600 nm'!M29="","",'450-600 nm'!M29) -> -6.2124248 | G27: =IF(F27="","",IF(F27>=$G$5,"POS","NEG")) -> NEG | H27: =IF(AND(E27="NEG",G27="NEG"),"N",IF(E27="POS","P",IF(G27="POS","P",""))) -> N | I27: =IF(ECHANTILLONS!D28="","",ECHANTILLONS!D28)
A28: S15 | B28: =IF(ECHANTILLONS!B29="","",ECHANTILLONS!B29) -> 852 | C28: =IF(ECHANTILLONS!C29="","",ECHANTILLONS!C29) -> 2503090 | D28: =IF('450-600 nm'!B30="","",'450-600 nm'!B30) -> 6.0992908 | E28: =IF(D28="","",IF(D28>=$G$5,"POS","NEG")) -> NEG | F28: =IF('450-600 nm'!H30="","",'450-600 nm'!H30) -> 14.686516 | G28: =IF(F28="","",IF(F28>=$G$5,"POS","NEG")) -> NEG | H28: =IF(AND(E28="NEG",G28="NEG"),"N",IF(E28="POS","P",IF(G28="POS","P",""))) -> N | I28: =IF(ECHANTILLONS!D29="","",ECHANTILLONS!D29)
A29: S16 | B29: =IF(ECHANTILLONS!B30="","",ECHANTILLONS!B30) -> 853 | C29: =IF(ECHANTILLONS!C30="","",ECHANTILLONS!C30) -> 2502265 | D29: =IF('450-600 nm'!C30="","",'450-600 nm'!C30) -> 28.368794 | E29: =IF(D29="","",IF(D29>=$G$5,"POS","NEG")) -> NEG | F29: =IF('450-600 nm'!I30="","",'450-600 nm'!I30) -> 28.256513 | G29: =IF(F29="","",IF(F29>=$G$5,"POS","NEG")) -> NEG | H29: =IF(AND(E29="NEG",G29="NEG"),"N",IF(E29="POS","P",IF(G29="POS","P",""))) -> N | I29: =IF(ECHANTILLONS!D30="","",ECHANTILLONS!D30)
A30: S17 | B30: =IF(ECHANTILLONS!B31="","",ECHANTILLONS!B31) -> 854 | C30: =IF(ECHANTILLONS!C31="","",ECHANTILLONS!C31) -> 2501302 | D30: =IF('450-600 nm'!D30="","",'450-600 nm'!D30) -> -1.1347518 | E30: =IF(D30="","",IF(D30>=$G$5,"POS","NEG")) -> NEG | F30: =IF('450-600 nm'!J30="","",'450-600 nm'!J30) -> 27.512167 | G30: =IF(F30="","",IF(F30>=$G$5,"POS","NEG")) -> NEG | H30: =IF(AND(E30="NEG",G30="NEG"),"N",IF(E30="POS","P",IF(G30="POS","P",""))) -> N | I30: =IF(ECHANTILLONS!D31="","",ECHANTILLONS!D31)
A31: S18 | B31: =IF(ECHANTILLONS!B32="","",ECHANTILLONS!B32) -> 855 | C31: =IF(ECHANTILLONS!C32="","",ECHANTILLONS!C32) -> 2501334 | D31: =IF('450-600 nm'!E30="","",'450-600 nm'!E30) -> 6.5248227 | E31: =IF(D31="","",IF(D31>=$G$5,"POS","NEG")) -> NEG | F31: =IF('450-600 nm'!K30="","",'450-600 nm'!K30) -> 21.729173 | G31: =IF(F31="","",IF(F31>=$G$5,"POS","NEG")) -> NEG | H31: =IF(AND(E31="NEG",G31="NEG"),"N",IF(E31="POS","P",IF(G31="POS","P",""))) -> N | I31: =IF(ECHANTILLONS!D32="","",ECHANTILLONS!D32)
A32: S19 | B32: =IF(ECHANTILLONS!B33="","",ECHANTILLONS!B33) -> 856 | C32: =IF(ECHANTILLONS!C33="","",ECHANTILLONS!C33) -> 2502209 | D32: =IF('450-600 nm'!F30="","",'450-600 nm'!F30) -> 0.70921986 | E32: =IF(D32="","",IF(D32>=$G$5,"POS","NEG")) -> NEG | F32: =IF('450-600 nm'!L30="","",'450-600 nm'!L30) -> -10.277698 | G32: =IF(F32="","",IF(F32>=$G$5,"POS","NEG")) -> NEG | H32: =IF(AND(E32="NEG",G32="NEG"),"N",IF(E32="POS","P",IF(G32="POS","P",""))) -> N | I32: =IF(ECHANTILLONS!D33="","",ECHANTILLONS!D33)
A33: S20 | B33: =IF(ECHANTILLONS!B34="","",ECHANTILLONS!B34) -> 857 | C33: =IF(ECHANTILLONS!C34="","",ECHANTILLONS!C34) -> 2500811 | D33: =IF('450-600 nm'!G30="","",'450-600 nm'!G30) -> 7.2340426 | E33: =IF(D33="","",IF(D33>=$G$5,"POS","NEG")) -> NEG | F33: =IF('450-600 nm'!M30="","",'450-600 nm'!M30) -> -6.6704838 | G33: =IF(F33="","",IF(F33>=$G$5,"POS","NEG")) -> NEG | H33: =IF(AND(E33="NEG",G33="NEG"),"N",IF(E33="POS","P",IF(G33="POS","P",""))) -> N | I33: =IF(ECHANTILLONS!D34="","",ECHANTILLONS!D34)
A34: S21 | B34: =IF(ECHANTILLONS!B35="","",ECHANTILLONS!B35) -> 858 | C34: =IF(ECHANTILLONS!C35="","",ECHANTILLONS!C35) -> 2500817 | D34: =IF('450-600 nm'!B31="","",'450-600 nm'!B31) -> 6.9503546 | E34: =IF(D34="","",IF(D34>=$G$5,"POS","NEG")) -> NEG | F34: =IF('450-600 nm'!H31="","",'450-600 nm'!H31) -> 25.164615 | G34: =IF(F34="","",IF(F34>=$G$5,"POS","NEG")) -> NEG | H34: =IF(AND(E34="NEG",G34="NEG"),"N",IF(E34="POS","P",IF(G34="POS","P",""))) -> N | I34: =IF(ECHANTILLONS!D35="","",ECHANTILLONS!D35)
A35: S22 | B35: =IF(ECHANTILLONS!B36="","",ECHANTILLONS!B36) -> 859 | C35: =IF(ECHANTILLONS!C36="","",ECHANTILLONS!C36) -> 2501996 | D35: =IF('450-600 nm'!C31="","",'450-600 nm'!C31) -> 7.6595745 | E35: =IF(D35="","",IF(D35>=$G$5,"POS","NEG")) -> NEG | F35: =IF('450-600 nm'!I31="","",'450-600 nm'!I31) -> 17.721157 | G35: =IF(F35="","",IF(F35>=$G$5,"POS","NEG")) -> NEG | H35: =IF(AND(E35="NEG",G35="NEG"),"N",IF(E35="POS","P",IF(G35="POS","P",""))) -> N | I35: =IF(ECHANTILLONS!D36="","",ECHANTILLONS!D36)
A36: S23 | B36: =IF(ECHANTILLONS!B37="","",ECHANTILLONS!B37) -> 860 | C36: =IF(ECHANTILLONS!C37="","",ECHANTILLONS!C37) -> 2501951 | D36: =IF('450-600 nm'!D31="","",'450-600 nm'!D31) -> 7.3758865 | E36: =IF(D36="","",IF(D36>=$G$5,"POS","NEG")) -> NEG | F36: =IF('450-600 nm'!J31="","",'450-600 nm'!J31) -> 23.790438 | G36: =IF(F36="","",IF(F36>=$G$5,"POS","NEG")) -> NEG | H36: =IF(AND(E36="NEG",G36="NEG"),"N",IF(E36="POS","P",IF(G36="POS","P",""))) -> N | I36: =IF(ECHANTILLONS!D37="","",ECHANTILLONS!D37)
A37: S24 | B37: =IF(ECHANTILLONS!B38="","",ECHANTILLONS!B38) -> 861 | C37: =IF(ECHANTILLONS!C38="","",ECHANTILLONS!C38) -> 2501948 | D37: =IF('450-600 nm'!E31="","",'450-600 nm'!E31) -> 2.1276596 | E37: =IF(D37="","",IF(D37>=$G$5,"POS","NEG")) -> NEG | F37: =IF('450-600 nm'!K31="","",'450-600 nm'!K31) -> 21.442886 | G37: =IF(F37="","",IF(F37>=$G$5,"POS","NEG")) -> NEG | H37: =IF(AND(E37="NEG",G37="NEG"),"N",IF(E37="POS","P",IF(G37="POS","P",""))) -> N | I37: =IF(ECHANTILLONS!D38="","",ECHANTILLONS!D38)
A38: S25 | B38: =IF(ECHANTILLONS!B39="","",ECHANTILLONS!B39) -> 862 | C38: =IF(ECHANTILLONS!C39="","",ECHANTILLONS!C39) -> 2500076 | D38: =IF('450-600 nm'!F31="","",'450-600 nm'!F31) -> 13.049645 | E38: =IF(D38="","",IF(D38>=$G$5,"POS","NEG")) -> NEG | F38: =IF('450-600 nm'!L31="","",'450-600 nm'!L31) -> 18.980819 | G38: =IF(F38="","",IF(F38>=$G$5,"POS","NEG")) -> NEG | H38: =IF(AND(E38="NEG",G38="NEG"),"N",IF(E38="POS","P",IF(G38="POS","P",""))) -> N | I38: =IF(ECHANTILLONS!D39="","",ECHANTILLONS!D39)
A39: S26 | B39: =IF(ECHANTILLONS!B40="","",ECHANTILLONS!B40) -> 863 | C39: =IF(ECHANTILLONS!C40="","",ECHANTILLONS!C40) -> 2500077 | D39: =IF('450-600 nm'!G31="","",'450-600 nm'!G31) -> 13.191489 | E39: =IF(D39="","",IF(D39>=$G$5,"POS","NEG")) -> NEG | F39: =IF('450-600 nm'!M31="","",'450-600 nm'!M31) -> 36.38706 | G39: =IF(F39="","",IF(F39>=$G$5,"POS","NEG")) -> POS | H39: =IF(AND(E39="NEG",G39="NEG"),"N",IF(E39="POS","P",IF(G39="POS","P",""))) -> P | I39: =IF(ECHANTILLONS!D40="","",ECHANTILLONS!D40)
A40: S27 | B40: =IF(ECHANTILLONS!B41="","",ECHANTILLONS!B41) -> 864 | C40: =IF(ECHANTILLONS!C41="","",ECHANTILLONS!C41) -> 2502080 | D40: =IF('450-600 nm'!B32="","",'450-600 nm'!B32) -> -9.3617021 | E40: =IF(D40="","",IF(D40>=$G$5,"POS","NEG")) -> NEG | F40: =IF('450-600 nm'!H32="","",'450-600 nm'!H32) -> 15.25909 | G40: =IF(F40="","",IF(F40>=$G$5,"POS","NEG")) -> NEG | H40: =IF(AND(E40="NEG",G40="NEG"),"N",IF(E40="POS","P",IF(G40="POS","P",""))) -> N | I40: =IF(ECHANTILLONS!D41="","",ECHANTILLONS!D41)
A41: S28 | B41: =IF(ECHANTILLONS!B42="","",ECHANTILLONS!B42) -> 865 | C41: =IF(ECHANTILLONS!C42="","",ECHANTILLONS!C42) -> 2502098 | D41: =IF('450-600 nm'!C32="","",'450-600 nm'!C32) -> -15.177305 | E41: =IF(D41="","",IF(D41>=$G$5,"POS","NEG")) -> NEG | F41: =IF('450-600 nm'!I32="","",'450-600 nm'!I32) -> 19.209848 | G41: =IF(F41="","",IF(F41>=$G$5,"POS","NEG")) -> NEG | H41: =IF(AND(E41="NEG",G41="NEG"),"N",IF(E41="POS","P",IF(G41="POS","P",""))) -> N | I41: =IF(ECHANTILLONS!D42="","",ECHANTILLONS!D42)
A42: S29 | B42: =IF(ECHANTILLONS!B43="","",ECHANTILLONS!B43) -> 866 | C42: =IF(ECHANTILLONS!C43="","",ECHANTILLONS!C43) -> 2501934 | D42: =IF('450-600 nm'!D32="","",'450-600 nm'!D32) -> -17.446809 | E42: =IF(D42="","",IF(D42>=$G$5,"POS","NEG")) -> NEG | F42: =IF('450-600 nm'!J32="","",'450-600 nm'!J32) -> 18.121958 | G42: =IF(F42="","",IF(F42>=$G$5,"POS","NEG")) -> NEG | H42: =IF(AND(E42="NEG",G42="NEG"),"N",IF(E42="POS","P",IF(G42="POS","P",""))) -> N | I42: =IF(ECHANTILLONS!D43="","",ECHANTILLONS!D43)
A43: S30 | B43: =IF(ECHANTILLONS!B44="","",ECHANTILLONS!B44) -> 867 | C43: =IF(ECHANTILLONS!C44="","",ECHANTILLONS!C44) -> 2501989 | D43: =IF('450-600 nm'!E32="","",'450-600 nm'!E32) -> -14.609929 | E43: =IF(D43="","",IF(D43>=$G$5,"POS","NEG")) -> NEG | F43: =IF('450-600 nm'!K32="","",'450-600 nm'!K32) -> 12.567993 | G43: =IF(F43="","",IF(F43>=$G$5,"POS","NEG")) -> NEG | H43: =IF(AND(E43="NEG",G43="NEG"),"N",IF(E43="POS","P",IF(G43="POS","P",""))) -> N | I43: =IF(ECHANTILLONS!D44="","",ECHANTILLONS!D44)
A44: S31 | B44: =IF(ECHANTILLONS!B45="","",ECHANTILLONS!B45) -> 868 | C44: =IF(ECHANTILLONS!C45="","",ECHANTILLONS!C45) -> 2502079 | D44: =IF('450-600 nm'!F32="","",'450-600 nm'!F32) -> -10.780142 | E44: =IF(D44="","",IF(D44>=$G$5,"POS","NEG")) -> NEG | F44: =IF('450-600 nm'!L32="","",'450-600 nm'!L32) -> 13.999427 | G44: =IF(F44="","",IF(F44>=$G$5,"POS","NEG")) -> NEG | H44: =IF(AND(E44="NEG",G44="NEG"),"N",IF(E44="POS","P",IF(G44="POS","P",""))) -> N | I44: =IF(ECHANTILLONS!D45="","",ECHANTILLONS!D45)
...
