Workbook

Sheet 177T
A1: Well | B1: Sample | C1: Cq | D1: Efficiency | E1: R² | F1: Result
A2: 1 | B2: 276 | C2: -1 | D2: -1 | F2: Excluded
A3: 2 | B3: 276 | C3: -1 | D3: -1 | F3: Excluded
A4: 3 | B4: 276 | C4: -1 | D4: -1 | F4: Excluded
A5: 4 | B5: 276 | C5: -1 | D5: -1 | F5: Excluded
A6: 5 | B6: 277 | C6: -1 | D6: -1 | F6: Excluded
A7: 6 | B7: 277 | C7: -1 | D7: -1 | F7: Excluded
A8: 7 | B8: 277 | C8: -1 | D8: -1 | F8: Excluded
A9: 8 | B9: 277 | C9: -1 | D9: -1 | F9: Excluded
A10: 9 | B10: 278 | C10: 31.57731 | D10: 0.65806351 | E10: 0.9996
A11: 10 | B11: 278 | C11: 31.181764 | D11: 0.69621313 | E11: 0.99971
A12: 11 | B12: 278 | C12: 32.143864 | D12: 0.67601901 | E12: 0.99974
A13: 12 | B13: 278 | C13: 32.316778 | D13: 0.68755572 | E13: 0.99782
A14: 13 | B14: 279 | C14: 28.571002 | D14: 0.75359656 | E14: 0.9999
A15: 14 | B15: 279 | C15: 28.822924 | D15: 0.70900513 | E15: 0.99975
A16: 15 | B16: 279 | C16: 28.110237 | D16: 0.72267504 | E16: 0.99981
A17: 16 | B17: 279 | C17: 28.837593 | D17: 0.70139406 | E17: 0.99984
A18: 17 | B18: 280 | C18: -1 | D18: -1 | F18: Excluded
A19: 18 | B19: 280 | C19: -1 | D19: -1 | F19: Excluded
A20: 19 | B20: 280 | C20: -1 | D20: -1 | F20: Excluded
A21: 20 | B21: 280 | C21: -1 | D21: -1 | F21: Excluded
A22: 21 | B22: 281 | C22: -1 | D22: -1 | F22: Excluded
A23: 22 | B23: 281 | C23: -1 | D23: -1 | F23: Excluded
A24: 23 | B24: 281 | C24: -1 | D24: -1 | F24: Excluded
A25: 24 | B25: 281 | C25: -1 | D25: -1 | F25: Excluded
A26: 25 | B26: 282 | C26: -1 | D26: -1 | F26: Excluded
A27: 26 | B27: 282 | C27: -1 | D27: -1 | F27: Excluded
A28: 27 | B28: 282 | C28: -1 | D28: -1 | F28: Excluded
A29: 28 | B29: 282 | C29: -1 | D29: -1 | F29: Excluded
... A41: 40 | B41: 285 | C41: -1 | D41: -1 | F41: Excluded
A42: 41 | B42: CP | C42: 21.300006 | D42: 0.84215824 | E42: 0.99999
A43: 42 | B43: CP | C43: 21.098586 | D43: 1.0140537 | E43: 0.99913
A44: 43 | B44: CP | C44: 22.76576 | D44: 0.87790007 | E44: 0.99971
A45: 44 | B45: CP | C45: 21.521545 | D45: 0.79923134 | E45: 0.99964
A46: 45 | B46: CN | C46: -1 | D46: -1 | F46: Excluded
A47: 46 | B47: CN | C47: -1 | D47: -1 | F47: Excluded
A48: 47 | B48: CN | C48: -1 | D48: -1 | F48: Excluded
A49: 48 | B49: CN | C49: -1 | D49: -1 | F49: Excluded

Sheet 18S2
A1: Well | B1: Sample | C1: Cq | D1: Efficiency | E1: R² | F1: Result
A2: 1 | B2: 276 | C2: -1 | D2: -1 | F2: Excluded
A3: 2 | B3: 276 | C3: -1 | D3: -1 | F3: Excluded
A4: 3 | B4: 276 | C4: -1 | D4: -1 | F4: Excluded
A5: 4 | B5: 276 | C5: -1 | D5: -1 | F5: Excluded
A6: 5 | B6: 277 | C6: -1 | D6: -1 | F6: Excluded
A7: 6 | B7: 277 | C7: -1 | D7: -1 | F7: Excluded
A8: 7 | B8: 277 | C8: -1 | D8: -1 | F8: Excluded
A9: 8 | B9: 277 | C9: -1 | D9: -1 | F9: Excluded
A10: 9 | B10: 278 | C10: 37.992424 | D10: 0.39801939 | E10: 0.99018
A11: 10 | B11: 278 | C11: -1 | D11: -1 | F11: Excluded
A12: 11 | B12: 278 | C12: 36.069112 | D12: 0.57547296 | E12: 0.99665
A13: 12 | B13: 278 | C13: -1 | D13: -1 | F13: Excluded
A14: 13 | B14: 279 | C14: 36.039407 | D14: 0.47692094 | E14: 0.99865
A15: 14 | B15: 279 | C15: -1 | D15: -1 | F15: Excluded
A16: 15 | B16: 279 | C16: -1 | D16: -1 | F16: Excluded
A17: 16 | B17: 279 | C17: 36.953018 | D17: 0.40971752 | E17: 0.99862
A18: 17 | B18: 280 | C18: -1 | D18: -1 | F18: Excluded
A19: 18 | B19: 280 | C19: -1 | D19: -1 | F19: Excluded
A20: 19 | B20: 280 | C20: -1 | D20: -1 | F20: Excluded
A21: 20 | B21: 280 | C21: -1 | D21: -1 | F21: Excluded
A22: 21 | B22: 281 | C22: -1 | D22: -1 | F22: Excluded
A23: 22 | B23: 281 | C23: -1 | D23: -1 | F23: Excluded
A24: 23 | B24: 281 | C24: -1 | D24: -1 | F24: Excluded
A25: 24 | B25: 281 | C25: -1 | D25: -1 | F25: Excluded
A26: 25 | B26: 282 | C26: -1 | D26: -1 | F26: Excluded
A27: 26 | B27: 282 | C27: -1 | D27: -1 | F27: Excluded
A28: 27 | B28: 282 | C28: -1 | D28: -1 | F28: Excluded
A29: 28 | B29: 282 | C29: -1 | D29: -1 | F29: Excluded
... A41: 40 | B41: 285 | C41: -1 | D41: -1 | F41: Excluded
A42: 41 | B42: CP | C42: 19.311493 | D42: 0.94018995 | E42: 0.99904
A43: 42 | B43: CP | C43: 19.138809 | D43: 0.96409682 | E43: 0.99839
A44: 43 | B44: CP | C44: 19.773424 | D44: 0.98742652 | E44: 0.99865
A45: 44 | B45: CP | C45: 19.811099 | D45: 0.96836309 | E45: 0.99883
A46: 45 | B46: CN | C46: -1 | D46: -1 | F46: Excluded
A47: 46 | B47: CN | C47: -1 | D47: -1 | F47: Excluded
A48: 47 | B48: CN | C48: -1 | D48: -1 | F48: Excluded
A49: 48 | B49: CN | C49: -1 | D49: -1 | F49: Excluded

Sheet RNAseP
A1: Well | B1: Sample | C1: Cq | D1: Efficiency | E1: R² | F1: Result
A2: 1 | B2: 276 | C2: 21.36346 | D2: 0.90843824 | E2: 0.99975
A3: 2 | B3: 276 | C3: 21.346938 | D3: 0.95603961 | E3: 0.99949
A4: 3 | B4: 276 | C4: 21.344152 | D4: 0.95790413 | E4: 0.99949
A5: 4 | B5: 276 | C5: 21.342432 | D5: 0.95370983 | E5: 0.99952
A6: 5 | B6: 277 | C6: 23.60286 | D6: 0.87737146 | E6: 0.99989
A7: 6 | B7: 277 | C7: 23.590057 | D7: 0.93528291 | E7: 0.99969
A8: 7 | B8: 277 | C8: 23.676463 | D8: 0.90387678 | E8: 0.99976
A9: 8 | B9: 277 | C9: 23.700155 | D9: 0.89332949 | E9: 0.99973
A10: 9 | B10: 278 | C10: 25.711903 | D10: 0.91321827 | E10: 0.99969
A11: 10 | B11: 278 | C11: 25.790695 | D11: 0.89155056 | E11: 0.99977
A12: 11 | B12: 278 | C12: 25.783214 | D12: 0.91548831 | E12: 0.99963
A13: 12 | B13: 278 | C13: 25.785934 | D13: 0.93735945 | E13: 0.99953
... A41: 40 | B41: 285 | C41: 21.907739 | D41: 0.77762559 | E41: 0.99999
A42: 41 | B42: CP | C42: 33.828497 | D42: 0.66083443 | E42: 0.99981
A43: 42 | B43: CP | C43: 33.474039 | D43: 0.69629806 | E43: 0.99964
A44: 43 | B44: CP | C44: 34.266779 | D44: 0.68475944 | E44: 0.99964
A45: 44 | B45: CP | C45: 34.574612 | D45: 0.63861062 | E45: 0.99969
A46: 45 | B46: CN | C46: 37.939379 | D46: 0.71756543 | E46: 0.99616
A47: 46 | B47: CN | C47: 37.779384 | D47: 0.49379895 | E47: 0.97529
A48: 47 | B48: CN | C48: -1 | D48: -1 | F48: Excluded
A49: 48 | B49: CN | C49: -1 | D49: -1 | F49: Excluded

Sheet Analysis
A1: Sample | B1: 177T | C1: 18S2 | D1: RNAseP | E1: 177T | F1: 18S2 | G1: RNaseP | H1: Decision | I1: Remark
A2: =IF(AND('177T'!B2 = '18S2'!B2, '177T'!B2 = RNAseP!B2, '177T'!B2 <> ""), '177T'!B2, IF('177T'!B2 = "", "", "Mismatch")) -> 276 | B2: =IF('177T'!C2="", "", '177T'!C2) -> -1 | C2: =IF('18S2'!C2="", "", '18S2'!C2) -> -1 | D2: =IF(RNAseP!C2="", "", RNAseP!C2) -> 21.36346 | E2: =IF(B2=-1, "-1", IF(B2<VLOOKUP("177T", Cutoff!$A$1:$B$4, 2, FALSE), "1", "0")) -> -1 | F2: =IF(C2=-1, "-1", IF(C2<VLOOKUP("18S2", Cutoff!$A$1:$B$4, 2, FALSE), "1", "0")) -> -1 | G2: =IF(D2=-1, "-1", IF(D2<VLOOKUP("RNAseP", Cutoff!$A$1:$B$4, 2, FALSE), "1", "0")) -> 1 | H2: {=INDEX(Decision!$D$1:$D$28, MATCH(E2&F2&G2, Decision!$A$1:$A$28&Decision!$B$1:$B$28&Decision!$C$1:$C$28, 0))} -> N | I2: {=INDEX(Decision!$E$1:$E$28, MATCH(E2&F2&G2, Decision!$A$1:$A$28&Decision!$B$1:$B$28&Decision!$C$1:$C$28, 0))} -> negative
A3: =IF(AND('177T'!B3 = '18S2'!B3, '177T'!B3 = RNAseP!B3, '177T'!B3 <> ""), '177T'!B3, IF('177T'!B3 = "", "", "Mismatch")) -> 276 | B3: =IF('177T'!C3="", "", '177T'!C3) -> -1 | C3: =IF('18S2'!C3="", "", '18S2'!C3) -> -1 | D3: =IF(RNAseP!C3="", "", RNAseP!C3) -> 21.346938 | E3: =IF(B3=-1, "-1", IF(B3<VLOOKUP("177T", Cutoff!$A$1:$B$4, 2, FALSE), "1", "0")) -> -1 | F3: =IF(C3=-1, "-1", IF(C3<VLOOKUP("18S2", Cutoff!$A$1:$B$4, 2, FALSE), "1", "0")) -> -1 | G3: =IF(D3=-1, "-1", IF(D3<VLOOKUP("RNAseP", Cutoff!$A$1:$B$4, 2, FALSE), "1", "0")) -> 1 | H3: {=INDEX(Decision!$D$1:$D$28, MATCH(E3&F3&G3, Decision!$A$1:$A$28&Decision!$B$1:$B$28&Decision!$C$1:$C$28, 0))} -> N | I3: {=INDEX(Decision!$E$1:$E$28, MATCH(E3&F3&G3, Decision!$A$1:$A$28&Decision!$B$1:$B$28&Decision!$C$1:$C$28, 0))} -> negative
A4: =IF(AND('177T'!B4 = '18S2'!B4, '177T'!B4 = RNAseP!B4, '177T'!B4 <> ""), '177T'!B4, IF('177T'!B4 = "", "", "Mismatch")) -> 276 | B4: =IF('177T'!C4="", "", '177T'!C4) -> -1 | C4: =IF('18S2'!C4="", "", '18S2'!C4) -> -1 | D4: =IF(RNAseP!C4="", "", RNAseP!C4) -> 21.344152 | E4: =IF(B4=-1, "-1", IF(B4<VLOOKUP("177T", Cutoff!$A$1:$B$4, 2, FALSE), "1", "0")) -> -1 | F4: =IF(C4=-1, "-1", IF(C4<VLOOKUP("18S2", Cutoff!$A$1:$B$4, 2, FALSE), "1", "0")) -> -1 | G4: =IF(D4=-1, "-1", IF(D4<VLOOKUP("RNAseP", Cutoff!$A$1:$B$4, 2, FALSE), "1", "0")) -> 1 | H4: {=INDEX(Decision!$D$1:$D$28, MATCH(E4&F4&G4, Decision!$A$1:$A$28&Decision!$B$1:$B$28&Decision!$C$1:$C$28, 0))} -> N | I4: {=INDEX(Decision!$E$1:$E$28, MATCH(E4&F4&G4, Decision!$A$1:$A$28&Decision!$B$1:$B$28&Decision!$C$1:$C$28, 0))} -> negative
A5: =IF(AND('177T'!B5 = '18S2'!B5, '177T'!B5 = RNAseP!B5, '177T'!B5 <> ""), '177T'!B5, IF('177T'!B5 = "", "", "Mismatch")) -> 276 | B5: =IF('177T'!C5="", "", '177T'!C5) -> -1 | C5: =IF('18S2'!C5="", "", '18S2'!C5) -> -1 | D5: =IF(RNAseP!C5="", "", RNAseP!C5) -> 21.342432 | E5: =IF(B5=-1, "-1", IF(B5<VLOOKUP("177T", Cutoff!$A$1:$B$4, 2, FALSE), "1", "0")) -> -1 | F5: =IF(C5=-1, "-1", IF(C5<VLOOKUP("18S2", Cutoff!$A$1:$B$4, 2, FALSE), "1", "0")) -> -1 | G5: =IF(D5=-1, "-1", IF(D5<VLOOKUP("RNAseP", Cutoff!$A$1:$B$4, 2, FALSE), "1", "0")) -> 1 | H5: {=INDEX(Decision!$D$1:$D$28, MATCH(E5&F5&G5, Decision!$A$1:$A$28&Decision!$B$1:$B$28&Decision!$C$1:$C$28, 0))} -> N | I5: {=INDEX(Decision!$E$1:$E$28, MATCH(E5&F5&G5, Decision!$A$1:$A$28&Decision!$B$1:$B$28&Decision!$C$1:$C$28, 0))} -> negative
A6: =IF(AND('177T'!B6 = '18S2'!B6, '177T'!B6 = RNAseP!B6, '177T'!B6 <> ""), '177T'!B6, IF('177T'!B6 = "", "", "Mismatch")) -> 277 | B6: =IF('177T'!C6="", "", '177T'!C6) -> -1 | C6: =IF('18S2'!C6="", "", '18S2'!C6) -> -1 | D6: =IF(RNAseP!C6="", "", RNAseP!C6) -> 23.60286 | E6: =IF(B6=-1, "-1", IF(B6<VLOOKUP("177T", Cutoff!$A$1:$B$4, 2, FALSE), "1", "0")) -> -1 | F6: =IF(C6=-1, "-1", IF(C6<VLOOKUP("18S2", Cutoff!$A$1:$B$4, 2, FALSE), "1", "0")) -> -1 | G6: =IF(D6=-1, "-1", IF(D6<VLOOKUP("RNAseP", Cutoff!$A$1:$B$4, 2, FALSE), "1", "0")) -> 1 | H6: {=INDEX(Decision!$D$1:$D$28, MATCH(E6&F6&G6, Decision!$A$1:$A$28&Decision!$B$1:$B$28&Decision!$C$1:$C$28, 0))} -> N | I6: {=INDEX(Decision!$E$1:$E$28, MATCH(E6&F6&G6, Decision!$A$1:$A$28&Decision!$B$1:$B$28&Decision!$C$1:$C$28, 0))} -> negative
A7: =IF(AND('177T'!B7 = '18S2'!B7, '177T'!B7 = RNAseP!B7, '177T'!B7 <> ""), '177T'!B7, IF('177T'!B7 = "", "", "Mismatch")) -> 277 | B7: =IF('177T'!C7="", "", '177T'!C7) -> -1 | C7: =IF('18S2'!C7="", "", '18S2'!C7) -> -1 | D7: =IF(RNAseP!C7="", "", RNAseP!C7) -> 23.590057 | E7: =IF(B7=-1, "-1", IF(B7<VLOOKUP("177T", Cutoff!$A$1:$B$4, 2, FALSE), "1", "0")) -> -1 | F7: =IF(C7=-1, "-1", IF(C7<VLOOKUP("18S2", Cutoff!$A$1:$B$4, 2, FALSE), "1", "0")) -> -1 | G7: =IF(D7=-1, "-1", IF(D7<VLOOKUP("RNAseP", Cutoff!$A$1:$B$4, 2, FALSE), "1", "0")) -> 1 | H7: {=INDEX(Decision!$D$1:$D$28, MATCH(E7&F7&G7, Decision!$A$1:$A$28&Decision!$B$1:$B$28&Decision!$C$1:$C$28, 0))} -> N | I7: {=INDEX(Decision!$E$1:$E$28, MATCH(E7&F7&G7, Decision!$A$1:$A$28&Decision!$B$1:$B$28&Decision!$C$1:$C$28, 0))} -> negative
A8: =IF(AND('177T'!B8 = '18S2'!B8, '177T'!B8 = RNAseP!B8, '177T'!B8 <> ""), '177T'!B8, IF('177T'!B8 = "", "", "Mismatch")) -> 277 | B8: =IF('177T'!C8="", "", '177T'!C8) -> -1 | C8: =IF('18S2'!C8="", "", '18S2'!C8) -> -1 | D8: =IF(RNAseP!C8="", "", RNAseP!C8) -> 23.676463 | E8: =IF(B8=-1, "-1", IF(B8<VLOOKUP("177T", Cutoff!$A$1:$B$4, 2, FALSE), "1", "0")) -> -1 | F8: =IF(C8=-1, "-1", IF(C8<VLOOKUP("18S2", Cutoff!$A$1:$B$4, 2, FALSE), "1", "0")) -> -1 | G8: =IF(D8=-1, "-1", IF(D8<VLOOKUP("RNAseP", Cutoff!$A$1:$B$4, 2, FALSE), "1", "0")) -> 1 | H8: {=INDEX(Decision!$D$1:$D$28, MATCH(E8&F8&G8, Decision!$A$1:$A$28&Decision!$B$1:$B$28&Decision!$C$1:$C$28, 0))} -> N | I8: {=INDEX(Decision!$E$1:$E$28, MATCH(E8&F8&G8, Decision!$A$1:$A$28&Decision!$B$1:$B$28&Decision!$C$1:$C$28, 0))} -> negative
A9: =IF(AND('177T'!B9 = '18S2'!B9, '177T'!B9 = RNAseP!B9, '177T'!B9 <> ""), '177T'!B9, IF('177T'!B9 = "", "", "Mismatch")) -> 277 | B9: =IF('177T'!C9="", "", '177T'!C9) -> -1 | C9: =IF('18S2'!C9="", "", '18S2'!C9) -> -1 | D9: =IF(RNAseP!C9="", "", RNAseP!C9) -> 23.700155 | E9: =IF(B9=-1, "-1", IF(B9<VLOOKUP("177T", Cutoff!$A$1:$B$4, 2, FALSE), "1", "0")) -> -1 | F9: =IF(C9=-1, "-1", IF(C9<VLOOKUP("18S2", Cutoff!$A$1:$B$4, 2, FALSE), "1", "0")) -> -1 | G9: =IF(D9=-1, "-1", IF(D9<VLOOKUP("RNAseP", Cutoff!$A$1:$B$4, 2, FALSE), "1", "0")) -> 1 | H9: {=INDEX(Decision!$D$1:$D$28, MATCH(E9&F9&G9, Decision!$A$1:$A$28&Decision!$B$1:$B$28&Decision!$C$1:$C$28, 0))} -> N | I9: {=INDEX(Decision!$E$1:$E$28, MATCH(E9&F9&G9, Decision!$A$1:$A$28&Decision!$B$1:$B$28&Decision!$C$1:$C$28, 0))} -> negative
A10: =IF(AND('177T'!B10 = '18S2'!B10, '177T'!B10 = RNAseP!B10, '177T'!B10 <> ""), '177T'!B10, IF('177T'!B10 = "", "", "Mismatch")) -> 278 | B10: =IF('177T'!C10="", "", '177T'!C10) -> 31.57731 | C10: =IF('18S2'!C10="", "", '18S2'!C10) -> 37.992424 | D10: =IF(RNAseP!C10="", "", RNAseP!C10) -> 25.711903 | E10: =IF(B10=-1, "-1", IF(B10<VLOOKUP("177T", Cutoff!$A$1:$B$4, 2, FALSE), "1", "0")) -> 1 | F10: =IF(C10=-1, "-1", IF(C10<VLOOKUP("18S2", Cutoff!$A$1:$B$4, 2, FALSE), "1", "0")) -> 0 | G10: =IF(D10=-1, "-1", IF(D10<VLOOKUP("RNAseP", Cutoff!$A$1:$B$4, 2, FALSE), "1", "0")) -> 1 | H10: {=INDEX(Decision!$D$1:$D$28, MATCH(E10&F10&G10, Decision!$A$1:$A$28&Decision!$B$1:$B$28&Decision!$C$1:$C$28, 0))} -> P | I10: {=INDEX(Decision!$E$1:$E$28, MATCH(E10&F10&G10, Decision!$A$1:$A$28&Decision!$B$1:$B$28&Decision!$C$1:$C$28, 0))} -> DNA case & RNA suspect
A11: =IF(AND('177T'!B11 = '18S2'!B11, '177T'!B11 = RNAseP!B11, '177T'!B11 <> ""), '177T'!B11, IF('177T'!B11 = "", "", "Mismatch")) -> 278 | B11: =IF('177T'!C11="", "", '177T'!C11) -> 31.181764 | C11: =IF('18S2'!C11="", "", '18S2'!C11) -> -1 | D11: =IF(RNAseP!C11="", "", RNAseP!C11) -> 25.790695 | E11: =IF(B11=-1, "-1", IF(B11<VLOOKUP("177T", Cutoff!$A$1:$B$4, 2, FALSE), "1", "0")) -> 1 | F11: =IF(C11=-1, "-1", IF(C11<VLOOKUP("18S2", Cutoff!$A$1:$B$4, 2, FALSE), "1", "0")) -> -1 | G11: =IF(D11=-1, "-1", IF(D11<VLOOKUP("RNAseP", Cutoff!$A$1:$B$4, 2, FALSE), "1", "0")) -> 1 | H11: {=INDEX(Decision!$D$1:$D$28, MATCH(E11&F11&G11, Decision!$A$1:$A$28&Decision!$B$1:$B$28&Decision!$C$1:$C$28, 0))} -> P | I11: {=INDEX(Decision!$E$1:$E$28, MATCH(E11&F11&G11, Decision!$A$1:$A$28&Decision!$B$1:$B$28&Decision!$C$1:$C$28, 0))} -> DNA case
A12: =IF(AND('177T'!B12 = '18S2'!B12, '177T'!B12 = RNAseP!B12, '177T'!B12 <> ""), '177T'!B12, IF('177T'!B12 = "", "", "Mismatch")) -> 278 | B12: =IF('177T'!C12="", "", '177T'!C12) -> 32.143864 | C12: =IF('18S2'!C12="", "", '18S2'!C12) -> 36.069112 | D12: =IF(RNAseP!C12="", "", RNAseP!C12) -> 25.783214 | E12: =IF(B12=-1, "-1", IF(B12<VLOOKUP("177T", Cutoff!$A$1:$B$4, 2, FALSE), "1", "0")) -> 1 | F12: =IF(C12=-1, "-1", IF(C12<VLOOKUP("18S2", Cutoff!$A$1:$B$4, 2, FALSE), "1", "0")) -> 0 | G12: =IF(D12=-1, "-1", IF(D12<VLOOKUP("RNAseP", Cutoff!$A$1:$B$4, 2, FALSE), "1", "0")) -> 1 | H12: {=INDEX(Decision!$D$1:$D$28, MATCH(E12&F12&G12, Decision!$A$1:$A$28&Decision!$B$1:$B$28&Decision!$C$1:$C$28, 0))} -> P | I12: {=INDEX(Decision!$E$1:$E$28, MATCH(E12&F12&G12, Decision!$A$1:$A$28&Decision!$B$1:$B$28&Decision!$C$1:$C$28, 0))} -> DNA case & RNA suspect
A13: =IF(AND('177T'!B13 = '18S2'!B13, '177T'!B13 = RNAseP!B13, '177T'!B13 <> ""), '177T'!B13, IF('177T'!B13 = "", "", "Mismatch")) -> 278 | B13: =IF('177T'!C13="", "", '177T'!C13) -> 32.316778 | C13: =IF('18S2'!C13="", "", '18S2'!C13) -> -1 | D13: =IF(RNAseP!C13="", "", RNAseP!C13) -> 25.785934 | E13: =IF(B13=-1, "-1", IF(B13<VLOOKUP("177T", Cutoff!$A$1:$B$4, 2, FALSE), "1", "0")) -> 1 | F13: =IF(C13=-1, "-1", IF(C13<VLOOKUP("18S2", Cutoff!$A$1:$B$4, 2, FALSE), "1", "0")) -> -1 | G13: =IF(D13=-1, "-1", IF(D13<VLOOKUP("RNAseP", Cutoff!$A$1:$B$4, 2, FALSE), "1", "0")) -> 1 | H13: {=INDEX(Decision!$D$1:$D$28, MATCH(E13&F13&G13, Decision!$A$1:$A$28&Decision!$B$1:$B$28&Decision!$C$1:$C$28, 0))} -> P | I13: {=INDEX(Decision!$E$1:$E$28, MATCH(E13&F13&G13, Decision!$A$1:$A$28&Decision!$B$1:$B$28&Decision!$C$1:$C$28, 0))} -> DNA case
... A41: =IF(AND('177T'!B41 = '18S2'!B41, '177T'!B41 = RNAseP!B41, '177T'!B41 <> ""), '177T'!B41, IF('177T'!B41 = "", "", "Mismatch")) -> 285 | B41: =IF('177T'!C41="", "", '177T'!C41) -> -1 | C41: =IF('18S2'!C41="", "", '18S2'!C41) -> -1 | D41: =IF(RNAseP!C41="", "", RNAseP!C41) -> 21.907739 | E41: =IF(B41=-1, "-1", IF(B41<VLOOKUP("177T", Cutoff!$A$1:$B$4, 2, FALSE), "1", "0")) -> -1 | F41: =IF(C41=-1, "-1", IF(C41<VLOOKUP("18S2", Cutoff!$A$1:$B$4, 2, FALSE), "1", "0")) -> -1 | G41: =IF(D41=-1, "-1", IF(D41<VLOOKUP("RNAseP", Cutoff!$A$1:$B$4, 2, FALSE), "1", "0")) -> 1 | H41: {=INDEX(Decision!$D$1:$D$28, MATCH(E41&F41&G41, Decision!$A$1:$A$28&Decision!$B$1:$B$28&Decision!$C$1:$C$28, 0))} -> N | I41: {=INDEX(Decision!$E$1:$E$28, MATCH(E41&F41&G41, Decision!$A$1:$A$28&Decision!$B$1:$B$28&Decision!$C$1:$C$28, 0))} -> negative
A42: =IF(AND('177T'!B42 = '18S2'!B42, '177T'!B42 = RNAseP!B42, '177T'!B42 <> ""), '177T'!B42, IF('177T'!B42 = "", "", "Mismatch")) -> CP | B42: =IF('177T'!C42="", "", '177T'!C42) -> 21.300006 | C42: =IF('18S2'!C42="", "", '18S2'!C42) -> 19.311493 | D42: =IF(RNAseP!C42="", "", RNAseP!C42) -> 33.828497 | E42: =IF(B42=-1, "-1", IF(B42<VLOOKUP("177T", Cutoff!$A$1:$B$4, 2, FALSE), "1", "0")) -> 1 | F42: =IF(C42=-1, "-1", IF(C42<VLOOKUP("18S2", Cutoff!$A$1:$B$4, 2, FALSE), "1", "0")) -> 1 | G42: =IF(D42=-1, "-1", IF(D42<VLOOKUP("RNAseP", Cutoff!$A$1:$B$4, 2, FALSE), "1", "0")) -> 0 | H42: {=INDEX(DecisionC!$E$1:$E$56, MATCH(A42&E42&F42&G42, DecisionC!$A$1:$A$56&DecisionC!$B$1:$B$56&DecisionC!$C$1:$C$56&DecisionC!$D$1:$D$56, 0))} -> OK | I42: {=INDEX(DecisionC!$F$1:$F$56, MATCH(A42&E42&F42&G42, DecisionC!$A$1:$A$56&DecisionC!$B$1:$B$56&DecisionC!$C$1:$C$56&DecisionC!$D$1:$D$56, 0))} -> CP3 works
A43: =IF(AND('177T'!B43 = '18S2'!B43, '177T'!B43 = RNAseP!B43, '177T'!B43 <> ""), '177T'!B43, IF('177T'!B43 = "", "", "Mismatch")) -> CP | B43: =IF('177T'!C43="", "", '177T'!C43) -> 21.098586 | C43: =IF('18S2'!C43="", "", '18S2'!C43) -> 19.138809 | D43: =IF(RNAseP!C43="", "", RNAseP!C43) -> 33.474039 | E43: =IF(B43=-1, "-1", IF(B43<VLOOKUP("177T", Cutoff!$A$1:$B$4, 2, FALSE), "1", "0")) -> 1 | F43: =IF(C43=-1, "-1", IF(C43<VLOOKUP("18S2", Cutoff!$A$1:$B$4, 2, FALSE), "1", "0")) -> 1 | G43: =IF(D43=-1, "-1", IF(D43<VLOOKUP("RNAseP", Cutoff!$A$1:$B$4, 2, FALSE), "1", "0")) -> 0 | H43: {=INDEX(DecisionC!$E$1:$E$56, MATCH(A43&E43&F43&G43, DecisionC!$A$1:$A$56&DecisionC!$B$1:$B$56&DecisionC!$C$1:$C$56&DecisionC!$D$1:$D$56, 0))} -> OK | I43: {=INDEX(DecisionC!$F$1:$F$56, MATCH(A43&E43&F43&G43, DecisionC!$A$1:$A$56&DecisionC!$B$1:$B$56&DecisionC!$C$1:$C$56&DecisionC!$D$1:$D$56, 0))} -> CP3 works
A44: =IF(AND('177T'!B44 = '18S2'!B44, '177T'!B44 = RNAseP!B44, '177T'!B44 <> ""), '177T'!B44, IF('177T'!B44 = "", "", "Mismatch")) -> CP | B44: =IF('177T'!C44="", "", '177T'!C44) -> 22.76576 | C44: =IF('18S2'!C44="", "", '18S2'!C44) -> 19.773424 | D44: =IF(RNAseP!C44="", "", RNAseP!C44) -> 34.266779 | E44: =IF(B44=-1, "-1", IF(B44<VLOOKUP("177T", Cutoff!$A$1:$B$4, 2, FALSE), "1", "0")) -> 1 | F44: =IF(C44=-1, "-1", IF(C44<VLOOKUP("18S2", Cutoff!$A$1:$B$4, 2, FALSE), "1", "0")) -> 1 | G44: =IF(D44=-1, "-1", IF(D44<VLOOKUP("RNAseP", Cutoff!$A$1:$B$4, 2, FALSE), "1", "0")) -> 0 | H44: {=INDEX(DecisionC!$E$1:$E$56, MATCH(A44&E44&F44&G44, DecisionC!$A$1:$A$56&DecisionC!$B$1:$B$56&DecisionC!$C$1:$C$56&DecisionC!$D$1:$D$56, 0))} -> OK | I44: {=INDEX(DecisionC!$F$1:$F$56, MATCH(A44&E44&F44&G44, DecisionC!$A$1:$A$56&DecisionC!$B$1:$B$56&DecisionC!$C$1:$C$56&DecisionC!$D$1:$D$56, 0))} -> CP3 works
A45: =IF(AND('177T'!B45 = '18S2'!B45, '177T'!B45 = RNAseP!B45, '177T'!B45 <> ""), '177T'!B45, IF('177T'!B45 = "", "", "Mismatch")) -> CP | B45: =IF('177T'!C45="", "", '177T'!C45) -> 21.521545 | C45: =IF('18S2'!C45="", "", '18S2'!C45) -> 19.811099 | D45: =IF(RNAseP!C45="", "", RNAseP!C45) -> 34.574612 | E45: =IF(B45=-1, "-1", IF(B45<VLOOKUP("177T", Cutoff!$A$1:$B$4, 2, FALSE), "1", "0")) -> 1 | F45: =IF(C45=-1, "-1", IF(C45<VLOOKUP("18S2", Cutoff!$A$1:$B$4, 2, FALSE), "1", "0")) -> 1 | G45: =IF(D45=-1, "-1", IF(D45<VLOOKUP("RNAseP", Cutoff!$A$1:$B$4, 2, FALSE), "1", "0")) -> 0 | H45: {=INDEX(DecisionC!$E$1:$E$56, MATCH(A45&E45&F45&G45, DecisionC!$A$1:$A$56&DecisionC!$B$1:$B$56&DecisionC!$C$1:$C$56&DecisionC!$D$1:$D$56, 0))} -> OK | I45: {=INDEX(DecisionC!$F$1:$F$56, MATCH(A45&E45&F45&G45, DecisionC!$A$1:$A$56&DecisionC!$B$1:$B$56&DecisionC!$C$1:$C$56&DecisionC!$D$1:$D$56, 0))} -> CP3 works
A46: =IF(AND('177T'!B46 = '18S2'!B46, '177T'!B46 = RNAseP!B46, '177T'!B46 <> ""), '177T'!B46, IF('177T'!B46 = "", "", "Mismatch")) -> CN | B46: =IF('177T'!C46="", "", '177T'!C46) -> -1 | C46: =IF('18S2'!C46="", "", '18S2'!C46) -> -1 | D46: =IF(RNAseP!C46="", "", RNAseP!C46) -> 37.939379 | E46: =IF(B46=-1, "-1", IF(B46<VLOOKUP("177T", Cutoff!$A$1:$B$4, 2, FALSE), "1", "0")) -> -1 | F46: =IF(C46=-1, "-1", IF(C46<VLOOKUP("18S2", Cutoff!$A$1:$B$4, 2, FALSE), "1", "0")) -> -1 | G46: =IF(D46=-1, "-1", IF(D46<VLOOKUP("RNAseP", Cutoff!$A$1:$B$4, 2, FALSE), "1", "0")) -> 0 | H46: {=INDEX(DecisionC!$E$1:$E$56, MATCH(A46&E46&F46&G46, DecisionC!$A$1:$A$56&DecisionC!$B$1:$B$56&DecisionC!$C$1:$C$56&DecisionC!$D$1:$D$56, 0))} -> F | I46: {=INDEX(DecisionC!$F$1:$F$56, MATCH(A46&E46&F46&G46, DecisionC!$A$1:$A$56&DecisionC!$B$1:$B$56&DecisionC!$C$1:$C$56&DecisionC!$D$1:$D$56, 0))} -> RNAseP
A47: =IF(AND('177T'!B47 = '18S2'!B47, '177T'!B47 = RNAseP!B47, '177T'!B47 <> ""), '177T'!B47, IF('177T'!B47 = "", "", "Mismatch")) -> CN | B47: =IF('177T'!C47="", "", '177T'!C47) -> -1 | C47: =IF('18S2'!C47="", "", '18S2'!C47) -> -1 | D47: =IF(RNAseP!C47="", "", RNAseP!C47) -> 37.779384 | E47: =IF(B47=-1, "-1", IF(B47<VLOOKUP("177T", Cutoff!$A$1:$B$4, 2, FALSE), "1", "0")) -> -1 | F47: =IF(C47=-1, "-1", IF(C47<VLOOKUP("18S2", Cutoff!$A$1:$B$4, 2, FALSE), "1", "0")) -> -1 | G47: =IF(D47=-1, "-1", IF(D47<VLOOKUP("RNAseP", Cutoff!$A$1:$B$4, 2, FALSE), "1", "0")) -> 0 | H47: {=INDEX(DecisionC!$E$1:$E$56, MATCH(A47&E47&F47&G47, DecisionC!$A$1:$A$56&DecisionC!$B$1:$B$56&DecisionC!$C$1:$C$56&DecisionC!$D$1:$D$56, 0))} -> F | I47: {=INDEX(DecisionC!$F$1:$F$56, MATCH(A47&E47&F47&G47, DecisionC!$A$1:$A$56&DecisionC!$B$1:$B$56&DecisionC!$C$1:$C$56&DecisionC!$D$1:$D$56, 0))} -> RNAseP
A48: =IF(AND('177T'!B48 = '18S2'!B48, '177T'!B48 = RNAseP!B48, '177T'!B48 <> ""), '177T'!B48, IF('177T'!B48 = "", "", "Mismatch")) -> CN | B48: =IF('177T'!C48="", "", '177T'!C48) -> -1 | C48: =IF('18S2'!C48="", "", '18S2'!C48) -> -1 | D48: =IF(RNAseP!C48="", "", RNAseP!C48) -> -1 | E48: =IF(B48=-1, "-1", IF(B48<VLOOKUP("177T", Cutoff!$A$1:$B$4, 2, FALSE), "1", "0")) -> -1 | F48: =IF(C48=-1, "-1", IF(C48<VLOOKUP("18S2", Cutoff!$A$1:$B$4, 2, FALSE), "1", "0")) -> -1 | G48: =IF(D48=-1, "-1", IF(D48<VLOOKUP("RNAseP", Cutoff!$A$1:$B$4, 2, FALSE), "1", "0")) -> -1 | H48: {=INDEX(DecisionC!$E$1:$E$56, MATCH(A48&E48&F48&G48, DecisionC!$A$1:$A$56&DecisionC!$B$1:$B$56&DecisionC!$C$1:$C$56&DecisionC!$D$1:$D$56, 0))} -> OK | I48: {=INDEX(DecisionC!$F$1:$F$56, MATCH(A48&E48&F48&G48, DecisionC!$A$1:$A$56&DecisionC!$B$1:$B$56&DecisionC!$C$1:$C$56&DecisionC!$D$1:$D$56, 0))} -> clean
A49: =IF(AND('177T'!B49 = '18S2'!B49, '177T'!B49 = RNAseP!B49, '177T'!B49 <> ""), '177T'!B49, IF('177T'!B49 = "", "", "Mismatch")) -> CN | B49: =IF('177T'!C49="", "", '177T'!C49) -> -1 | C49: =IF('18S2'!C49="", "", '18S2'!C49) -> -1 | D49: =IF(RNAseP!C49="", "", RNAseP!C49) -> -1 | E49: =IF(B49=-1, "-1", IF(B49<VLOOKUP("177T", Cutoff!$A$1:$B$4, 2, FALSE), "1", "0")) -> -1 | F49: =IF(C49=-1, "-1", IF(C49<VLOOKUP("18S2", Cutoff!$A$1:$B$4, 2, FALSE), "1", "0")) -> -1 | G49: =IF(D49=-1, "-1", IF(D49<VLOOKUP("RNAseP", Cutoff!$A$1:$B$4, 2, FALSE), "1", "0")) -> -1 | H49: {=INDEX(DecisionC!$E$1:$E$56, MATCH(A49&E49&F49&G49, DecisionC!$A$1:$A$56&DecisionC!$B$1:$B$56&DecisionC!$C$1:$C$56&DecisionC!$D$1:$D$56, 0))} -> OK | I49: {=INDEX(DecisionC!$F$1:$F$56, MATCH(A49&E49&F49&G49, DecisionC!$A$1:$A$56&DecisionC!$B$1:$B$56&DecisionC!$C$1:$C$56&DecisionC!$D$1:$D$56, 0))} -> clean

Sheet Cutoff
A1: Marker | B1: Cutoff
A2: 177T | B2: 35
A3: 18S2 | B3: 35
A4: RNAseP | B4: 28

Sheet Decision
A1: 177T | B1: 18S2 | C1: RNAseP | D1: Decision | E1: Remark
A2: -1 | B2: -1 | C2: -1 | D2: F | E2: extraction fail
A3: 0 | B3: -1 | C3: -1 | D3: F | E3: extraction fail
A4: 1 | B4: -1 | C4: -1 | D4: F | E4: extraction fail
A5: -1 | B5: 0 | C5: -1 | D5: F | E5: extraction fail
A6: 0 | B6: 0 | C6: -1 | D6: F | E6: extraction fail
A7: 1 | B7: 0 | C7: -1 | D7: F | E7: extraction fail
A8: -1 | B8: 1 | C8: -1 | D8: F | E8: extraction fail
A9: 0 | B9: 1 | C9: -1 | D9: F | E9: extraction fail
A10: 1 | B10: 1 | C10: -1 | D10: F | E10: extraction fail
A11: -1 | B11: -1 | C11: 0 | D11: F | E11: low human DNA
A12: 0 | B12: -1 | C12: 0 | D12: F | E12: low human DNA
A13: 1 | B13: -1 | C13: 0 | D13: F | E13: low human DNA
... A28: 1 | B28: 1 | C28: 1 | D28: P | E28: TNA case

Sheet DecisionC
A1: Sample | B1: 177T | C1: 18S2 | D1: RNAseP | E1: Decision | F1: Remark
A2: CP | B2: -1 | C2: -1 | D2: -1 | E2: F | F2: 177T/18S2/RNaseP
A3: CP | B3: 0 | C3: -1 | D3: -1 | E3: F | F3: 177T/18S2/RNAseP
A4: CP | B4: 1 | C4: -1 | D4: -1 | E4: F | F4: 18S2/RNAseP
A5: CP | B5: -1 | C5: 0 | D5: -1 | E5: F | F5: 177T/18S2/RNAseP
A6: CP | B6: 0 | C6: 0 | D6: -1 | E6: F | F6: 177T/18S2/RNAseP
A7: CP | B7: 1 | C7: 0 | D7: -1 | E7: F | F7: 18S2/RNAseP
A8: CP | B8: -1 | C8: 1 | D8: -1 | E8: F | F8: 177T/RNAseP
A9: CP | B9: 0 | C9: 1 | D9: -1 | E9: F | F9: 177T/RNAseP
A10: CP | B10: 1 | C10: 1 | D10: -1 | E10: F | F10: RNAseP
A11: CP | B11: -1 | C11: -1 | D11: 0 | E11: F | F11: 177T/18S2
A12: CP | B12: 0 | C12: -1 | D12: 0 | E12: F | F12: 177T/18S2
A13: CP | B13: 1 | C13: -1 | D13: 0 | E13: F | F13: 18S2
... A55: CN | B55: -1 | C55: -1 | D55: -1 | E55: OK | F55: clean

Sheet Report
A1: qPCR report file
A3: Date | C3: 45947
A4: Operator | C4: DIEUDO
A5: Qrun file name | C5: 2025-10-17 10.32.29 Run
A6: Qrun directory | C6: 301
A7: XLT qScript batch | C7: 45771
A8: 177T batch | C8: 45771
A9: 18S2 batch | C9: 45771
A10: RNAseP batch | C10: 45771
A11: water (CN) | C11: 45771
A12: positive controle (CP)
A15: {=IF(INDEX(Analysis!A:A,MATCH(0,COUNTIF($A$14:A14,Analysis!A:A),0))="","",INDEX(Analysis!A:A,MATCH(0,COUNTIF($A$14:A14,Analysis!A:A),0)))} -> Sample | B15: Code Barre | C15: Final | D15: 177T | E15: 18S2 | F15: RNAseP | G15: Validation (Echec/Valide)
A16: {=IF(INDEX(Analysis!A:A,MATCH(0,COUNTIF($A$14:A15,Analysis!A:A),0))="","",INDEX(Analysis!A:A,MATCH(0,COUNTIF($A$14:A15,Analysis!A:A),0)))} -> 276 | B16: 2501177 | C16: =IF(COUNTIFS(Analysis!$A$2:$A$82,A16,Analysis!$H$2:$H$82,"F")>COUNTIFS(Analysis!$A$2:$A$82,A16,Analysis!$H$2:$H$82,"N")+COUNTIFS(Analysis!$A$2:$A$82,A16,Analysis!$H$2:$H$82,"P")+COUNTIFS(Analysis!$A$2:$A$82,A16,Analysis!$H$2:$H$82,"S"),"F", IF(COUNTIFS(Analysis!$A$2:$A$82,A16,Analysis!$H$2:$H$82,"N")>COUNTIFS(Analysis!$A$2:$A$82,A16,Analysis!$H$2:$H$82,"F")+COUNTIFS(Analysis!$A$2:$A$82,A16,Analysis!$H$2:$H$82,"P")+COUNTIFS(Analysis!$A$2:$A$82,A16,Analysis!$H$2:$H$82,"S"),"N", IF(COUNTIFS(Analysis!$A$2:$A$82,A16,Analysis!$H$2:$H$82,"P")>COUNTIFS(Analysis!$A$2:$A$82,A16,Analysis!$H$2:$H$82,"F")+COUNTIFS(Analysis!$A$2:$A$82,A16,Analysis!$H$2:$H$82,"N")+COUNTIFS(Analysis!$A$2:$A$82,A16,Analysis!$H$2:$H$82,"S"),"P", IF(COUNTIFS(Analysis!$A$2:$A$82,A16,Analysis!$H$2:$H$82,"S")>COUNTIFS(Analysis!$A$2:$A$82,A16,Analysis!$H$2:$H$82,"F")+COUNTIFS(Analysis!$A$2:$A$82,A16,Analysis!$H$2:$H$82,"N")+COUNTIFS(Analysis!$A$2:$A$82,A16,Analysis!$H$2:$H$82,"P"),"S","R")))) -> N | D16: {=IFERROR( IF( ROUND(AVERAGEIFS(Analysis!$B$2:$B$100, Analysis!$A$2:$A$100, Replicates!$A2, Analysis!$B$2:$B$100, "<>-1"), 1)="", "", ROUND(AVERAGEIFS(Analysis!$B$2:$B$100, Analysis!$A$2:$A$100, Replicates!$A2, Analysis!$B$2:$B$100, "<>-1"), 1) & IF( ISNUMBER( ROUND(_xlfn.STDEV.S(IF((Analysis!$A$2:$A$100=Replicates!$A2) * (Analysis!$B$2:$B$100<>-1), Analysis!$B$2:$B$100, "")), 1) ), " +/- " & ROUND(_xlfn.STDEV.S(IF((Analysis!$A$2:$A$100=Replicates!$A2) * (Analysis!$B$2:$B$100<>-1), Analysis!$B$2:$B$100, "")), 1), "" ) ), "" )} | E16: {=IFERROR( IF( ROUND(AVERAGEIFS(Analysis!$C$2:$C$100, Analysis!$A$2:$A$100, Replicates!$A2, Analysis!$C$2:$C$100, "<>-1"), 1)="", "", ROUND(AVERAGEIFS(Analysis!$C$2:$C$100, Analysis!$A$2:$A$100, Replicates!$A2, Analysis!$C$2:$C$100, "<>-1"), 1) & IF( ISNUMBER( ROUND(_xlfn.STDEV.S(IF((Analysis!$A$2:$A$100=Replicates!$A2) * (Analysis!$C$2:$C$100<>-1), Analysis!$C$2:$C$100, "")), 1) ), " +/- " & ROUND(_xlfn.STDEV.S(IF((Analysis!$A$2:$A$100=Replicates!$A2) * (Analysis!$C$2:$C$100<>-1), Analysis!$C$2:$C$100, "")), 1), "" ) ), "" )} | F16: {=IFERROR( IF( ROUND(AVERAGEIFS(Analysis!$D$2:$D$100, Analysis!$A$2:$A$100, Replicates!$A2, Analysis!$D$2:$D$100, "<>-1"), 1)="", "", ROUND(AVERAGEIFS(Analysis!$D$2:$D$100, Analysis!$A$2:$A$100, Replicates!$A2, Analysis!$D$2:$D$100, "<>-1"), 1) & IF( ISNUMBER( ROUND(_xlfn.STDEV.S(IF((Analysis!$A$2:$A$100=Replicates!$A2) * (Analysis!$D$2:$D$100<>-1), Analysis!$D$2:$D$100, "")), 1) ), " +/- " & ROUND(_xlfn.STDEV.S(IF((Analysis!$A$2:$A$100=Replicates!$A2) * (Analysis!$D$2:$D$100<>-1), Analysis!$D$2:$D$100, "")), 1), "" ) ), "" )} -> 21,3 +/- 0
A17: {=IF(INDEX(Analysis!A:A,MATCH(0,COUNTIF($A$14:A16,Analysis!A:A),0))="","",INDEX(Analysis!A:A,MATCH(0,COUNTIF($A$14:A16,Analysis!A:A),0)))} -> 277 | B17: 2501181 | C17: =IF(COUNTIFS(Analysis!$A$2:$A$82,A17,Analysis!$H$2:$H$82,"F")>COUNTIFS(Analysis!$A$2:$A$82,A17,Analysis!$H$2:$H$82,"N")+COUNTIFS(Analysis!$A$2:$A$82,A17,Analysis!$H$2:$H$82,"P")+COUNTIFS(Analysis!$A$2:$A$82,A17,Analysis!$H$2:$H$82,"S"),"F", IF(COUNTIFS(Analysis!$A$2:$A$82,A17,Analysis!$H$2:$H$82,"N")>COUNTIFS(Analysis!$A$2:$A$82,A17,Analysis!$H$2:$H$82,"F")+COUNTIFS(Analysis!$A$2:$A$82,A17,Analysis!$H$2:$H$82,"P")+COUNTIFS(Analysis!$A$2:$A$82,A17,Analysis!$H$2:$H$82,"S"),"N", IF(COUNTIFS(Analysis!$A$2:$A$82,A17,Analysis!$H$2:$H$82,"P")>COUNTIFS(Analysis!$A$2:$A$82,A17,Analysis!$H$2:$H$82,"F")+COUNTIFS(Analysis!$A$2:$A$82,A17,Analysis!$H$2:$H$82,"N")+COUNTIFS(Analysis!$A$2:$A$82,A17,Analysis!$H$2:$H$82,"S"),"P", IF(COUNTIFS(Analysis!$A$2:$A$82,A17,Analysis!$H$2:$H$82,"S")>COUNTIFS(Analysis!$A$2:$A$82,A17,Analysis!$H$2:$H$82,"F")+COUNTIFS(Analysis!$A$2:$A$82,A17,Analysis!$H$2:$H$82,"N")+COUNTIFS(Analysis!$A$2:$A$82,A17,Analysis!$H$2:$H$82,"P"),"S","R")))) -> N | D17: {=IFERROR( IF( ROUND(AVERAGEIFS(Analysis!$B$2:$B$100, Analysis!$A$2:$A$100, Replicates!$A3, Analysis!$B$2:$B$100, "<>-1"), 1)="", "", ROUND(AVERAGEIFS(Analysis!$B$2:$B$100, Analysis!$A$2:$A$100, Replicates!$A3, Analysis!$B$2:$B$100, "<>-1"), 1) & IF( ISNUMBER( ROUND(_xlfn.STDEV.S(IF((Analysis!$A$2:$A$100=Replicates!$A3) * (Analysis!$B$2:$B$100<>-1), Analysis!$B$2:$B$100, "")), 1) ), " +/- " & ROUND(_xlfn.STDEV.S(IF((Analysis!$A$2:$A$100=Replicates!$A3) * (Analysis!$B$2:$B$100<>-1), Analysis!$B$2:$B$100, "")), 1), "" ) ), "" )} | E17: {=IFERROR( IF( ROUND(AVERAGEIFS(Analysis!$C$2:$C$100, Analysis!$A$2:$A$100, Replicates!$A3, Analysis!$C$2:$C$100, "<>-1"), 1)="", "", ROUND(AVERAGEIFS(Analysis!$C$2:$C$100, Analysis!$A$2:$A$100, Replicates!$A3, Analysis!$C$2:$C$100, "<>-1"), 1) & IF( ISNUMBER( ROUND(_xlfn.STDEV.S(IF((Analysis!$A$2:$A$100=Replicates!$A3) * (Analysis!$C$2:$C$100<>-1), Analysis!$C$2:$C$100, "")), 1) ), " +/- " & ROUND(_xlfn.STDEV.S(IF((Analysis!$A$2:$A$100=Replicates!$A3) * (Analysis!$C$2:$C$100<>-1), Analysis!$C$2:$C$100, "")), 1), "" ) ), "" )} | F17: {=IFERROR( IF( ROUND(AVERAGEIFS(Analysis!$D$2:$D$100, Analysis!$A$2:$A$100, Replicates!$A3, Analysis!$D$2:$D$100, "<>-1"), 1)="", "", ROUND(AVERAGEIFS(Analysis!$D$2:$D$100, Analysis!$A$2:$A$100, Replicates!$A3, Analysis!$D$2:$D$100, "<>-1"), 1) & IF( ISNUMBER( ROUND(_xlfn.STDEV.S(IF((Analysis!$A$2:$A$100=Replicates!$A3) * (Analysis!$D$2:$D$100<>-1), Analysis!$D$2:$D$100, "")), 1) ), " +/- " & ROUND(_xlfn.STDEV.S(IF((Analysis!$A$2:$A$100=Replicates!$A3) * (Analysis!$D$2:$D$100<>-1), Analysis!$D$2:$D$100, "")), 1), "" ) ), "" )} -> 23,6 +/- 0,1
A18: {=IF(INDEX(Analysis!A:A,MATCH(0,COUNTIF($A$14:A17,Analysis!A:A),0))="","",INDEX(Analysis!A:A,MATCH(0,COUNTIF($A$14:A17,Analysis!A:A),0)))} -> 278 | B18: 2501285 | C18: =IF(COUNTIFS(Analysis!$A$2:$A$82,A18,Analysis!$H$2:$H$82,"F")>COUNTIFS(Analysis!$A$2:$A$82,A18,Analysis!$H$2:$H$82,"N")+COUNTIFS(Analysis!$A$2:$A$82,A18,Analysis!$H$2:$H$82,"P")+COUNTIFS(Analysis!$A$2:$A$82,A18,Analysis!$H$2:$H$82,"S"),"F", IF(COUNTIFS(Analysis!$A$2:$A$82,A18,Analysis!$H$2:$H$82,"N")>COUNTIFS(Analysis!$A$2:$A$82,A18,Analysis!$H$2:$H$82,"F")+COUNTIFS(Analysis!$A$2:$A$82,A18,Analysis!$H$2:$H$82,"P")+COUNTIFS(Analysis!$A$2:$A$82,A18,Analysis!$H$2:$H$82,"S"),"N", IF(COUNTIFS(Analysis!$A$2:$A$82,A18,Analysis!$H$2:$H$82,"P")>COUNTIFS(Analysis!$A$2:$A$82,A18,Analysis!$H$2:$H$82,"F")+COUNTIFS(Analysis!$A$2:$A$82,A18,Analysis!$H$2:$H$82,"N")+COUNTIFS(Analysis!$A$2:$A$82,A18,Analysis!$H$2:$H$82,"S"),"P", IF(COUNTIFS(Analysis!$A$2:$A$82,A18,Analysis!$H$2:$H$82,"S")>COUNTIFS(Analysis!$A$2:$A$82,A18,Analysis!$H$2:$H$82,"F")+COUNTIFS(Analysis!$A$2:$A$82,A18,Analysis!$H$2:$H$82,"N")+COUNTIFS(Analysis!$A$2:$A$82,A18,Analysis!$H$2:$H$82,"P"),"S","R")))) -> P | D18: {=IFERROR( IF( ROUND(AVERAGEIFS(Analysis!$B$2:$B$100, Analysis!$A$2:$A$100, Replicates!$A4, Analysis!$B$2:$B$100, "<>-1"), 1)="", "", ROUND(AVERAGEIFS(Analysis!$B$2:$B$100, Analysis!$A$2:$A$100, Replicates!$A4, Analysis!$B$2:$B$100, "<>-1"), 1) & IF( ISNUMBER( ROUND(_xlfn.STDEV.S(IF((Analysis!$A$2:$A$100=Replicates!$A4) * (Analysis!$B$2:$B$100<>-1), Analysis!$B$2:$B$100, "")), 1) ), " +/- " & ROUND(_xlfn.STDEV.S(IF((Analysis!$A$2:$A$100=Replicates!$A4) * (Analysis!$B$2:$B$100<>-1), Analysis!$B$2:$B$100, "")), 1), "" ) ), "" )} -> 31,8 +/- 0,5 | E18: {=IFERROR( IF( ROUND(AVERAGEIFS(Analysis!$C$2:$C$100, Analysis!$A$2:$A$100, Replicates!$A4, Analysis!$C$2:$C$100, "<>-1"), 1)="", "", ROUND(AVERAGEIFS(Analysis!$C$2:$C$100, Analysis!$A$2:$A$100, Replicates!$A4, Analysis!$C$2:$C$100, "<>-1"), 1) & IF( ISNUMBER( ROUND(_xlfn.STDEV.S(IF((Analysis!$A$2:$A$100=Replicates!$A4) * (Analysis!$C$2:$C$100<>-1), Analysis!$C$2:$C$100, "")), 1) ), " +/- " & ROUND(_xlfn.STDEV.S(IF((Analysis!$A$2:$A$100=Replicates!$A4) * (Analysis!$C$2:$C$100<>-1), Analysis!$C$2:$C$100, "")), 1), "" ) ), "" )} -> 37 +/- 1,4 | F18: {=IFERROR( IF( ROUND(AVERAGEIFS(Analysis!$D$2:$D$100, Analysis!$A$2:$A$100, Replicates!$A4, Analysis!$D$2:$D$100, "<>-1"), 1)="", "", ROUND(AVERAGEIFS(Analysis!$D$2:$D$100, Analysis!$A$2:$A$100, Replicates!$A4, Analysis!$D$2:$D$100, "<>-1"), 1) & IF( ISNUMBER( ROUND(_xlfn.STDEV.S(IF((Analysis!$A$2:$A$100=Replicates!$A4) * (Analysis!$D$2:$D$100<>-1), Analysis!$D$2:$D$100, "")), 1) ), " +/- " & ROUND(_xlfn.STDEV.S(IF((Analysis!$A$2:$A$100=Replicates!$A4) * (Analysis!$D$2:$D$100<>-1), Analysis!$D$2:$D$100, "")), 1), "" ) ), "" )} -> 25,8 +/- 0
A19: {=IF(INDEX(Analysis!A:A,MATCH(0,COUNTIF($A$14:A18,Analysis!A:A),0))="","",INDEX(Analysis!A:A,MATCH(0,COUNTIF($A$14:A18,Analysis!A:A),0)))} -> 279 | B19: 2501228 | C19: =IF(COUNTIFS(Analysis!$A$2:$A$82,A19,Analysis!$H$2:$H$82,"F")>COUNTIFS(Analysis!$A$2:$A$82,A19,Analysis!$H$2:$H$82,"N")+COUNTIFS(Analysis!$A$2:$A$82,A19,Analysis!$H$2:$H$82,"P")+COUNTIFS(Analysis!$A$2:$A$82,A19,Analysis!$H$2:$H$82,"S"),"F", IF(COUNTIFS(Analysis!$A$2:$A$82,A19,Analysis!$H$2:$H$82,"N")>COUNTIFS(Analysis!$A$2:$A$82,A19,Analysis!$H$2:$H$82,"F")+COUNTIFS(Analysis!$A$2:$A$82,A19,Analysis!$H$2:$H$82,"P")+COUNTIFS(Analysis!$A$2:$A$82,A19,Analysis!$H$2:$H$82,"S"),"N", IF(COUNTIFS(Analysis!$A$2:$A$82,A19,Analysis!$H$2:$H$82,"P")>COUNTIFS(Analysis!$A$2:$A$82,A19,Analysis!$H$2:$H$82,"F")+COUNTIFS(Analysis!$A$2:$A$82,A19,Analysis!$H$2:$H$82,"N")+COUNTIFS(Analysis!$A$2:$A$82,A19,Analysis!$H$2:$H$82,"S"),"P", IF(COUNTIFS(Analysis!$A$2:$A$82,A19,Analysis!$H$2:$H$82,"S")>COUNTIFS(Analysis!$A$2:$A$82,A19,Analysis!$H$2:$H$82,"F")+COUNTIFS(Analysis!$A$2:$A$82,A19,Analysis!$H$2:$H$82,"N")+COUNTIFS(Analysis!$A$2:$A$82,A19,Analysis!$H$2:$H$82,"P"),"S","R")))) -> P | D19: {=IFERROR( IF( ROUND(AVERAGEIFS(Analysis!$B$2:$B$100, Analysis!$A$2:$A$100, Replicates!$A5, Analysis!$B$2:$B$100, "<>-1"), 1)="", "", ROUND(AVERAGEIFS(Analysis!$B$2:$B$100, Analysis!$A$2:$A$100, Replicates!$A5, Analysis!$B$2:$B$100, "<>-1"), 1) & IF( ISNUMBER( ROUND(_xlfn.STDEV.S(IF((Analysis!$A$2:$A$100=Replicates!$A5) * (Analysis!$B$2:$B$100<>-1), Analysis!$B$2:$B$100, "")), 1) ), " +/- " & ROUND(_xlfn.STDEV.S(IF((Analysis!$A$2:$A$100=Replicates!$A5) * (Analysis!$B$2:$B$100<>-1), Analysis!$B$2:$B$100, "")), 1), "" ) ), "" )} -> 28,6 +/- 0,3 | E19: {=IFERROR( IF( ROUND(AVERAGEIFS(Analysis!$C$2:$C$100, Analysis!$A$2:$A$100, Replicates!$A5, Analysis!$C$2:$C$100, "<>-1"), 1)="", "", ROUND(AVERAGEIFS(Analysis!$C$2:$C$100, Analysis!$A$2:$A$100, Replicates!$A5, Analysis!$C$2:$C$100, "<>-1"), 1) & IF( ISNUMBER( ROUND(_xlfn.STDEV.S(IF((Analysis!$A$2:$A$100=Replicates!$A5) * (Analysis!$C$2:$C$100<>-1), Analysis!$C$2:$C$100, "")), 1) ), " +/- " & ROUND(_xlfn.STDEV.S(IF((Analysis!$A$2:$A$100=Replicates!$A5) * (Analysis!$C$2:$C$100<>-1), Analysis!$C$2:$C$100, "")), 1), "" ) ), "" )} -> 36,5 +/- 0,6 | F19: {=IFERROR( IF( ROUND(AVERAGEIFS(Analysis!$D$2:$D$100, Analysis!$A$2:$A$100, Replicates!$A5, Analysis!$D$2:$D$100, "<>-1"), 1)="", "", ROUND(AVERAGEIFS(Analysis!$D$2:$D$100, Analysis!$A$2:$A$100, Replicates!$A5, Analysis!$D$2:$D$100, "<>-1"), 1) & IF( ISNUMBER( ROUND(_xlfn.STDEV.S(IF((Analysis!$A$2:$A$100=Replicates!$A5) * (Analysis!$D$2:$D$100<>-1), Analysis!$D$2:$D$100, "")), 1) ), " +/- " & ROUND(_xlfn.STDEV.S(IF((Analysis!$A$2:$A$100=Replicates!$A5) * (Analysis!$D$2:$D$100<>-1), Analysis!$D$2:$D$100, "")), 1), "" ) ), "" )} -> 22,8 +/- 0,1
A20: {=IF(INDEX(Analysis!A:A,MATCH(0,COUNTIF($A$14:A19,Analysis!A:A),0))="","",INDEX(Analysis!A:A,MATCH(0,COUNTIF($A$14:A19,Analysis!A:A),0)))} -> 280 | B20: 2501917 | C20: =IF(COUNTIFS(Analysis!$A$2:$A$82,A20,Analysis!$H$2:$H$82,"F")>COUNTIFS(Analysis!$A$2:$A$82,A20,Analysis!$H$2:$H$82,"N")+COUNTIFS(Analysis!$A$2:$A$82,A20,Analysis!$H$2:$H$82,"P")+COUNTIFS(Analysis!$A$2:$A$82,A20,Analysis!$H$2:$H$82,"S"),"F", IF(COUNTIFS(Analysis!$A$2:$A$82,A20,Analysis!$H$2:$H$82,"N")>COUNTIFS(Analysis!$A$2:$A$82,A20,Analysis!$H$2:$H$82,"F")+COUNTIFS(Analysis!$A$2:$A$82,A20,Analysis!$H$2:$H$82,"P")+COUNTIFS(Analysis!$A$2:$A$82,A20,Analysis!$H$2:$H$82,"S"),"N", IF(COUNTIFS(Analysis!$A$2:$A$82,A20,Analysis!$H$2:$H$82,"P")>COUNTIFS(Analysis!$A$2:$A$82,A20,Analysis!$H$2:$H$82,"F")+COUNTIFS(Analysis!$A$2:$A$82,A20,Analysis!$H$2:$H$82,"N")+COUNTIFS(Analysis!$A$2:$A$82,A20,Analysis!$H$2:$H$82,"S"),"P", IF(COUNTIFS(Analysis!$A$2:$A$82,A20,Analysis!$H$2:$H$82,"S")>COUNTIFS(Analysis!$A$2:$A$82,A20,Analysis!$H$2:$H$82,"F")+COUNTIFS(Analysis!$A$2:$A$82,A20,Analysis!$H$2:$H$82,"N")+COUNTIFS(Analysis!$A$2:$A$82,A20,Analysis!$H$2:$H$82,"P"),"S","R")))) -> N | D20: {=IFERROR( IF( ROUND(AVERAGEIFS(Analysis!$B$2:$B$100, Analysis!$A$2:$A$100, Replicates!$A6, Analysis!$B$2:$B$100, "<>-1"), 1)="", "", ROUND(AVERAGEIFS(Analysis!$B$2:$B$100, Analysis!$A$2:$A$100, Replicates!$A6, Analysis!$B$2:$B$100, "<>-1"), 1) & IF( ISNUMBER( ROUND(_xlfn.STDEV.S(IF((Analysis!$A$2:$A$100=Replicates!$A6) * (Analysis!$B$2:$B$100<>-1), Analysis!$B$2:$B$100, "")), 1) ), " +/- " & ROUND(_xlfn.STDEV.S(IF((Analysis!$A$2:$A$100=Replicates!$A6) * (Analysis!$B$2:$B$100<>-1), Analysis!$B$2:$B$100, "")), 1), "" ) ), "" )} | E20: {=IFERROR( IF( ROUND(AVERAGEIFS(Analysis!$C$2:$C$100, Analysis!$A$2:$A$100, Replicates!$A6, Analysis!$C$2:$C$100, "<>-1"), 1)="", "", ROUND(AVERAGEIFS(Analysis!$C$2:$C$100, Analysis!$A$2:$A$100, Replicates!$A6, Analysis!$C$2:$C$100, "<>-1"), 1) & IF( ISNUMBER( ROUND(_xlfn.STDEV.S(IF((Analysis!$A$2:$A$100=Replicates!$A6) * (Analysis!$C$2:$C$100<>-1), Analysis!$C$2:$C$100, "")), 1) ), " +/- " & ROUND(_xlfn.STDEV.S(IF((Analysis!$A$2:$A$100=Replicates!$A6) * (Analysis!$C$2:$C$100<>-1), Analysis!$C$2:$C$100, "")), 1), "" ) ), "" )} | F20: {=IFERROR( IF( ROUND(AVERAGEIFS(Analysis!$D$2:$D$100, Analysis!$A$2:$A$100, Replicates!$A6, Analysis!$D$2:$D$100, "<>-1"), 1)="", "", ROUND(AVERAGEIFS(Analysis!$D$2:$D$100, Analysis!$A$2:$A$100, Replicates!$A6, Analysis!$D$2:$D$100, "<>-1"), 1) & IF( ISNUMBER( ROUND(_xlfn.STDEV.S(IF((Analysis!$A$2:$A$100=Replicates!$A6) * (Analysis!$D$2:$D$100<>-1), Analysis!$D$2:$D$100, "")), 1) ), " +/- " & ROUND(_xlfn.STDEV.S(IF((Analysis!$A$2:$A$100=Replicates!$A6) * (Analysis!$D$2:$D$100<>-1), Analysis!$D$2:$D$100, "")), 1), "" ) ), "" )} -> 23,7 +/- 0
A21: {=IF(INDEX(Analysis!A:A,MATCH(0,COUNTIF($A$14:A20,Analysis!A:A),0))="","",INDEX(Analysis!A:A,MATCH(0,COUNTIF($A$14:A20,Analysis!A:A),0)))} -> 281 | B21: 2502000 | C21: =IF(COUNTIFS(Analysis!$A$2:$A$82,A21,Analysis!$H$2:$H$82,"F")>COUNTIFS(Analysis!$A$2:$A$82,A21,Analysis!$H$2:$H$82,"N")+COUNTIFS(Analysis!$A$2:$A$82,A21,Analysis!$H$2:$H$82,"P")+COUNTIFS(Analysis!$A$2:$A$82,A21,Analysis!$H$2:$H$82,"S"),"F", IF(COUNTIFS(Analysis!$A$2:$A$82,A21,Analysis!$H$2:$H$82,"N")>COUNTIFS(Analysis!$A$2:$A$82,A21,Analysis!$H$2:$H$82,"F")+COUNTIFS(Analysis!$A$2:$A$82,A21,Analysis!$H$2:$H$82,"P")+COUNTIFS(Analysis!$A$2:$A$82,A21,Analysis!$H$2:$H$82,"S"),"N", IF(COUNTIFS(Analysis!$A$2:$A$82,A21,Analysis!$H$2:$H$82,"P")>COUNTIFS(Analysis!$A$2:$A$82,A21,Analysis!$H$2:$H$82,"F")+COUNTIFS(Analysis!$A$2:$A$82,A21,Analysis!$H$2:$H$82,"N")+COUNTIFS(Analysis!$A$2:$A$82,A21,Analysis!$H$2:$H$82,"S"),"P", IF(COUNTIFS(Analysis!$A$2:$A$82,A21,Analysis!$H$2:$H$82,"S")>COUNTIFS(Analysis!$A$2:$A$82,A21,Analysis!$H$2:$H$82,"F")+COUNTIFS(Analysis!$A$2:$A$82,A21,Analysis!$H$2:$H$82,"N")+COUNTIFS(Analysis!$A$2:$A$82,A21,Analysis!$H$2:$H$82,"P"),"S","R")))) -> N | D21: {=IFERROR( IF( ROUND(AVERAGEIFS(Analysis!$B$2:$B$100, Analysis!$A$2:$A$100, Replicates!$A7, Analysis!$B$2:$B$100, "<>-1"), 1)="", "", ROUND(AVERAGEIFS(Analysis!$B$2:$B$100, Analysis!$A$2:$A$100, Replicates!$A7, Analysis!$B$2:$B$100, "<>-1"), 1) & IF( ISNUMBER( ROUND(_xlfn.STDEV.S(IF((Analysis!$A$2:$A$100=Replicates!$A7) * (Analysis!$B$2:$B$100<>-1), Analysis!$B$2:$B$100, "")), 1) ), " +/- " & ROUND(_xlfn.STDEV.S(IF((Analysis!$A$2:$A$100=Replicates!$A7) * (Analysis!$B$2:$B$100<>-1), Analysis!$B$2:$B$100, "")), 1), "" ) ), "" )} | E21: {=IFERROR( IF( ROUND(AVERAGEIFS(Analysis!$C$2:$C$100, Analysis!$A$2:$A$100, Replicates!$A7, Analysis!$C$2:$C$100, "<>-1"), 1)="", "", ROUND(AVERAGEIFS(Analysis!$C$2:$C$100, Analysis!$A$2:$A$100, Replicates!$A7, Analysis!$C$2:$C$100, "<>-1"), 1) & IF( ISNUMBER( ROUND(_xlfn.STDEV.S(IF((Analysis!$A$2:$A$100=Replicates!$A7) * (Analysis!$C$2:$C$100<>-1), Analysis!$C$2:$C$100, "")), 1) ), " +/- " & ROUND(_xlfn.STDEV.S(IF((Analysis!$A$2:$A$100=Replicates!$A7) * (Analysis!$C$2:$C$100<>-1), Analysis!$C$2:$C$100, "")), 1), "" ) ), "" )} | F21: {=IFERROR( IF( ROUND(AVERAGEIFS(Analysis!$D$2:$D$100, Analysis!$A$2:$A$100, Replicates!$A7, Analysis!$D$2:$D$100, "<>-1"), 1)="", "", ROUND(AVERAGEIFS(Analysis!$D$2:$D$100, Analysis!$A$2:$A$100, Replicates!$A7, Analysis!$D$2:$D$100, "<>-1"), 1) & IF( ISNUMBER( ROUND(_xlfn.STDEV.S(IF((Analysis!$A$2:$A$100=Replicates!$A7) * (Analysis!$D$2:$D$100<>-1), Analysis!$D$2:$D$100, "")), 1) ), " +/- " & ROUND(_xlfn.STDEV.S(IF((Analysis!$A$2:$A$100=Replicates!$A7) * (Analysis!$D$2:$D$100<>-1), Analysis!$D$2:$D$100, "")), 1), "" ) ), "" )} -> 21,2 +/- 0
A22: {=IF(INDEX(Analysis!A:A,MATCH(0,COUNTIF($A$14:A21,Analysis!A:A),0))="","",INDEX(Analysis!A:A,MATCH(0,COUNTIF($A$14:A21,Analysis!A:A),0)))} -> 282 | B22: 2501965 | C22: =IF(COUNTIFS(Analysis!$A$2:$A$82,A22,Analysis!$H$2:$H$82,"F")>COUNTIFS(Analysis!$A$2:$A$82,A22,Analysis!$H$2:$H$82,"N")+COUNTIFS(Analysis!$A$2:$A$82,A22,Analysis!$H$2:$H$82,"P")+COUNTIFS(Analysis!$A$2:$A$82,A22,Analysis!$H$2:$H$82,"S"),"F", IF(COUNTIFS(Analysis!$A$2:$A$82,A22,Analysis!$H$2:$H$82,"N")>COUNTIFS(Analysis!$A$2:$A$82,A22,Analysis!$H$2:$H$82,"F")+COUNTIFS(Analysis!$A$2:$A$82,A22,Analysis!$H$2:$H$82,"P")+COUNTIFS(Analysis!$A$2:$A$82,A22,Analysis!$H$2:$H$82,"S"),"N", IF(COUNTIFS(Analysis!$A$2:$A$82,A22,Analysis!$H$2:$H$82,"P")>COUNTIFS(Analysis!$A$2:$A$82,A22,Analysis!$H$2:$H$82,"F")+COUNTIFS(Analysis!$A$2:$A$82,A22,Analysis!$H$2:$H$82,"N")+COUNTIFS(Analysis!$A$2:$A$82,A22,Analysis!$H$2:$H$82,"S"),"P", IF(COUNTIFS(Analysis!$A$2:$A$82,A22,Analysis!$H$2:$H$82,"S")>COUNTIFS(Analysis!$A$2:$A$82,A22,Analysis!$H$2:$H$82,"F")+COUNTIFS(Analysis!$A$2:$A$82,A22,Analysis!$H$2:$H$82,"N")+COUNTIFS(Analysis!$A$2:$A$82,A22,Analysis!$H$2:$H$82,"P"),"S","R")))) -> N | D22: {=IFERROR( IF( ROUND(AVERAGEIFS(Analysis!$B$2:$B$100, Analysis!$A$2:$A$100, Replicates!$A8, Analysis!$B$2:$B$100, "<>-1"), 1)="", "", ROUND(AVERAGEIFS(Analysis!$B$2:$B$100, Analysis!$A$2:$A$100, Replicates!$A8, Analysis!$B$2:$B$100, "<>-1"), 1) & IF( ISNUMBER( ROUND(_xlfn.STDEV.S(IF((Analysis!$A$2:$A$100=Replicates!$A8) * (Analysis!$B$2:$B$100<>-1), Analysis!$B$2:$B$100, "")), 1) ), " +/- " & ROUND(_xlfn.STDEV.S(IF((Analysis!$A$2:$A$100=Replicates!$A8) * (Analysis!$B$2:$B$100<>-1), Analysis!$B$2:$B$100, "")), 1), "" ) ), "" )} | E22: {=IFERROR( IF( ROUND(AVERAGEIFS(Analysis!$C$2:$C$100, Analysis!$A$2:$A$100, Replicates!$A8, Analysis!$C$2:$C$100, "<>-1"), 1)="", "", ROUND(AVERAGEIFS(Analysis!$C$2:$C$100, Analysis!$A$2:$A$100, Replicates!$A8, Analysis!$C$2:$C$100, "<>-1"), 1) & IF( ISNUMBER( ROUND(_xlfn.STDEV.S(IF((Analysis!$A$2:$A$100=Replicates!$A8) * (Analysis!$C$2:$C$100<>-1), Analysis!$C$2:$C$100, "")), 1) ), " +/- " & ROUND(_xlfn.STDEV.S(IF((Analysis!$A$2:$A$100=Replicates!$A8) * (Analysis!$C$2:$C$100<>-1), Analysis!$C$2:$C$100, "")), 1), "" ) ), "" )} | F22: {=IFERROR( IF( ROUND(AVERAGEIFS(Analysis!$D$2:$D$100, Analysis!$A$2:$A$100, Replicates!$A8, Analysis!$D$2:$D$100, "<>-1"), 1)="", "", ROUND(AVERAGEIFS(Analysis!$D$2:$D$100, Analysis!$A$2:$A$100, Replicates!$A8, Analysis!$D$2:$D$100, "<>-1"), 1) & IF( ISNUMBER( ROUND(_xlfn.STDEV.S(IF((Analysis!$A$2:$A$100=Replicates!$A8) * (Analysis!$D$2:$D$100<>-1), Analysis!$D$2:$D$100, "")), 1) ), " +/- " & ROUND(_xlfn.STDEV.S(IF((Analysis!$A$2:$A$100=Replicates!$A8) * (Analysis!$D$2:$D$100<>-1), Analysis!$D$2:$D$100, "")), 1), "" ) ), "" )} -> 24,4 +/- 0,1
A23: {=IF(INDEX(Analysis!A:A,MATCH(0,COUNTIF($A$14:A22,Analysis!A:A),0))="","",INDEX(Analysis!A:A,MATCH(0,COUNTIF($A$14:A22,Analysis!A:A),0)))} -> 283 | B23: 2501945 | C23: =IF(COUNTIFS(Analysis!$A$2:$A$82,A23,Analysis!$H$2:$H$82,"F")>COUNTIFS(Analysis!$A$2:$A$82,A23,Analysis!$H$2:$H$82,"N")+COUNTIFS(Analysis!$A$2:$A$82,A23,Analysis!$H$2:$H$82,"P")+COUNTIFS(Analysis!$A$2:$A$82,A23,Analysis!$H$2:$H$82,"S"),"F", IF(COUNTIFS(Analysis!$A$2:$A$82,A23,Analysis!$H$2:$H$82,"N")>COUNTIFS(Analysis!$A$2:$A$82,A23,Analysis!$H$2:$H$82,"F")+COUNTIFS(Analysis!$A$2:$A$82,A23,Analysis!$H$2:$H$82,"P")+COUNTIFS(Analysis!$A$2:$A$82,A23,Analysis!$H$2:$H$82,"S"),"N", IF(COUNTIFS(Analysis!$A$2:$A$82,A23,Analysis!$H$2:$H$82,"P")>COUNTIFS(Analysis!$A$2:$A$82,A23,Analysis!$H$2:$H$82,"F")+COUNTIFS(Analysis!$A$2:$A$82,A23,Analysis!$H$2:$H$82,"N")+COUNTIFS(Analysis!$A$2:$A$82,A23,Analysis!$H$2:$H$82,"S"),"P", IF(COUNTIFS(Analysis!$A$2:$A$82,A23,Analysis!$H$2:$H$82,"S")>COUNTIFS(Analysis!$A$2:$A$82,A23,Analysis!$H$2:$H$82,"F")+COUNTIFS(Analysis!$A$2:$A$82,A23,Analysis!$H$2:$H$82,"N")+COUNTIFS(Analysis!$A$2:$A$82,A23,Analysis!$H$2:$H$82,"P"),"S","R")))) -> N | D23: {=IFERROR( IF( ROUND(AVERAGEIFS(Analysis!$B$2:$B$100, Analysis!$A$2:$A$100, Replicates!$A9, Analysis!$B$2:$B$100, "<>-1"), 1)="", "", ROUND(AVERAGEIFS(Analysis!$B$2:$B$100, Analysis!$A$2:$A$100, Replicates!$A9, Analysis!$B$2:$B$100, "<>-1"), 1) & IF( ISNUMBER( ROUND(_xlfn.STDEV.S(IF((Analysis!$A$2:$A$100=Replicates!$A9) * (Analysis!$B$2:$B$100<>-1), Analysis!$B$2:$B$100, "")), 1) ), " +/- " & ROUND(_xlfn.STDEV.S(IF((Analysis!$A$2:$A$100=Replicates!$A9) * (Analysis!$B$2:$B$100<>-1), Analysis!$B$2:$B$100, "")), 1), "" ) ), "" )} | E23: {=IFERROR( IF( ROUND(AVERAGEIFS(Analysis!$C$2:$C$100, Analysis!$A$2:$A$100, Replicates!$A9, Analysis!$C$2:$C$100, "<>-1"), 1)="", "", ROUND(AVERAGEIFS(Analysis!$C$2:$C$100, Analysis!$A$2:$A$100, Replicates!$A9, Analysis!$C$2:$C$100, "<>-1"), 1) & IF( ISNUMBER( ROUND(_xlfn.STDEV.S(IF((Analysis!$A$2:$A$100=Replicates!$A9) * (Analysis!$C$2:$C$100<>-1), Analysis!$C$2:$C$100, "")), 1) ), " +/- " & ROUND(_xlfn.STDEV.S(IF((Analysis!$A$2:$A$100=Replicates!$A9) * (Analysis!$C$2:$C$100<>-1), Analysis!$C$2:$C$100, "")), 1), "" ) ), "" )} | F23: {=IFERROR( IF( ROUND(AVERAGEIFS(Analysis!$D$2:$D$100, Analysis!$A$2:$A$100, Replicates!$A9, Analysis!$D$2:$D$100, "<>-1"), 1)="", "", ROUND(AVERAGEIFS(Analysis!$D$2:$D$100, Analysis!$A$2:$A$100, Replicates!$A9, Analysis!$D$2:$D$100, "<>-1"), 1) & IF( ISNUMBER( ROUND(_xlfn.STDEV.S(IF((Analysis!$A$2:$A$100=Replicates!$A9) * (Analysis!$D$2:$D$100<>-1), Analysis!$D$2:$D$100, "")), 1) ), " +/- " & ROUND(_xlfn.STDEV.S(IF((Analysis!$A$2:$A$100=Replicates!$A9) * (Analysis!$D$2:$D$100<>-1), Analysis!$D$2:$D$100, "")), 1), "" ) ), "" )} -> 20,6 +/- 0,1
A24: {=IF(INDEX(Analysis!A:A,MATCH(0,COUNTIF($A$14:A23,Analysis!A:A),0))="","",INDEX(Analysis!A:A,MATCH(0,COUNTIF($A$14:A23,Analysis!A:A),0)))} -> 284 | B24: 2501981 | C24: =IF(COUNTIFS(Analysis!$A$2:$A$82,A24,Analysis!$H$2:$H$82,"F")>COUNTIFS(Analysis!$A$2:$A$82,A24,Analysis!$H$2:$H$82,"N")+COUNTIFS(Analysis!$A$2:$A$82,A24,Analysis!$H$2:$H$82,"P")+COUNTIFS(Analysis!$A$2:$A$82,A24,Analysis!$H$2:$H$82,"S"),"F", IF(COUNTIFS(Analysis!$A$2:$A$82,A24,Analysis!$H$2:$H$82,"N")>COUNTIFS(Analysis!$A$2:$A$82,A24,Analysis!$H$2:$H$82,"F")+COUNTIFS(Analysis!$A$2:$A$82,A24,Analysis!$H$2:$H$82,"P")+COUNTIFS(Analysis!$A$2:$A$82,A24,Analysis!$H$2:$H$82,"S"),"N", IF(COUNTIFS(Analysis!$A$2:$A$82,A24,Analysis!$H$2:$H$82,"P")>COUNTIFS(Analysis!$A$2:$A$82,A24,Analysis!$H$2:$H$82,"F")+COUNTIFS(Analysis!$A$2:$A$82,A24,Analysis!$H$2:$H$82,"N")+COUNTIFS(Analysis!$A$2:$A$82,A24,Analysis!$H$2:$H$82,"S"),"P", IF(COUNTIFS(Analysis!$A$2:$A$82,A24,Analysis!$H$2:$H$82,"S")>COUNTIFS(Analysis!$A$2:$A$82,A24,Analysis!$H$2:$H$82,"F")+COUNTIFS(Analysis!$A$2:$A$82,A24,Analysis!$H$2:$H$82,"N")+COUNTIFS(Analysis!$A$2:$A$82,A24,Analysis!$H$2:$H$82,"P"),"S","R")))) -> N | D24: {=IFERROR( IF( ROUND(AVERAGEIFS(Analysis!$B$2:$B$100, Analysis!$A$2:$A$100, Replicates!$A10, Analysis!$B$2:$B$100, "<>-1"), 1)="", "", ROUND(AVERAGEIFS(Analysis!$B$2:$B$100, Analysis!$A$2:$A$100, Replicates!$A10, Analysis!$B$2:$B$100, "<>-1"), 1) & IF( ISNUMBER( ROUND(_xlfn.STDEV.S(IF((Analysis!$A$2:$A$100=Replicates!$A10) * (Analysis!$B$2:$B$100<>-1), Analysis!$B$2:$B$100, "")), 1) ), " +/- " & ROUND(_xlfn.STDEV.S(IF((Analysis!$A$2:$A$100=Replicates!$A10) * (Analysis!$B$2:$B$100<>-1), Analysis!$B$2:$B$100, "")), 1), "" ) ), "" )} | E24: {=IFERROR( IF( ROUND(AVERAGEIFS(Analysis!$C$2:$C$100, Analysis!$A$2:$A$100, Replicates!$A10, Analysis!$C$2:$C$100, "<>-1"), 1)="", "", ROUND(AVERAGEIFS(Analysis!$C$2:$C$100, Analysis!$A$2:$A$100, Replicates!$A10, Analysis!$C$2:$C$100, "<>-1"), 1) & IF( ISNUMBER( ROUND(_xlfn.STDEV.S(IF((Analysis!$A$2:$A$100=Replicates!$A10) * (Analysis!$C$2:$C$100<>-1), Analysis!$C$2:$C$100, "")), 1) ), " +/- " & ROUND(_xlfn.STDEV.S(IF((Analysis!$A$2:$A$100=Replicates!$A10) * (Analysis!$C$2:$C$100<>-1), Analysis!$C$2:$C$100, "")), 1), "" ) ), "" )} | F24: {=IFERROR( IF( ROUND(AVERAGEIFS(Analysis!$D$2:$D$100, Analysis!$A$2:$A$100, Replicates!$A10, Analysis!$D$2:$D$100, "<>-1"), 1)="", "", ROUND(AVERAGEIFS(Analysis!$D$2:$D$100, Analysis!$A$2:$A$100, Replicates!$A10, Analysis!$D$2:$D$100, "<>-1"), 1) & IF( ISNUMBER( ROUND(_xlfn.STDEV.S(IF((Analysis!$A$2:$A$100=Replicates!$A10) * (Analysis!$D$2:$D$100<>-1), Analysis!$D$2:$D$100, "")), 1) ), " +/- " & ROUND(_xlfn.STDEV.S(IF((Analysis!$A$2:$A$100=Replicates!$A10) * (Analysis!$D$2:$D$100<>-1), Analysis!$D$2:$D$100, "")), 1), "" ) ), "" )} -> 24,2 +/- 0
A25: {=IF(INDEX(Analysis!A:A,MATCH(0,COUNTIF($A$14:A24,Analysis!A:A),0))="","",INDEX(Analysis!A:A,MATCH(0,COUNTIF($A$14:A24,Analysis!A:A),0)))} -> 285 | B25: 2501916 | C25: =IF(COUNTIFS(Analysis!$A$2:$A$82,A25,Analysis!$H$2:$H$82,"F")>COUNTIFS(Analysis!$A$2:$A$82,A25,Analysis!$H$2:$H$82,"N")+COUNTIFS(Analysis!$A$2:$A$82,A25,Analysis!$H$2:$H$82,"P")+COUNTIFS(Analysis!$A$2:$A$82,A25,Analysis!$H$2:$H$82,"S"),"F", IF(COUNTIFS(Analysis!$A$2:$A$82,A25,Analysis!$H$2:$H$82,"N")>COUNTIFS(Analysis!$A$2:$A$82,A25,Analysis!$H$2:$H$82,"F")+COUNTIFS(Analysis!$A$2:$A$82,A25,Analysis!$H$2:$H$82,"P")+COUNTIFS(Analysis!$A$2:$A$82,A25,Analysis!$H$2:$H$82,"S"),"N", IF(COUNTIFS(Analysis!$A$2:$A$82,A25,Analysis!$H$2:$H$82,"P")>COUNTIFS(Analysis!$A$2:$A$82,A25,Analysis!$H$2:$H$82,"F")+COUNTIFS(Analysis!$A$2:$A$82,A25,Analysis!$H$2:$H$82,"N")+COUNTIFS(Analysis!$A$2:$A$82,A25,Analysis!$H$2:$H$82,"S"),"P", IF(COUNTIFS(Analysis!$A$2:$A$82,A25,Analysis!$H$2:$H$82,"S")>COUNTIFS(Analysis!$A$2:$A$82,A25,Analysis!$H$2:$H$82,"F")+COUNTIFS(Analysis!$A$2:$A$82,A25,Analysis!$H$2:$H$82,"N")+COUNTIFS(Analysis!$A$2:$A$82,A25,Analysis!$H$2:$H$82,"P"),"S","R")))) -> N | D25: {=IFERROR( IF( ROUND(AVERAGEIFS(Analysis!$B$2:$B$100, Analysis!$A$2:$A$100, Replicates!$A11, Analysis!$B$2:$B$100, "<>-1"), 1)="", "", ROUND(AVERAGEIFS(Analysis!$B$2:$B$100, Analysis!$A$2:$A$100, Replicates!$A11, Analysis!$B$2:$B$100, "<>-1"), 1) & IF( ISNUMBER( ROUND(_xlfn.STDEV.S(IF((Analysis!$A$2:$A$100=Replicates!$A11) * (Analysis!$B$2:$B$100<>-1), Analysis!$B$2:$B$100, "")), 1) ), " +/- " & ROUND(_xlfn.STDEV.S(IF((Analysis!$A$2:$A$100=Replicates!$A11) * (Analysis!$B$2:$B$100<>-1), Analysis!$B$2:$B$100, "")), 1), "" ) ), "" )} | E25: {=IFERROR( IF( ROUND(AVERAGEIFS(Analysis!$C$2:$C$100, Analysis!$A$2:$A$100, Replicates!$A11, Analysis!$C$2:$C$100, "<>-1"), 1)="", "", ROUND(AVERAGEIFS(Analysis!$C$2:$C$100, Analysis!$A$2:$A$100, Replicates!$A11, Analysis!$C$2:$C$100, "<>-1"), 1) & IF( ISNUMBER( ROUND(_xlfn.STDEV.S(IF((Analysis!$A$2:$A$100=Replicates!$A11) * (Analysis!$C$2:$C$100<>-1), Analysis!$C$2:$C$100, "")), 1) ), " +/- " & ROUND(_xlfn.STDEV.S(IF((Analysis!$A$2:$A$100=Replicates!$A11) * (Analysis!$C$2:$C$100<>-1), Analysis!$C$2:$C$100, "")), 1), "" ) ), "" )} | F25: {=IFERROR( IF( ROUND(AVERAGEIFS(Analysis!$D$2:$D$100, Analysis!$A$2:$A$100, Replicates!$A11, Analysis!$D$2:$D$100, "<>-1"), 1)="", "", ROUND(AVERAGEIFS(Analysis!$D$2:$D$100, Analysis!$A$2:$A$100, Replicates!$A11, Analysis!$D$2:$D$100, "<>-1"), 1) & IF( ISNUMBER( ROUND(_xlfn.STDEV.S(IF((Analysis!$A$2:$A$100=Replicates!$A11) * (Analysis!$D$2:$D$100<>-1), Analysis!$D$2:$D$100, "")), 1) ), " +/- " & ROUND(_xlfn.STDEV.S(IF((Analysis!$A$2:$A$100=Replicates!$A11) * (Analysis!$D$2:$D$100<>-1), Analysis!$D$2:$D$100, "")), 1), "" ) ), "" )} -> 22,3 +/- 0,3
A26: {=IF(INDEX(Analysis!A:A,MATCH(0,COUNTIF($A$14:A25,Analysis!A:A),0))="","",INDEX(Analysis!A:A,MATCH(0,COUNTIF($A$14:A25,Analysis!A:A),0)))} -> CP | C26: =IF(COUNTIFS(Analysis!$A$2:$A$82,A26,Analysis!$H$2:$H$82,"F")>COUNTIFS(Analysis!$A$2:$A$82,A26,Analysis!$H$2:$H$82,"OK"),"F",IF(COUNTIFS(Analysis!$A$2:$A$82,A26,Analysis!$H$2:$H$82,"OK")>COUNTIFS(Analysis!$A$2:$A$82,A26,Analysis!$H$2:$H$82,"F"),"OK","I")) -> OK | D26: {=IFERROR( IF( ROUND(AVERAGEIFS(Analysis!$B$2:$B$100, Analysis!$A$2:$A$100, Replicates!$A12, Analysis!$B$2:$B$100, "<>-1"), 1)="", "", ROUND(AVERAGEIFS(Analysis!$B$2:$B$100, Analysis!$A$2:$A$100, Replicates!$A12, Analysis!$B$2:$B$100, "<>-1"), 1) & IF( ISNUMBER( ROUND(_xlfn.STDEV.S(IF((Analysis!$A$2:$A$100=Replicates!$A12) * (Analysis!$B$2:$B$100<>-1), Analysis!$B$2:$B$100, "")), 1) ), " +/- " & ROUND(_xlfn.STDEV.S(IF((Analysis!$A$2:$A$100=Replicates!$A12) * (Analysis!$B$2:$B$100<>-1), Analysis!$B$2:$B$100, "")), 1), "" ) ), "" )} -> 21,7 +/- 0,7 | E26: {=IFERROR( IF( ROUND(AVERAGEIFS(Analysis!$C$2:$C$100, Analysis!$A$2:$A$100, Replicates!$A12, Analysis!$C$2:$C$100, "<>-1"), 1)="", "", ROUND(AVERAGEIFS(Analysis!$C$2:$C$100, Analysis!$A$2:$A$100, Replicates!$A12, Analysis!$C$2:$C$100, "<>-1"), 1) & IF( ISNUMBER( ROUND(_xlfn.STDEV.S(IF((Analysis!$A$2:$A$100=Replicates!$A12) * (Analysis!$C$2:$C$100<>-1), Analysis!$C$2:$C$100, "")), 1) ), " +/- " & ROUND(_xlfn.STDEV.S(IF((Analysis!$A$2:$A$100=Replicates!$A12) * (Analysis!$C$2:$C$100<>-1), Analysis!$C$2:$C$100, "")), 1), "" ) ), "" )} -> 19,5 +/- 0,3 | F26: {=IFERROR( IF( ROUND(AVERAGEIFS(Analysis!$D$2:$D$100, Analysis!$A$2:$A$100, Replicates!$A12, Analysis!$D$2:$D$100, "<>-1"), 1)="", "", ROUND(AVERAGEIFS(Analysis!$D$2:$D$100, Analysis!$A$2:$A$100, Replicates!$A12, Analysis!$D$2:$D$100, "<>-1"), 1) & IF( ISNUMBER( ROUND(_xlfn.STDEV.S(IF((Analysis!$A$2:$A$100=Replicates!$A12) * (Analysis!$D$2:$D$100<>-1), Analysis!$D$2:$D$100, "")), 1) ), " +/- " & ROUND(_xlfn.STDEV.S(IF((Analysis!$A$2:$A$100=Replicates!$A12) * (Analysis!$D$2:$D$100<>-1), Analysis!$D$2:$D$100, "")), 1), "" ) ), "" )} -> 34 +/- 0,5
A27: {=IF(INDEX(Analysis!A:A,MATCH(0,COUNTIF($A$14:A26,Analysis!A:A),0))="","",INDEX(Analysis!A:A,MATCH(0,COUNTIF($A$14:A26,Analysis!A:A),0)))} -> CN | C27: =IF(COUNTIFS(Analysis!$A$2:$A$82,A27,Analysis!$H$2:$H$82,"F")>COUNTIFS(Analysis!$A$2:$A$82,A27,Analysis!$H$2:$H$82,"OK"),"F",IF(COUNTIFS(Analysis!$A$2:$A$82,A27,Analysis!$H$2:$H$82,"OK")>COUNTIFS(Analysis!$A$2:$A$82,A27,Analysis!$H$2:$H$82,"F"),"OK","I")) -> I | D27: {=IFERROR( IF( ROUND(AVERAGEIFS(Analysis!$B$2:$B$100, Analysis!$A$2:$A$100, Replicates!$A13, Analysis!$B$2:$B$100, "<>-1"), 1)="", "", ROUND(AVERAGEIFS(Analysis!$B$2:$B$100, Analysis!$A$2:$A$100, Replicates!$A13, Analysis!$B$2:$B$100, "<>-1"), 1) & IF( ISNUMBER( ROUND(_xlfn.STDEV.S(IF((Analysis!$A$2:$A$100=Replicates!$A13) * (Analysis!$B$2:$B$100<>-1), Analysis!$B$2:$B$100, "")), 1) ), " +/- " & ROUND(_xlfn.STDEV.S(IF((Analysis!$A$2:$A$100=Replicates!$A13) * (Analysis!$B$2:$B$100<>-1), Analysis!$B$2:$B$100, "")), 1), "" ) ), "" )} | E27: {=IFERROR( IF( ROUND(AVERAGEIFS(Analysis!$C$2:$C$100, Analysis!$A$2:$A$100, Replicates!$A13, Analysis!$C$2:$C$100, "<>-1"), 1)="", "", ROUND(AVERAGEIFS(Analysis!$C$2:$C$100, Analysis!$A$2:$A$100, Replicates!$A13, Analysis!$C$2:$C$100, "<>-1"), 1) & IF( ISNUMBER( ROUND(_xlfn.STDEV.S(IF((Analysis!$A$2:$A$100=Replicates!$A13) * (Analysis!$C$2:$C$100<>-1), Analysis!$C$2:$C$100, "")), 1) ), " +/- " & ROUND(_xlfn.STDEV.S(IF((Analysis!$A$2:$A$100=Replicates!$A13) * (Analysis!$C$2:$C$100<>-1), Analysis!$C$2:$C$100, "")), 1), "" ) ), "" )} | F27: {=IFERROR( IF( ROUND(AVERAGEIFS(Analysis!$D$2:$D$100, Analysis!$A$2:$A$100, Replicates!$A13, Analysis!$D$2:$D$100, "<>-1"), 1)="", "", ROUND(AVERAGEIFS(Analysis!$D$2:$D$100, Analysis!$A$2:$A$100, Replicates!$A13, Analysis!$D$2:$D$100, "<>-1"), 1) & IF( ISNUMBER( ROUND(_xlfn.STDEV.S(IF((Analysis!$A$2:$A$100=Replicates!$A13) * (Analysis!$D$2:$D$100<>-1), Analysis!$D$2:$D$100, "")), 1) ), " +/- " & ROUND(_xlfn.STDEV.S(IF((Analysis!$A$2:$A$100=Replicates!$A13) * (Analysis!$D$2:$D$100<>-1), Analysis!$D$2:$D$100, "")), 1), "" ) ), "" )} -> 37,9 +/- 0,1
F28: {=IFERROR( IF( ROUND(AVERAGEIFS(Analysis!$B$2:$B$100, Analysis!$A$2:$A$100, Replicates!$A14, Analysis!$B$2:$B$100, "<>-1"), 1)="", "", ROUND(AVERAGEIFS(Analysis!$B$2:$B$100, Analysis!$A$2:$A$100, Replicates!$A14, Analysis!$B$2:$B$100, "<>-1"), 1) & IF( ISNUMBER( ROUND(_xlfn.STDEV.S(IF((Analysis!$A$2:$A$100=Replicates!$A14) * (Analysis!$B$2:$B$100<>-1), Analysis!$B$2:$B$100, "")), 1) ), " +/- " & ROUND(_xlfn.STDEV.S(IF((Analysis!$A$2:$A$100=Replicates!$A14) * (Analysis!$B$2:$B$100<>-1), Analysis!$B$2:$B$100, "")), 1), "" ) ), "" )} | G28: {=IFERROR( IF( ROUND(AVERAGEIFS(Analysis!$C$2:$C$100, Analysis!$A$2:$A$100, Replicates!$A14, Analysis!$C$2:$C$100, "<>-1"), 1)="", "", ROUND(AVERAGEIFS(Analysis!$C$2:$C$100, Analysis!$A$2:$A$100, Replicates!$A14, Analysis!$C$2:$C$100, "<>-1"), 1) & IF( ISNUMBER( ROUND(_xlfn.STDEV.S(IF((Analysis!$A$2:$A$100=Replicates!$A14) * (Analysis!$C$2:$C$100<>-1), Analysis!$C$2:$C$100, "")), 1) ), " +/- " & ROUND(_xlfn.STDEV.S(IF((Analysis!$A$2:$A$100=Replicates!$A14) * (Analysis!$C$2:$C$100<>-1), Analysis!$C$2:$C$100, "")), 1), "" ) ), "" )}
A29: Abbreviation | B29: Meaning | C29: Action | F29: {=IFERROR(IF(ROUND(AVERAGEIFS(Analysis!$B$2:$B$100, Analysis!$A$2:$A$100, $A30, Analysis!$B$2:$B$100, "<>-1"), 1)="", "", ROUND(AVERAGEIFS(Analysis!$B$2:$B$100, Analysis!$A$2:$A$100, $A30, Analysis!$B$2:$B$100, "<>-1"), 1) & IF(ISNUMBER(ROUND(_xlfn.STDEV.S(IF((Analysis!$A$2:$A$100=$A30) * (Analysis!$B$2:$B$100<>-1), Analysis!$B$2:$B$100, "")), 1)), " +/- " & ROUND(_xlfn.STDEV.S(IF((Analysis!$A$2:$A$100=$A30) * (Analysis!$B$2:$B$100<>-1), Analysis!$B$2:$B$100, "")), 1), "")), "")}
A30: P | B30: positive | C30: treat
A31: N | B31: negative | C31: do not treat
A32: S | B32: suspect | C32: best to treat
A33: R | B33: redo | C33: likely true negative
A34: F | B34: failed | C34: retest
