Workbook

Sheet Batch
A1: T.b. gambiense indirect ELISA
A3: General info
B5: Study | C5: DP/DA
B6: Date | C6: 46092
B7: Operator | C7: HENRIETTE
A9: Buffer preparation date
B11: PBS-blotto | C11: 46071
B12: PBS-blotto-tween | C12: 46091
A14: Lot number of buffers
B16: apDia pH 7.2
B17: iELISA wash (20x) | C17: 251122
B18: TMB solution | C18: 230426
B19: STOP solution | C19: 51124
A21: Lot number of reagents
B23: VSG LiTat 1.3 | C23: L00619
B24: VSG LiTat 1.5 | C24: L00465
B25: IgG HAT +
B26: IgG HAT -
A28: Numéro de la plaque

Sheet Deepwell
A1: T.b. gambiense indirect ELISA
A3: Deepwell plate (code-barres)
B5: 1 | C5: 2 | D5: 3 | E5: 4 | F5: 5 | G5: 6 | H5: 7 | I5: 8 | J5: 9 | K5: 10 | L5: 11 | M5: 12
A6: A | B6: 2502333 | C6: 2500729 | D6: 2502373 | E6: 2502740 | F6: 2500131 | G6: 2500684 | H6: 2500898 | I6: 2501178 | J6: 2501117 | K6: 2502327 | L6: 2501999 | M6: 2502076
A7: B | B7: 2502307 | C7: 2500727 | D7: 2503088 | E7: 2502743 | F7: 2502305 | G7: 2501900 | H7: 2502219 | I7: 2501199 | J7: 2501906 | K7: 2501932 | L7: 2400844 | M7: 2502094
A8: C | B8: 2502334 | C8: 2500728 | D8: 2503083 | E8: 250274 | F8: 2502081 | G8: 2500874 | H8: 2502236 | I8: 2502883 | J8: 2402781 | K8: 2500686 | L8: 2502768 | M8: 2502065
A9: D | B9: 2502335 | C9: 2500720 | D9: 250271 | E9: 2500725 | F9: 2502328 | G9: 2500872 | H9: 2502233 | I9: 2502843 | J9: 2402568 | K9: 2500608 | L9: 2502323 | M9: 2502068
A10: E | B10: 2502352 | C10: 2501117 | D10: 2502744 | E10: 2500730 | F10: 2502313 | G10: 2501018 | H10: 2502235 | I10: 2501141 | J10: 2502317 | K10: 2501973 | L10: 2502067 | M10: 2502095
A11: F | B11: 2502337 | C11: 2501098 | D11: CC | E11: 2500136 | F11: 2501067 | G11: CC | H11: 2502244 | I11: 2502851 | J11: CC | K11: 2501534 | L11: 2502069 | M11: CC
A12: G | B12: 2500731 | C12: 2501111 | D12: CP | E12: 2500127 | F12: 2501068 | G12: CP | H12: 2502214 | I12: 2502850 | J12: CP | K12: 2500700 | L12: 2502074 | M12: CP
A13: H | B13: 2502288 | C13: 2502366 | D13: CN | E13: 2500133 | F13: 2500893 | G13: CN | H13: 2501191 | I13: 2500852 | J13: CN | K13: 2500698 | L13: 2501097 | M13: CN
A15: Deepwell plate (numéro labo Dipumba)
B17: 1 | C17: 2 | D17: 3 | E17: 4 | F17: 5 | G17: 6 | H17: 7 | I17: 8 | J17: 9 | K17: 10 | L17: 11 | M17: 12
A18: A | B18: 967 | C18: 975 | D18: 983 | E18: 988 | F18: 996 | G18: 1004 | H18: 1009 | I18: 1017 | J18: 1025 | K18: 1030 | L18: 1038 | M18: 1046
A19: B | B19: 968 | C19: 976 | D19: 984 | E19: 989 | F19: 997 | G19: 1005 | H19: 1010 | I19: 1018 | J19: 1026 | K19: 1031 | L19: 1039 | M19: 1047
A20: C | B20: 969 | C20: 977 | D20: 985 | E20: 990 | F20: 998 | G20: 1006 | H20: 1011 | I20: 1019 | J20: 1027 | K20: 1032 | L20: 1040 | M20: 1048
A21: D | B21: 970 | C21: 978 | D21: 986 | E21: 991 | F21: 999 | G21: 1007 | H21: 1012 | I21: 1020 | J21: 1028 | K21: 1033 | L21: 1041 | M21: 1049
A22: E | B22: 971 | C22: 979 | D22: 987 | E22: 992 | F22: 1000 | G22: 1008 | H22: 1013 | I22: 1021 | J22: 1029 | K22: 1034 | L22: 1042 | M22: 1050
A23: F | B23: 972 | C23: 980 | D23: CC | E23: 993 | F23: 1001 | G23: CC | H23: 1014 | I23: 1022 | J23: CC | K23: 1035 | L23: 1043 | M23: CC
A24: G | B24: 973 | C24: 981 | D24: CP | E24: 994 | F24: 1002 | G24: CP | H24: 1015 | I24: 1023 | J24: CP | K24: 1036 | L24: 1044 | M24: CP
A25: H | B25: 974 | C25: 982 | D25: CN | E25: 995 | F25: 1003 | G25: CN | H25: 1016 | I25: 1024 | J25: CN | K25: 1037 | L25: 1045 | M25: CN

Sheet ELISA
A1: T.b. gambiense indirect ELISA
A3: ELISA plates
A5: Plate 1 (column 1-3 DEEPWELL): | E5: Plate 2 (column 4-6 DEEPWELL): | I5: Plate 3 (column 7-9 DEEPWELL): | M5: Plate 4 (column 10-12 DEEPWELL):
B6: Sample code | C6: Comments | F6: Sample code | G6: Comments | J6: Sample code | K6: Comments | N6: Sample code | O6: Comments
A7: S01 | B7: =IF(Deepwell!B6="","",Deepwell!B6) -> 2502333 | E7: S22 | F7: =IF(Deepwell!E6="","",Deepwell!E6) -> 2502740 | I7: S43 | J7: =IF(Deepwell!H6="","",Deepwell!H6) -> 2500898 | M7: S64 | N7: =IF(Deepwell!K6="","",Deepwell!K6) -> 2502327
A8: S02 | B8: =IF(Deepwell!B7="","",Deepwell!B7) -> 2502307 | E8: S23 | F8: =IF(Deepwell!E7="","",Deepwell!E7) -> 2502743 | I8: S44 | J8: =IF(Deepwell!H7="","",Deepwell!H7) -> 2502219 | M8: S65 | N8: =IF(Deepwell!K7="","",Deepwell!K7) -> 2501932
A9: S03 | B9: =IF(Deepwell!B8="","",Deepwell!B8) -> 2502334 | E9: S24 | F9: =IF(Deepwell!E8="","",Deepwell!E8) -> 250274 | I9: S45 | J9: =IF(Deepwell!H8="","",Deepwell!H8) -> 2502236 | M9: S66 | N9: =IF(Deepwell!K8="","",Deepwell!K8) -> 2500686
A10: S04 | B10: =IF(Deepwell!B9="","",Deepwell!B9) -> 2502335 | E10: S25 | F10: =IF(Deepwell!E9="","",Deepwell!E9) -> 2500725 | I10: S46 | J10: =IF(Deepwell!H9="","",Deepwell!H9) -> 2502233 | M10: S67 | N10: =IF(Deepwell!K9="","",Deepwell!K9) -> 2500608
A11: S05 | B11: =IF(Deepwell!B10="","",Deepwell!B10) -> 2502352 | E11: S26 | F11: =IF(Deepwell!E10="","",Deepwell!E10) -> 2500730 | I11: S47 | J11: =IF(Deepwell!H10="","",Deepwell!H10) -> 2502235 | M11: S68 | N11: =IF(Deepwell!K10="","",Deepwell!K10) -> 2501973
A12: S06 | B12: =IF(Deepwell!B11="","",Deepwell!B11) -> 2502337 | E12: S27 | F12: =IF(Deepwell!E11="","",Deepwell!E11) -> 2500136 | I12: S48 | J12: =IF(Deepwell!H11="","",Deepwell!H11) -> 2502244 | M12: S69 | N12: =IF(Deepwell!K11="","",Deepwell!K11) -> 2501534
A13: S07 | B13: =IF(Deepwell!B12="","",Deepwell!B12) -> 2500731 | E13: S28 | F13: =IF(Deepwell!E12="","",Deepwell!E12) -> 2500127 | I13: S49 | J13: =IF(Deepwell!H12="","",Deepwell!H12) -> 2502214 | M13: S70 | N13: =IF(Deepwell!K12="","",Deepwell!K12) -> 2500700
A14: S08 | B14: =IF(Deepwell!B13="","",Deepwell!B13) -> 2502288 | E14: S29 | F14: =IF(Deepwell!E13="","",Deepwell!E13) -> 2500133 | I14: S50 | J14: =IF(Deepwell!H13="","",Deepwell!H13) -> 2501191 | M14: S71 | N14: =IF(Deepwell!K13="","",Deepwell!K13) -> 2500698
A15: S09 | B15: =IF(Deepwell!C6="","",Deepwell!C6) -> 2500729 | E15: S30 | F15: =IF(Deepwell!F6="","",Deepwell!F6) -> 2500131 | I15: S51 | J15: =IF(Deepwell!I6="","",Deepwell!I6) -> 2501178 | M15: S72 | N15: =IF(Deepwell!L6="","",Deepwell!L6) -> 2501999
A16: S10 | B16: =IF(Deepwell!C7="","",Deepwell!C7) -> 2500727 | E16: S31 | F16: =IF(Deepwell!F7="","",Deepwell!F7) -> 2502305 | I16: S52 | J16: =IF(Deepwell!I7="","",Deepwell!I7) -> 2501199 | M16: S73 | N16: =IF(Deepwell!L7="","",Deepwell!L7) -> 2400844
A17: S11 | B17: =IF(Deepwell!C8="","",Deepwell!C8) -> 2500728 | E17: S32 | F17: =IF(Deepwell!F8="","",Deepwell!F8) -> 2502081 | I17: S53 | J17: =IF(Deepwell!I8="","",Deepwell!I8) -> 2502883 | M17: S74 | N17: =IF(Deepwell!L8="","",Deepwell!L8) -> 2502768
A18: S12 | B18: =IF(Deepwell!C9="","",Deepwell!C9) -> 2500720 | E18: S33 | F18: =IF(Deepwell!F9="","",Deepwell!F9) -> 2502328 | I18: S54 | J18: =IF(Deepwell!I9="","",Deepwell!I9) -> 2502843 | M18: S75 | N18: =IF(Deepwell!L9="","",Deepwell!L9) -> 2502323
A19: S13 | B19: =IF(Deepwell!C10="","",Deepwell!C10) -> 2501117 | E19: S34 | F19: =IF(Deepwell!F10="","",Deepwell!F10) -> 2502313 | I19: S55 | J19: =IF(Deepwell!I10="","",Deepwell!I10) -> 2501141 | M19: S76 | N19: =IF(Deepwell!L10="","",Deepwell!L10) -> 2502067
A20: S14 | B20: =IF(Deepwell!C11="","",Deepwell!C11) -> 2501098 | E20: S35 | F20: =IF(Deepwell!F11="","",Deepwell!F11) -> 2501067 | I20: S56 | J20: =IF(Deepwell!I11="","",Deepwell!I11) -> 2502851 | M20: S77 | N20: =IF(Deepwell!L11="","",Deepwell!L11) -> 2502069
A21: S15 | B21: =IF(Deepwell!C12="","",Deepwell!C12) -> 2501111 | E21: S36 | F21: =IF(Deepwell!F12="","",Deepwell!F12) -> 2501068 | I21: S57 | J21: =IF(Deepwell!I12="","",Deepwell!I12) -> 2502850 | M21: S78 | N21: =IF(Deepwell!L12="","",Deepwell!L12) -> 2502074
A22: S16 | B22: =IF(Deepwell!C13="","",Deepwell!C13) -> 2502366 | E22: S37 | F22: =IF(Deepwell!F13="","",Deepwell!F13) -> 2500893 | I22: S58 | J22: =IF(Deepwell!I13="","",Deepwell!I13) -> 2500852 | M22: S79 | N22: =IF(Deepwell!L13="","",Deepwell!L13) -> 2501097
A23: S17 | B23: =IF(Deepwell!D6="","",Deepwell!D6) -> 2502373 | E23: S38 | F23: =IF(Deepwell!G6="","",Deepwell!G6) -> 2500684 | I23: S59 | J23: =IF(Deepwell!J6="","",Deepwell!J6) -> 2501117 | M23: S80 | N23: =IF(Deepwell!M6="","",Deepwell!M6) -> 2502076
A24: S18 | B24: =IF(Deepwell!D7="","",Deepwell!D7) -> 2503088 | E24: S39 | F24: =IF(Deepwell!G7="","",Deepwell!G7) -> 2501900 | I24: S60 | J24: =IF(Deepwell!J7="","",Deepwell!J7) -> 2501906 | M24: S81 | N24: =IF(Deepwell!M7="","",Deepwell!M7) -> 2502094
A25: S19 | B25: =IF(Deepwell!D8="","",Deepwell!D8) -> 2503083 | E25: S40 | F25: =IF(Deepwell!G8="","",Deepwell!G8) -> 2500874 | I25: S61 | J25: =IF(Deepwell!J8="","",Deepwell!J8) -> 2402781 | M25: S82 | N25: =IF(Deepwell!M8="","",Deepwell!M8) -> 2502065
A26: S20 | B26: =IF(Deepwell!D9="","",Deepwell!D9) -> 250271 | E26: S41 | F26: =IF(Deepwell!G9="","",Deepwell!G9) -> 2500872 | I26: S62 | J26: =IF(Deepwell!J9="","",Deepwell!J9) -> 2402568 | M26: S83 | N26: =IF(Deepwell!M9="","",Deepwell!M9) -> 2502068
A27: S21 | B27: =IF(Deepwell!D10="","",Deepwell!D10) -> 2502744 | E27: S42 | F27: =IF(Deepwell!G10="","",Deepwell!G10) -> 2501018 | I27: S63 | J27: =IF(Deepwell!J10="","",Deepwell!J10) -> 2502317 | M27: S84 | N27: =IF(Deepwell!M10="","",Deepwell!M10) -> 2502095
A28: CC1 | B28: =IF(Deepwell!D11="","",Deepwell!D11) -> CC | E28: CC2 | F28: =IF(Deepwell!G11="","",Deepwell!G11) -> CC | I28: CC3 | J28: =IF(Deepwell!J11="","",Deepwell!J11) -> CC | M28: CC4 | N28: =IF(Deepwell!M11="","",Deepwell!M11) -> CC
A29: PC1 | B29: =IF(Deepwell!D12="","",Deepwell!D12) -> CP | E29: PC2 | F29: =IF(Deepwell!G12="","",Deepwell!G12) -> CP | I29: PC3 | J29: =IF(Deepwell!J12="","",Deepwell!J12) -> CP | M29: PC4 | N29: =IF(Deepwell!M12="","",Deepwell!M12) -> CP
A30: NC1 | B30: =IF(Deepwell!D13="","",Deepwell!D13) -> CN | E30: NC2 | F30: =IF(Deepwell!G13="","",Deepwell!G13) -> CN | I30: NC3 | J30: =IF(Deepwell!J13="","",Deepwell!J13) -> CN | M30: NC4 | N30: =IF(Deepwell!M13="","",Deepwell!M13) -> CN
A32: CC = conjugate controle
A33: PC = positive controle (IgG HAT+)
A34: NC = negative controle (IgG HAT-)

Sheet 450 nm - 600 nm
A1: T.b. gambiense indirect ELISA
A3: Résultats brutes
A5: Date préparation | C5: =IF(Batch!C6="","",Batch!C6) -> 46092 | E5: Etude | F5: =IF(Batch!C5="","",Batch!C5) -> DP/DA
A6: Opérateur | C6: =IF(Batch!C7="","",Batch!C7) -> HENRIETTE
A7: N° du Lot | C7: =IF(Batch!C18="","",Batch!C18) -> 230426
A8: N° de la plaque | C8: =IF(Batch!C28="","",Batch!C28)
A9: Filtre (nm) | C9: 450-600 nm
A11: Plaque 1:
B13: 1 | C13: 2 | D13: 3 | E13: 4 | F13: 5 | G13: 6 | H13: 7 | I13: 8 | J13: 9 | K13: 10 | L13: 11 | M13: 12
A14: A | B14: 0.131 | C14: 0.096 | D14: 0.092 | E14: 0.117 | F14: 0.082 | G14: 0.091 | H14: 0.145 | I14: 0.081 | J14: 0.093 | K14: 0.117 | L14: 0.068 | M14: 0.097
A15: B | B15: 0.091 | C15: 0.078 | D15: 0.086 | E15: 0.089 | F15: 0.084 | G15: 0.069 | H15: 0.089 | I15: 0.061 | J15: 0.072 | K15: 0.083 | L15: 0.076 | M15: 0.067
A16: C | B16: 0.15 | C16: 0.078 | D16: 0.098 | E16: 0.153 | F16: 0.084 | G16: 0.093 | H16: 0.13 | I16: 0.064 | J16: 0.062 | K16: 0.117 | L16: 0.063 | M16: 0.062
A17: D | B17: 0.109 | C17: 0.16 | D17: 0.099 | E17: 0.104 | F17: 0.133 | G17: 0.092 | H17: 0.075 | I17: 0.07 | J17: 0.074 | K17: 0.101 | L17: 0.088 | M17: 0.076
A18: E | B18: 0.11 | C18: 0.078 | D18: 0.164 | E18: 0.096 | F18: 0.079 | G18: 0.171 | H18: 0.078 | I18: 0.11 | J18: 0.07 | K18: 0.054 | L18: 0.098 | M18: 0.065
A19: F | B19: 0.11 | C19: 0.145 | D19: 0.033 | E19: 0.096 | F19: 0.123 | G19: 0.035 | H19: 0.084 | I19: 0.075 | J19: 0.035 | K19: 0.085 | L19: 0.069 | M19: 0.018
A20: G | B20: 0.084 | C20: 0.094 | D20: 0.515 | E20: 0.09 | F20: 0.072 | G20: 0.704 | H20: 0.085 | I20: 0.049 | J20: 0.035 | K20: 0.088 | L20: 0.05 | M20: 0.026
A21: H | B21: 0.096 | C21: 0.125 | D21: 0.051 | E21: 0.074 | F21: 0.093 | G21: 0.044 | H21: 0.067 | I21: 0.087 | J21: 0.046 | K21: 0.057 | L21: 0.079 | M21: 0.036
A23: Plaque 2:
B25: 1 | C25: 2 | D25: 3 | E25: 4 | F25: 5 | G25: 6 | H25: 7 | I25: 8 | J25: 9 | K25: 10 | L25: 11 | M25: 12
A26: A | B26: 0.098 | C26: 0.077 | D26: 0.117 | E26: 0.089 | F26: 0.069 | G26: 0.113 | H26: 0.087 | I26: 0.081 | J26: 0.1 | K26: 0.079 | L26: 0.062 | M26: 0.086
A27: B | B27: 0.096 | C27: 0.117 | D27: 0.158 | E27: 0.094 | F27: 0.133 | G27: 0.151 | H27: 0.105 | I27: 0.112 | J27: 0.149 | K27: 0.076 | L27: 0.107 | M27: 0.138
A28: C | B28: 0.09 | C28: 0.092 | D28: 0.148 | E28: 0.081 | F28: 0.095 | G28: 0.146 | H28: 0.061 | I28: 0.073 | J28: 0.105 | K28: 0.055 | L28: 0.071 | M28: 0.11
A29: D | B29: 0.24 | C29: 0.083 | D29: 0.117 | E29: 0.218 | F29: 0.097 | G29: 0.116 | H29: 0.069 | I29: 0.12 | J29: 0.075 | K29: 0.084 | L29: 0.095 | M29: 0.118
A30: E | B30: 0.117 | C30: 0.131 | D30: 0.125 | E30: 0.121 | F30: 0.104 | G30: 0.111 | H30: 0.102 | I30: 0.068 | J30: 0.063 | K30: 0.069 | L30: 0.093 | M30: 0.069
A31: F | B31: 0.133 | C31: 0.195 | D31: 0.036 | E31: 0.131 | F31: 0.167 | G31: 0.035 | H31: 0.091 | I31: 0.078 | J31: 0.034 | K31: 0.06 | L31: 0.076 | M31: 0.029
A32: G | B32: 0.132 | C32: 0.087 | D32: 0.505 | E32: 0.126 | F32: 0.072 | G32: 0.601 | H32: 0.063 | I32: 0.054 | J32: 0.035 | K32: 0.051 | L32: 0.051 | M32: 0.035
A33: H | B33: 0.509 | C33: 0.136 | D33: 0.05 | E33: 0.345 | F33: 0.137 | G33: 0.037 | H33: 0.055 | I33: 0.075 | J33: 0.042 | K33: 0.05 | L33: 0.092 | M33: 0.059
A35: Plaque 3:
B37: 1 | C37: 2 | D37: 3 | E37: 4 | F37: 5 | G37: 6 | H37: 7 | I37: 8 | J37: 9 | K37: 10 | L37: 11 | M37: 12
A38: A | B38: 0.165 | C38: 0.094 | D38: 0.145 | E38: 0.157 | F38: 0.081 | G38: 0.143 | H38: 0.17 | I38: 0.081 | J38: 0.085 | K38: 0.159 | L38: 0.078 | M38: 0.103
A39: B | B39: 0.167 | C39: 0.099 | D39: 0.113 | E39: 0.171 | F39: 0.094 | G39: 0.1 | H39: 0.125 | I39: 0.063 | J39: 0.089 | K39: 0.118 | L39: 0.099 | M39: 0.108
A40: C | B40: 0.093 | C40: 0.124 | D40: 0.15 | E40: 0.087 | F40: 0.122 | G40: 0.169 | H40: 0.108 | I40: 0.101 | J40: 0.176 | K40: 0.121 | L40: 0.121 | M40: 0.188
A41: D | B41: 0.109 | C41: 0.128 | D41: 0.201 | E41: 0.113 | F41: 0.13 | G41: 0.213 | H41: 0.141 | I41: 0.066 | J41: 0.091 | K41: 0.149 | L41: 0.088 | M41: 0.102
A42: E | B42: 0.122 | C42: 0.111 | D42: 0.111 | E42: 0.112 | F42: 0.096 | G42: 0.109 | H42: 0.06 | I42: 0.065 | J42: 0.08 | K42: 0.064 | L42: 0.063 | M42: 0.11
A43: F | B43: 0.137 | C43: 0.133 | D43: 0.036 | E43: 0.112 | F43: 0.114 | G43: 0.038 | H43: 0.158 | I43: 0.129 | J43: 0.042 | K43: 0.139 | L43: 0.132 | M43: 0.016
A44: G | B44: 0.128 | C44: 0.145 | D44: 0.968 | E44: 0.135 | F44: 0.125 | G44: 0.958 | H44: 0.078 | I44: 0.056 | J44: 0.034 | K44: 0.102 | L44: 0.072 | M44: 0.035
A45: H | B45: 0.104 | C45: 0.093 | D45: 0.046 | E45: 0.097 | F45: 0.088 | G45: 0.048 | H45: 0.094 | I45: 0.072 | J45: 0.046 | K45: 0.093 | L45: 0.091 | M45: 0.046
A47: Plaque 4:
B49: 1 | C49: 2 | D49: 3 | E49: 4 | F49: 5 | G49: 6 | H49: 7 | I49: 8 | J49: 9 | K49: 10 | L49: 11 | M49: 12
A50: A | B50: 0.105 | C50: 0.194 | D50: 0.134 | E50: 0.095 | F50: 0.181 | G50: 0.127 | H50: 0.097 | I50: 0.138 | J50: 0.107 | K50: 0.1 | L50: 0.129 | M50: 0.089
...

Sheet Results
A1: Deepwell | B1: ELISA | C1: Sample | D1: Numéro labo | E1: Code-barres KPS | F1: D OD | G1: PP % | H1: Result PP60 | I1: Result PP50 | J1: Résultat final | K1: Comments
A2: A1 | B2: 1 | C2: S01 | D2: =IF(Deepwell!B18="","",Deepwell!B18) -> 967 | E2: =IF(ELISA!B7="","",ELISA!B7) -> 2502333 | F2: =IF('450 nm - 600 nm'!B14="","",(('450 nm - 600 nm'!B14+'450 nm - 600 nm'!E14)/2)-(('450 nm - 600 nm'!H14+'450 nm - 600 nm'!K14)/2)) -> -0.007 | G2: =IF(F2="","",(F2-Controls!$E$10)/(Controls!$E$2-Controls!$E$10)) -> -0.023580786 | H2: =IF(G2="","",IF(G2>=60%,"POS","NEG")) -> NEG | I2: =IF(G2="","",IF(G2>=50%,"POS","NEG")) -> NEG | J2: =IF(I2="POS","P",IF(I2="NEG","N","")) -> N | K2: V
A3: B1 | B3: 1 | C3: S02 | D3: =IF(Deepwell!B19="","",Deepwell!B19) -> 968 | E3: =IF(ELISA!B8="","",ELISA!B8) -> 2502307 | F3: =IF('450 nm - 600 nm'!B15="","",(('450 nm - 600 nm'!B15+'450 nm - 600 nm'!E15)/2)-(('450 nm - 600 nm'!H15+'450 nm - 600 nm'!K15)/2)) -> 0.004 | G3: =IF(F3="","",(F3-Controls!$E$10)/(Controls!$E$2-Controls!$E$10)) -> -0.0043668122 | H3: =IF(G3="","",IF(G3>=60%,"POS","NEG")) -> NEG | I3: =IF(G3="","",IF(G3>=50%,"POS","NEG")) -> NEG | J3: =IF(I3="POS","P",IF(I3="NEG","N","")) -> N | K3: V
A4: C1 | B4: 1 | C4: S03 | D4: =IF(Deepwell!B20="","",Deepwell!B20) -> 969 | E4: =IF(ELISA!B9="","",ELISA!B9) -> 2502334 | F4: =IF('450 nm - 600 nm'!B16="","",(('450 nm - 600 nm'!B16+'450 nm - 600 nm'!E16)/2)-(('450 nm - 600 nm'!H16+'450 nm - 600 nm'!K16)/2)) -> 0.028 | G4: =IF(F4="","",(F4-Controls!$E$10)/(Controls!$E$2-Controls!$E$10)) -> 0.037554585 | H4: =IF(G4="","",IF(G4>=60%,"POS","NEG")) -> NEG | I4: =IF(G4="","",IF(G4>=50%,"POS","NEG")) -> NEG | J4: =IF(I4="POS","P",IF(I4="NEG","N","")) -> N | K4: V
A5: D1 | B5: 1 | C5: S04 | D5: =IF(Deepwell!B21="","",Deepwell!B21) -> 970 | E5: =IF(ELISA!B10="","",ELISA!B10) -> 2502335 | F5: =IF('450 nm - 600 nm'!B17="","",(('450 nm - 600 nm'!B17+'450 nm - 600 nm'!E17)/2)-(('450 nm - 600 nm'!H17+'450 nm - 600 nm'!K17)/2)) -> 0.0185 | G5: =IF(F5="","",(F5-Controls!$E$10)/(Controls!$E$2-Controls!$E$10)) -> 0.020960699 | H5: =IF(G5="","",IF(G5>=60%,"POS","NEG")) -> NEG | I5: =IF(G5="","",IF(G5>=50%,"POS","NEG")) -> NEG | J5: =IF(I5="POS","P",IF(I5="NEG","N","")) -> N | K5: V
A6: E1 | B6: 1 | C6: S05 | D6: =IF(Deepwell!B22="","",Deepwell!B22) -> 971 | E6: =IF(ELISA!B11="","",ELISA!B11) -> 2502352 | F6: =IF('450 nm - 600 nm'!B18="","",(('450 nm - 600 nm'!B18+'450 nm - 600 nm'!E18)/2)-(('450 nm - 600 nm'!H18+'450 nm - 600 nm'!K18)/2)) -> 0.037 | G6: =IF(F6="","",(F6-Controls!$E$10)/(Controls!$E$2-Controls!$E$10)) -> 0.053275109 | H6: =IF(G6="","",IF(G6>=60%,"POS","NEG")) -> NEG | I6: =IF(G6="","",IF(G6>=50%,"POS","NEG")) -> NEG | J6: =IF(I6="POS","P",IF(I6="NEG","N","")) -> N | K6: V
A7: F1 | B7: 1 | C7: S06 | D7: =IF(Deepwell!B23="","",Deepwell!B23) -> 972 | E7: =IF(ELISA!B12="","",ELISA!B12) -> 2502337 | F7: =IF('450 nm - 600 nm'!B19="","",(('450 nm - 600 nm'!B19+'450 nm - 600 nm'!E19)/2)-(('450 nm - 600 nm'!H19+'450 nm - 600 nm'!K19)/2)) -> 0.0185 | G7: =IF(F7="","",(F7-Controls!$E$10)/(Controls!$E$2-Controls!$E$10)) -> 0.020960699 | H7: =IF(G7="","",IF(G7>=60%,"POS","NEG")) -> NEG | I7: =IF(G7="","",IF(G7>=50%,"POS","NEG")) -> NEG | J7: =IF(I7="POS","P",IF(I7="NEG","N","")) -> N | K7: V
A8: G1 | B8: 1 | C8: S07 | D8: =IF(Deepwell!B24="","",Deepwell!B24) -> 973 | E8: =IF(ELISA!B13="","",ELISA!B13) -> 2500731 | F8: =IF('450 nm - 600 nm'!B20="","",(('450 nm - 600 nm'!B20+'450 nm - 600 nm'!E20)/2)-(('450 nm - 600 nm'!H20+'450 nm - 600 nm'!K20)/2)) -> 0.0005 | G8: =IF(F8="","",(F8-Controls!$E$10)/(Controls!$E$2-Controls!$E$10)) -> -0.010480349 | H8: =IF(G8="","",IF(G8>=60%,"POS","NEG")) -> NEG | I8: =IF(G8="","",IF(G8>=50%,"POS","NEG")) -> NEG | J8: =IF(I8="POS","P",IF(I8="NEG","N","")) -> N | K8: V
A9: H1 | B9: 1 | C9: S08 | D9: =IF(Deepwell!B25="","",Deepwell!B25) -> 974 | E9: =IF(ELISA!B14="","",ELISA!B14) -> 2502288 | F9: =IF('450 nm - 600 nm'!B21="","",(('450 nm - 600 nm'!B21+'450 nm - 600 nm'!E21)/2)-(('450 nm - 600 nm'!H21+'450 nm - 600 nm'!K21)/2)) -> 0.023 | G9: =IF(F9="","",(F9-Controls!$E$10)/(Controls!$E$2-Controls!$E$10)) -> 0.028820961 | H9: =IF(G9="","",IF(G9>=60%,"POS","NEG")) -> NEG | I9: =IF(G9="","",IF(G9>=50%,"POS","NEG")) -> NEG | J9: =IF(I9="POS","P",IF(I9="NEG","N","")) -> N | K9: V
A10: A2 | B10: 1 | C10: S09 | D10: =IF(Deepwell!C18="","",Deepwell!C18) -> 975 | E10: =IF(ELISA!B15="","",ELISA!B15) -> 2500729 | F10: =IF('450 nm - 600 nm'!C14="","",(('450 nm - 600 nm'!C14+'450 nm - 600 nm'!F14)/2)-(('450 nm - 600 nm'!I14+'450 nm - 600 nm'!L14)/2)) -> 0.0145 | G10: =IF(F10="","",(F10-Controls!$E$10)/(Controls!$E$2-Controls!$E$10)) -> 0.013973799 | H10: =IF(G10="","",IF(G10>=60%,"POS","NEG")) -> NEG | I10: =IF(G10="","",IF(G10>=50%,"POS","NEG")) -> NEG | J10: =IF(I10="POS","P",IF(I10="NEG","N","")) -> N | K10: V
A11: B2 | B11: 1 | C11: S10 | D11: =IF(Deepwell!C19="","",Deepwell!C19) -> 976 | E11: =IF(ELISA!B16="","",ELISA!B16) -> 2500727 | F11: =IF('450 nm - 600 nm'!C15="","",(('450 nm - 600 nm'!C15+'450 nm - 600 nm'!F15)/2)-(('450 nm - 600 nm'!I15+'450 nm - 600 nm'!L15)/2)) -> 0.0125 | G11: =IF(F11="","",(F11-Controls!$E$10)/(Controls!$E$2-Controls!$E$10)) -> 0.010480349 | H11: =IF(G11="","",IF(G11>=60%,"POS","NEG")) -> NEG | I11: =IF(G11="","",IF(G11>=50%,"POS","NEG")) -> NEG | J11: =IF(I11="POS","P",IF(I11="NEG","N","")) -> N | K11: V
A12: C2 | B12: 1 | C12: S11 | D12: =IF(Deepwell!C20="","",Deepwell!C20) -> 977 | E12: =IF(ELISA!B17="","",ELISA!B17) -> 2500728 | F12: =IF('450 nm - 600 nm'!C16="","",(('450 nm - 600 nm'!C16+'450 nm - 600 nm'!F16)/2)-(('450 nm - 600 nm'!I16+'450 nm - 600 nm'!L16)/2)) -> 0.0175 | G12: =IF(F12="","",(F12-Controls!$E$10)/(Controls!$E$2-Controls!$E$10)) -> 0.019213974 | H12: =IF(G12="","",IF(G12>=60%,"POS","NEG")) -> NEG | I12: =IF(G12="","",IF(G12>=50%,"POS","NEG")) -> NEG | J12: =IF(I12="POS","P",IF(I12="NEG","N","")) -> N | K12: V
A13: D2 | B13: 1 | C13: S12 | D13: =IF(Deepwell!C21="","",Deepwell!C21) -> 978 | E13: =IF(ELISA!B18="","",ELISA!B18) -> 2500720 | F13: =IF('450 nm - 600 nm'!C17="","",(('450 nm - 600 nm'!C17+'450 nm - 600 nm'!F17)/2)-(('450 nm - 600 nm'!I17+'450 nm - 600 nm'!L17)/2)) -> 0.0675 | G13: =IF(F13="","",(F13-Controls!$E$10)/(Controls!$E$2-Controls!$E$10)) -> 0.10655022 | H13: =IF(G13="","",IF(G13>=60%,"POS","NEG")) -> NEG | I13: =IF(G13="","",IF(G13>=50%,"POS","NEG")) -> NEG | J13: =IF(I13="POS","P",IF(I13="NEG","N","")) -> N | K13: V
A14: E2 | B14: 1 | C14: S13 | D14: =IF(Deepwell!C22="","",Deepwell!C22) -> 979 | E14: =IF(ELISA!B19="","",ELISA!B19) -> 2501117 | F14: =IF('450 nm - 600 nm'!C18="","",(('450 nm - 600 nm'!C18+'450 nm - 600 nm'!F18)/2)-(('450 nm - 600 nm'!I18+'450 nm - 600 nm'!L18)/2)) -> -0.0255 | G14: =IF(F14="","",(F14-Controls!$E$10)/(Controls!$E$2-Controls!$E$10)) -> -0.055895197 | H14: =IF(G14="","",IF(G14>=60%,"POS","NEG")) -> NEG | I14: =IF(G14="","",IF(G14>=50%,"POS","NEG")) -> NEG | J14: =IF(I14="POS","P",IF(I14="NEG","N","")) -> N | K14: V
A15: F2 | B15: 1 | C15: S14 | D15: =IF(Deepwell!C23="","",Deepwell!C23) -> 980 | E15: =IF(ELISA!B20="","",ELISA!B20) -> 2501098 | F15: =IF('450 nm - 600 nm'!C19="","",(('450 nm - 600 nm'!C19+'450 nm - 600 nm'!F19)/2)-(('450 nm - 600 nm'!I19+'450 nm - 600 nm'!L19)/2)) -> 0.062 | G15: =IF(F15="","",(F15-Controls!$E$10)/(Controls!$E$2-Controls!$E$10)) -> 0.096943231 | H15: =IF(G15="","",IF(G15>=60%,"POS","NEG")) -> NEG | I15: =IF(G15="","",IF(G15>=50%,"POS","NEG")) -> NEG | J15: =IF(I15="POS","P",IF(I15="NEG","N","")) -> N | K15: V
A16: G2 | B16: 1 | C16: S15 | D16: =IF(Deepwell!C24="","",Deepwell!C24) -> 981 | E16: =IF(ELISA!B21="","",ELISA!B21) -> 2501111 | F16: =IF('450 nm - 600 nm'!C20="","",(('450 nm - 600 nm'!C20+'450 nm - 600 nm'!F20)/2)-(('450 nm - 600 nm'!I20+'450 nm - 600 nm'!L20)/2)) -> 0.0335 | G16: =IF(F16="","",(F16-Controls!$E$10)/(Controls!$E$2-Controls!$E$10)) -> 0.047161572 | H16: =IF(G16="","",IF(G16>=60%,"POS","NEG")) -> NEG | I16: =IF(G16="","",IF(G16>=50%,"POS","NEG")) -> NEG | J16: =IF(I16="POS","P",IF(I16="NEG","N","")) -> N | K16: V
A17: H2 | B17: 1 | C17: S16 | D17: =IF(Deepwell!C25="","",Deepwell!C25) -> 982 | E17: =IF(ELISA!B22="","",ELISA!B22) -> 2502366 | F17: =IF('450 nm - 600 nm'!C21="","",(('450 nm - 600 nm'!C21+'450 nm - 600 nm'!F21)/2)-(('450 nm - 600 nm'!I21+'450 nm - 600 nm'!L21)/2)) -> 0.026 | G17: =IF(F17="","",(F17-Controls!$E$10)/(Controls!$E$2-Controls!$E$10)) -> 0.034061135 | H17: =IF(G17="","",IF(G17>=60%,"POS","NEG")) -> NEG | I17: =IF(G17="","",IF(G17>=50%,"POS","NEG")) -> NEG | J17: =IF(I17="POS","P",IF(I17="NEG","N","")) -> N | K17: V
A18: A3 | B18: 1 | C18: S17 | D18: =IF(Deepwell!D18="","",Deepwell!D18) -> 983 | E18: =IF(ELISA!B23="","",ELISA!B23) -> 2502373 | F18: =IF('450 nm - 600 nm'!D14="","",(('450 nm - 600 nm'!D14+'450 nm - 600 nm'!G14)/2)-(('450 nm - 600 nm'!J14+'450 nm - 600 nm'!M14)/2)) -> -0.0035 | G18: =IF(F18="","",(F18-Controls!$E$10)/(Controls!$E$2-Controls!$E$10)) -> -0.017467249 | H18: =IF(G18="","",IF(G18>=60%,"POS","NEG")) -> NEG | I18: =IF(G18="","",IF(G18>=50%,"POS","NEG")) -> NEG | J18: =IF(I18="POS","P",IF(I18="NEG","N","")) -> N | K18: V
A19: B3 | B19: 1 | C19: S18 | D19: =IF(Deepwell!D19="","",Deepwell!D19) -> 984 | E19: =IF(ELISA!B24="","",ELISA!B24) -> 2503088 | F19: =IF('450 nm - 600 nm'!D15="","",(('450 nm - 600 nm'!D15+'450 nm - 600 nm'!G15)/2)-(('450 nm - 600 nm'!J15+'450 nm - 600 nm'!M15)/2)) -> 0.008 | G19: =IF(F19="","",(F19-Controls!$E$10)/(Controls!$E$2-Controls!$E$10)) -> 0.0026200873 | H19: =IF(G19="","",IF(G19>=60%,"POS","NEG")) -> NEG | I19: =IF(G19="","",IF(G19>=50%,"POS","NEG")) -> NEG | J19: =IF(I19="POS","P",IF(I19="NEG","N","")) -> N | K19: V
A20: C3 | B20: 1 | C20: S19 | D20: =IF(Deepwell!D20="","",Deepwell!D20) -> 985 | E20: =IF(ELISA!B25="","",ELISA!B25) -> 2503083 | F20: =IF('450 nm - 600 nm'!D16="","",(('450 nm - 600 nm'!D16+'450 nm - 600 nm'!G16)/2)-(('450 nm - 600 nm'!J16+'450 nm - 600 nm'!M16)/2)) -> 0.0335 | G20: =IF(F20="","",(F20-Controls!$E$10)/(Controls!$E$2-Controls!$E$10)) -> 0.047161572 | H20: =IF(G20="","",IF(G20>=60%,"POS","NEG")) -> NEG | I20: =IF(G20="","",IF(G20>=50%,"POS","NEG")) -> NEG | J20: =IF(I20="POS","P",IF(I20="NEG","N","")) -> N | K20: V
A21: D3 | B21: 1 | C21: S20 | D21: =IF(Deepwell!D21="","",Deepwell!D21) -> 986 | E21: =IF(ELISA!B26="","",ELISA!B26) -> 250271 | F21: =IF('450 nm - 600 nm'!D17="","",(('450 nm - 600 nm'!D17+'450 nm - 600 nm'!G17)/2)-(('450 nm - 600 nm'!J17+'450 nm - 600 nm'!M17)/2)) -> 0.0205 | G21: =IF(F21="","",(F21-Controls!$E$10)/(Controls!$E$2-Controls!$E$10)) -> 0.024454148 | H21: =IF(G21="","",IF(G21>=60%,"POS","NEG")) -> NEG | I21: =IF(G21="","",IF(G21>=50%,"POS","NEG")) -> NEG | J21: =IF(I21="POS","P",IF(I21="NEG","N","")) -> N | K21: V
A22: E3 | B22: 1 | C22: S21 | D22: =IF(Deepwell!D22="","",Deepwell!D22) -> 987 | E22: =IF(ELISA!B27="","",ELISA!B27) -> 2502744 | F22: =IF('450 nm - 600 nm'!D18="","",(('450 nm - 600 nm'!D18+'450 nm - 600 nm'!G18)/2)-(('450 nm - 600 nm'!J18+'450 nm - 600 nm'!M18)/2)) -> 0.1 | G22: =IF(F22="","",(F22-Controls!$E$10)/(Controls!$E$2-Controls!$E$10)) -> 0.16331878 | H22: =IF(G22="","",IF(G22>=60%,"POS","NEG")) -> NEG | I22: =IF(G22="","",IF(G22>=50%,"POS","NEG")) -> NEG | J22: =IF(I22="POS","P",IF(I22="NEG","N","")) -> N | K22: V
A23: A4 | B23: 2 | C23: S22 | D23: =IF(Deepwell!E18="","",Deepwell!E18) -> 988 | E23: =IF(ELISA!F7="","",ELISA!F7) -> 2502740 | F23: =IF('450 nm - 600 nm'!B26="","",(('450 nm - 600 nm'!B26+'450 nm - 600 nm'!E26)/2)-(('450 nm - 600 nm'!H26+'450 nm - 600 nm'!K26)/2)) -> 0.0105 | G23: =IF(F23="","",(F23-Controls!$E$11)/(Controls!$E$3-Controls!$E$11)) -> 0.033333333 | H23: =IF(G23="","",IF(G23>=60%,"POS","NEG")) -> NEG | I23: =IF(G23="","",IF(G23>=50%,"POS","NEG")) -> NEG | J23: =IF(I23="POS","P",IF(I23="NEG","N","")) -> N | K23: V
A24: B4 | B24: 2 | C24: S23 | D24: =IF(Deepwell!E19="","",Deepwell!E19) -> 989 | E24: =IF(ELISA!F8="","",ELISA!F8) -> 2502743 | F24: =IF('450 nm - 600 nm'!B27="","",(('450 nm - 600 nm'!B27+'450 nm - 600 nm'!E27)/2)-(('450 nm - 600 nm'!H27+'450 nm - 600 nm'!K27)/2)) -> 0.0045 | G24: =IF(F24="","",(F24-Controls!$E$11)/(Controls!$E$3-Controls!$E$11)) -> 0.021904762 | H24: =IF(G24="","",IF(G24>=60%,"POS","NEG")) -> NEG | I24: =IF(G24="","",IF(G24>=50%,"POS","NEG")) -> NEG | J24: =IF(I24="POS","P",IF(I24="NEG","N","")) -> N | K24: V
A25: C4 | B25: 2 | C25: S24 | D25: =IF(Deepwell!E20="","",Deepwell!E20) -> 990 | E25: =IF(ELISA!F9="","",ELISA!F9) -> 250274 | F25: =IF('450 nm - 600 nm'!B28="","",(('450 nm - 600 nm'!B28+'450 nm - 600 nm'!E28)/2)-(('450 nm - 600 nm'!H28+'450 nm - 600 nm'!K28)/2)) -> 0.0275 | G25: =IF(F25="","",(F25-Controls!$E$11)/(Controls!$E$3-Controls!$E$11)) -> 0.065714286 | H25: =IF(G25="","",IF(G25>=60%,"POS","NEG")) -> NEG | I25: =IF(G25="","",IF(G25>=50%,"POS","NEG")) -> NEG | J25: =IF(I25="POS","P",IF(I25="NEG","N","")) -> N | K25: V
A26: D4 | B26: 2 | C26: S25 | D26: =IF(Deepwell!E21="","",Deepwell!E21) -> 991 | E26: =IF(ELISA!F10="","",ELISA!F10) -> 2500725 | F26: =IF('450 nm - 600 nm'!B29="","",(('450 nm - 600 nm'!B29+'450 nm - 600 nm'!E29)/2)-(('450 nm - 600 nm'!H29+'450 nm - 600 nm'!K29)/2)) -> 0.1525 | G26: =IF(F26="","",(F26-Controls!$E$11)/(Controls!$E$3-Controls!$E$11)) -> 0.30380952 | H26: =IF(G26="","",IF(G26>=60%,"POS","NEG")) -> NEG | I26: =IF(G26="","",IF(G26>=50%,"POS","NEG")) -> NEG | J26: =IF(I26="POS","P",IF(I26="NEG","N","")) -> N | K26: V
A27: E4 | B27: 2 | C27: S26 | D27: =IF(Deepwell!E22="","",Deepwell!E22) -> 992 | E27: =IF(ELISA!F11="","",ELISA!F11) -> 2500730 | F27: =IF('450 nm - 600 nm'!B30="","",(('450 nm - 600 nm'!B30+'450 nm - 600 nm'!E30)/2)-(('450 nm - 600 nm'!H30+'450 nm - 600 nm'!K30)/2)) -> 0.0335 | G27: =IF(F27="","",(F27-Controls!$E$11)/(Controls!$E$3-Controls!$E$11)) -> 0.077142857 | H27: =IF(G27="","",IF(G27>=60%,"POS","NEG")) -> NEG | I27: =IF(G27="","",IF(G27>=50%,"POS","NEG")) -> NEG | J27: =IF(I27="POS","P",IF(I27="NEG","N","")) -> N | K27: V
A28: F4 | B28: 2 | C28: S27 | D28: =IF(Deepwell!E23="","",Deepwell!E23) -> 993 | E28: =IF(ELISA!F12="","",ELISA!F12) -> 2500136 | F28: =IF('450 nm - 600 nm'!B31="","",(('450 nm - 600 nm'!B31+'450 nm - 600 nm'!E31)/2)-(('450 nm - 600 nm'!H31+'450 nm - 600 nm'!K31)/2)) -> 0.0565 | G28: =IF(F28="","",(F28-Controls!$E$11)/(Controls!$E$3-Controls!$E$11)) -> 0.12095238 | H28: =IF(G28="","",IF(G28>=60%,"POS","NEG")) -> NEG | I28: =IF(G28="","",IF(G28>=50%,"POS","NEG")) -> NEG | J28: =IF(I28="POS","P",IF(I28="NEG","N","")) -> N | K28: V
A29: G4 | B29: 2 | C29: S28 | D29: =IF(Deepwell!E24="","",Deepwell!E24) -> 994 | E29: =IF(ELISA!F13="","",ELISA!F13) -> 2500127 | F29: =IF('450 nm - 600 nm'!B32="","",(('450 nm - 600 nm'!B32+'450 nm - 600 nm'!E32)/2)-(('450 nm - 600 nm'!H32+'450 nm - 600 nm'!K32)/2)) -> 0.072 | G29: =IF(F29="","",(F29-Controls!$E$11)/(Controls!$E$3-Controls!$E$11)) -> 0.15047619 | H29: =IF(G29="","",IF(G29>=60%,"POS","NEG")) -> NEG | I29: =IF(G29="","",IF(G29>=50%,"POS","NEG")) -> NEG | J29: =IF(I29="POS","P",IF(I29="NEG","N","")) -> N | K29: V
A30: H4 | B30: 2 | C30: S29 | D30: =IF(Deepwell!E25="","",Deepwell!E25) -> 995 | E30: =IF(ELISA!F14="","",ELISA!F14) -> 2500133 | F30: =IF('450 nm - 600 nm'!B33="","",(('450 nm - 600 nm'!B33+'450 nm - 600 nm'!E33)/2)-(('450 nm - 600 nm'!H33+'450 nm - 600 nm'!K33)/2)) -> 0.3745 | G30: =IF(F30="","",(F30-Controls!$E$11)/(Controls!$E$3-Controls!$E$11)) -> 0.72666667 | H30: =IF(G30="","",IF(G30>=60%,"POS","NEG")) -> POS | I30: =IF(G30="","",IF(G30>=50%,"POS","NEG")) -> POS | J30: =IF(I30="POS","P",IF(I30="NEG","N","")) -> P | K30: V
A31: A5 | B31: 2 | C31: S30 | D31: =IF(Deepwell!F18="","",Deepwell!F18) -> 996 | E31: =IF(ELISA!F15="","",ELISA!F15) -> 2500131 | F31: =IF('450 nm - 600 nm'!C26="","",(('450 nm - 600 nm'!C26+'450 nm - 600 nm'!F26)/2)-(('450 nm - 600 nm'!I26+'450 nm - 600 nm'!L26)/2)) -> 0.0015 | G31: =IF(F31="","",(F31-Controls!$E$11)/(Controls!$E$3-Controls!$E$11)) -> 0.016190476 | H31: =IF(G31="","",IF(G31>=60%,"POS","NEG")) -> NEG | I31: =IF(G31="","",IF(G31>=50%,"POS","NEG")) -> NEG | J31: =IF(I31="POS","P",IF(I31="NEG","N","")) -> N | K31: V
A32: B5 | B32: 2 | C32: S31 | D32: =IF(Deepwell!F19="","",Deepwell!F19) -> 997 | E32: =IF(ELISA!F16="","",ELISA!F16) -> 2502305 | F32: =IF('450 nm - 600 nm'!C27="","",(('450 nm - 600 nm'!C27+'450 nm - 600 nm'!F27)/2)-(('450 nm - 600 nm'!I27+'450 nm - 600 nm'!L27)/2)) -> 0.0155 | G32: =IF(F32="","",(F32-Controls!$E$11)/(Controls!$E$3-Controls!$E$11)) -> 0.042857143 | H32: =IF(G32="","",IF(G32>=60%,"POS","NEG")) -> NEG | I32: =IF(G32="","",IF(G32>=50%,"POS","NEG")) -> NEG | J32: =IF(I32="POS","P",IF(I32="NEG","N","")) -> N | K32: V
A33: C5 | B33: 2 | C33: S32 | D33: =IF(Deepwell!F20="","",Deepwell!F20) -> 998 | E33: =IF(ELISA!F17="","",ELISA!F17) -> 2502081 | F33: =IF('450 nm - 600 nm'!C28="","",(('450 nm - 600 nm'!C28+'450 nm - 600 nm'!F28)/2)-(('450 nm - 600 nm'!I28+'450 nm - 600 nm'!L28)/2)) -> 0.0215 | G33: =IF(F33="","",(F33-Controls!$E$11)/(Controls!$E$3-Controls!$E$11)) -> 0.054285714 | H33: =IF(G33="","",IF(G33>=60%,"POS","NEG")) -> NEG | I33: =IF(G33="","",IF(G33>=50%,"POS","NEG")) -> NEG | J33: =IF(I33="POS","P",IF(I33="NEG","N","")) -> N | K33: V
A34: D5 | B34: 2 | C34: S33 | D34: =IF(Deepwell!F21="","",Deepwell!F21) -> 999 | E34: =IF(ELISA!F18="","",ELISA!F18) -> 2502328 | F34: =IF('450 nm - 600 nm'!C29="","",(('450 nm - 600 nm'!C29+'450 nm - 600 nm'!F29)/2)-(('450 nm - 600 nm'!I29+'450 nm - 600 nm'!L29)/2)) -> -0.0175 | G34: =IF(F34="","",(F34-Controls!$E$11)/(Controls!$E$3-Controls!$E$11)) -> -0.02 | H34: =IF(G34="","",IF(G34>=60%,"POS","NEG")) -> NEG | I34: =IF(G34="","",IF(G34>=50%,"POS","NEG")) -> NEG | J34: =IF(I34="POS","P",IF(I34="NEG","N","")) -> N | K34: V
A35: E5 | B35: 2 | C35: S34 | D35: =IF(Deepwell!F22="","",Deepwell!F22) -> 1000 | E35: =IF(ELISA!F19="","",ELISA!F19) -> 2502313 | F35: =IF('450 nm - 600 nm'!C30="","",(('450 nm - 600 nm'!C30+'450 nm - 600 nm'!F30)/2)-(('450 nm - 600 nm'!I30+'450 nm - 600 nm'!L30)/2)) -> 0.037 | G35: =IF(F35="","",(F35-Controls!$E$11)/(Controls!$E$3-Controls!$E$11)) -> 0.083809524 | H35: =IF(G35="","",IF(G35>=60%,"POS","NEG")) -> NEG | I35: =IF(G35="","",IF(G35>=50%,"POS","NEG")) -> NEG | J35: =IF(I35="POS","P",IF(I35="NEG","N","")) -> N | K35: V
A36: F5 | B36: 2 | C36: S35 | D36: =IF(Deepwell!F23="","",Deepwell!F23) -> 1001 | E36: =IF(ELISA!F20="","",ELISA!F20) -> 2501067 | F36: =IF('450 nm - 600 nm'!C31="","",(('450 nm - 600 nm'!C31+'450 nm - 600 nm'!F31)/2)-(('450 nm - 600 nm'!I31+'450 nm - 600 nm'!L31)/2)) -> 0.104 | G36: =IF(F36="","",(F36-Controls!$E$11)/(Controls!$E$3-Controls!$E$11)) -> 0.21142857 | H36: =IF(G36="","",IF(G36>=60%,"POS","NEG")) -> NEG | I36: =IF(G36="","",IF(G36>=50%,"POS","NEG")) -> NEG | J36: =IF(I36="POS","P",IF(I36="NEG","N","")) -> N | K36: V
A37: G5 | B37: 2 | C37: S36 | D37: =IF(Deepwell!F24="","",Deepwell!F24) -> 1002 | E37: =IF(ELISA!F21="","",ELISA!F21) -> 2501068 | F37: =IF('450 nm - 600 nm'!C32="","",(('450 nm - 600 nm'!C32+'450 nm - 600 nm'!F32)/2)-(('450 nm - 600 nm'!I32+'450 nm - 600 nm'!L32)/2)) -> 0.027 | G37: =IF(F37="","",(F37-Controls!$E$11)/(Controls!$E$3-Controls!$E$11)) -> 0.064761905 | H37: =IF(G37="","",IF(G37>=60%,"POS","NEG")) -> NEG | I37: =IF(G37="","",IF(G37>=50%,"POS","NEG")) -> NEG | J37: =IF(I37="POS","P",IF(I37="NEG","N","")) -> N | K37: V
A38: H5 | B38: 2 | C38: S37 | D38: =IF(Deepwell!F25="","",Deepwell!F25) -> 1003 | E38: =IF(ELISA!F22="","",ELISA!F22) -> 2500893 | F38: =IF('450 nm - 600 nm'!C33="","",(('450 nm - 600 nm'!C33+'450 nm - 600 nm'!F33)/2)-(('450 nm - 600 nm'!I33+'450 nm - 600 nm'!L33)/2)) -> 0.053 | G38: =IF(F38="","",(F38-Controls!$E$11)/(Controls!$E$3-Controls!$E$11)) -> 0.11428571 | H38: =IF(G38="","",IF(G38>=60%,"POS","NEG")) -> NEG | I38: =IF(G38="","",IF(G38>=50%,"POS","NEG")) -> NEG | J38: =IF(I38="POS","P",IF(I38="NEG","N","")) -> N | K38: V
A39: A6 | B39: 2 | C39: S38 | D39: =IF(Deepwell!G18="","",Deepwell!G18) -> 1004 | E39: =IF(ELISA!F23="","",ELISA!F23) -> 2500684 | F39: =IF('450 nm - 600 nm'!D26="","",(('450 nm - 600 nm'!D26+'450 nm - 600 nm'!G26)/2)-(('450 nm - 600 nm'!J26+'450 nm - 600 nm'!M26)/2)) -> 0.022 | G39: =IF(F39="","",(F39-Controls!$E$11)/(Controls!$E$3-Controls!$E$11)) -> 0.055238095 | H39: =IF(G39="","",IF(G39>=60%,"POS","NEG")) -> NEG | I39: =IF(G39="","",IF(G39>=50%,"POS","NEG")) -> NEG | J39: =IF(I39="POS","P",IF(I39="NEG","N","")) -> N | K39: V
A40: B6 | B40: 2 | C40: S39 | D40: =IF(Deepwell!G19="","",Deepwell!G19) -> 1005 | E40: =IF(ELISA!F24="","",ELISA!F24) -> 2501900 | F40: =IF('450 nm - 600 nm'!D27="","",(('450 nm - 600 nm'!D27+'450 nm - 600 nm'!G27)/2)-(('450 nm - 600 nm'!J27+'450 nm - 600 nm'!M27)/2)) -> 0.011 | G40: =IF(F40="","",(F40-Controls!$E$11)/(Controls!$E$3-Controls!$E$11)) -> 0.034285714 | H40: =IF(G40="","",IF(G40>=60%,"POS","NEG")) -> NEG | I40: =IF(G40="","",IF(G40>=50%,"POS","NEG")) -> NEG | J40: =IF(I40="POS","P",IF(I40="NEG","N","")) -> N | K40: V
...

Sheet Controls
A1: Deepwell | B1: ELISA | C1: Sample | D1: Sample Code | E1: D OD | F1: PP % | G1: Result | H1: Comments
A2: G3 | B2: 1 | C2: PC1 | D2: =IF(ELISA!B29="","",ELISA!B29) -> CP | E2: =IF('450 nm - 600 nm'!D20="","",(('450 nm - 600 nm'!D20+'450 nm - 600 nm'!G20)/2)-(('450 nm - 600 nm'!J20+'450 nm - 600 nm'!M20)/2)) -> 0.579 | F2: =IF(E2="","",(E2-$E$10)/($E$2-$E$10)) -> 1 | G2: =IF(F2="","",IF(F2>=50%,"POS","NEG")) -> POS | H2: =IF(ELISA!C29="","",ELISA!C29)
A3: G6 | B3: 2 | C3: PC2 | D3: =IF(ELISA!F29="","",ELISA!F29) -> CP | E3: =IF('450 nm - 600 nm'!D32="","",(('450 nm - 600 nm'!D32+'450 nm - 600 nm'!G32)/2)-(('450 nm - 600 nm'!J32+'450 nm - 600 nm'!M32)/2)) -> 0.518 | F3: =IF(E3="","",(E3-$E$11)/($E$3-$E$11)) -> 1 | G3: =IF(F3="","",IF(F3>=50%,"POS","NEG")) -> POS | H3: =IF(ELISA!G29="","",ELISA!G29)
A4: G9 | B4: 3 | C4: PC3 | D4: =IF(ELISA!J29="","",ELISA!J29) -> CP | E4: =IF('450 nm - 600 nm'!D44="","",(('450 nm - 600 nm'!D44+'450 nm - 600 nm'!G44)/2)-(('450 nm - 600 nm'!J44+'450 nm - 600 nm'!M44)/2)) -> 0.9285 | F4: =IF(E4="","",(E4-$E$12)/(E$4-$E$12)) -> 1 | G4: =IF(F4="","",IF(F4>=50%,"POS","NEG")) -> POS | H4: =IF(ELISA!K29="","",ELISA!K29)
A5: G12 | B5: 4 | C5: PC4 | D5: =IF(ELISA!N29="","",ELISA!N29) -> CP | E5: =IF('450 nm - 600 nm'!D56="","",(('450 nm - 600 nm'!D56+'450 nm - 600 nm'!G56)/2)-(('450 nm - 600 nm'!J56+'450 nm - 600 nm'!M56)/2)) -> 0.8425 | F5: =IF(E5="","",(E5-$E$13)/(E$5-$E$13)) -> 1 | G5: =IF(F5="","",IF(F5>=50%,"POS","NEG")) -> POS | H5: =IF(ELISA!O29="","",ELISA!O29)
A6: F3 | B6: 1 | C6: CC1 | D6: =IF(ELISA!B28="","",ELISA!B28) -> CC | E6: =IF('450 nm - 600 nm'!D19="","",(('450 nm - 600 nm'!D19+'450 nm - 600 nm'!G19)/2)-(('450 nm - 600 nm'!J19+'450 nm - 600 nm'!M19)/2)) -> 0.0075 | F6: =IF(E6="","",(E6-$E$10)/($E$2-$E$10)) -> 0.0017467249 | G6: =IF(F6="","",IF(F6>=50%,"POS","NEG")) -> NEG | H6: =IF(ELISA!C28="","",ELISA!C28)
A7: F6 | B7: 2 | C7: CC2 | D7: =IF(ELISA!F28="","",ELISA!F28) -> CC | E7: =IF('450 nm - 600 nm'!D31="","",(('450 nm - 600 nm'!D31+'450 nm - 600 nm'!G31)/2)-(('450 nm - 600 nm'!J31+'450 nm - 600 nm'!M31)/2)) -> 0.004 | F7: =IF(E7="","",(E7-$E$11)/($E$3-$E$11)) -> 0.020952381 | G7: =IF(F7="","",IF(F7>=50%,"POS","NEG")) -> NEG | H7: =IF(ELISA!G28="","",ELISA!G28)
A8: F9 | B8: 3 | C8: CC3 | D8: =IF(ELISA!J28="","",ELISA!J28) -> CC | E8: =IF('450 nm - 600 nm'!D43="","",(('450 nm - 600 nm'!D43+'450 nm - 600 nm'!G43)/2)-(('450 nm - 600 nm'!J43+'450 nm - 600 nm'!M43)/2)) -> 0.008 | F8: =IF(E8="","",(E8-$E$12)/(E$4-$E$12)) -> 0.0075471698 | G8: =IF(F8="","",IF(F8>=50%,"POS","NEG")) -> NEG | H8: =IF(ELISA!K28="","",ELISA!K28)
A9: F12 | B9: 4 | C9: CC4 | D9: =IF(ELISA!N28="","",ELISA!N28) -> CC | E9: =IF('450 nm - 600 nm'!D55="","",(('450 nm - 600 nm'!D55+'450 nm - 600 nm'!G55)/2)-(('450 nm - 600 nm'!J55+'450 nm - 600 nm'!M55)/2)) -> 0.0015 | F9: =IF(E9="","",(E9-$E$13)/(E$5-$E$13)) -> -0.0096038415 | G9: =IF(F9="","",IF(F9>=50%,"POS","NEG")) -> NEG | H9: =IF(ELISA!O28="","",ELISA!O28)
A10: H3 | B10: 1 | C10: NC1 | D10: =IF(ELISA!B30="","",ELISA!B30) -> CN | E10: =IF('450 nm - 600 nm'!D21="","",(('450 nm - 600 nm'!D21+'450 nm - 600 nm'!G21)/2)-(('450 nm - 600 nm'!J21+'450 nm - 600 nm'!M21)/2)) -> 0.0065 | F10: =IF(E10="","",(E10-$E$10)/($E$2-$E$10)) -> 0 | G10: =IF(F10="","",IF(F10>=50%,"POS","NEG")) -> NEG | H10: =IF(ELISA!C30="","",ELISA!C30)
A11: H6 | B11: 2 | C11: NC2 | D11: =IF(ELISA!F30="","",ELISA!F30) -> CN | E11: =IF('450 nm - 600 nm'!D33="","",(('450 nm - 600 nm'!D33+'450 nm - 600 nm'!G33)/2)-(('450 nm - 600 nm'!J33+'450 nm - 600 nm'!M33)/2)) -> -0.007 | F11: =IF(E11="","",(E11-$E$11)/($E$3-$E$11)) -> 0 | G11: =IF(F11="","",IF(F11>=50%,"POS","NEG")) -> NEG | H11: =IF(ELISA!G30="","",ELISA!G30)
A12: H9 | B12: 3 | C12: NC3 | D12: =IF(ELISA!J30="","",ELISA!J30) -> CN | E12: =IF('450 nm - 600 nm'!D45="","",(('450 nm - 600 nm'!D45+'450 nm - 600 nm'!G45)/2)-(('450 nm - 600 nm'!J45+'450 nm - 600 nm'!M45)/2)) -> 0.001 | F12: =IF(E12="","",(E12-$E$12)/(E$4-$E$12)) -> 0 | G12: =IF(F12="","",IF(F12>=50%,"POS","NEG")) -> NEG | H12: =IF(ELISA!K30="","",ELISA!K30)
A13: H12 | B13: 4 | C13: NC4 | D13: =IF(ELISA!N30="","",ELISA!N30) -> CN | E13: =IF('450 nm - 600 nm'!D57="","",(('450 nm - 600 nm'!D57+'450 nm - 600 nm'!G57)/2)-(('450 nm - 600 nm'!J57+'450 nm - 600 nm'!M57)/2)) -> 0.0095 | F13: =IF(E13="","",(E13-$E$13)/(E$5-$E$13)) -> 0 | G13: =IF(F13="","",IF(F13>=50%,"POS","NEG")) -> NEG | H13: =IF(ELISA!O30="","",ELISA!O30)

Sheet Repeatability
B2: Allowed deviation (in %): | C2: 30
B4: Sample | C4: Sample Code | D4: Repeatibility 450nm
D5: Ag+
B6: S01 | C6: =IF(ELISA!B7="","",ELISA!B7) -> 2502333 | D6: =IF('450 nm - 600 nm'!B14="","",IF(ABS(1-('450 nm - 600 nm'!B14/'450 nm - 600 nm'!E14))<($C$2/100),"OK","NOK")) -> OK
B7: S02 | C7: =IF(ELISA!B8="","",ELISA!B8) -> 2502307 | D7: =IF('450 nm - 600 nm'!B15="","",IF(ABS(1-('450 nm - 600 nm'!B15/'450 nm - 600 nm'!E15))<($C$2/100),"OK","NOK")) -> OK
B8: S03 | C8: =IF(ELISA!B9="","",ELISA!B9) -> 2502334 | D8: =IF('450 nm - 600 nm'!B16="","",IF(ABS(1-('450 nm - 600 nm'!B16/'450 nm - 600 nm'!E16))<($C$2/100),"OK","NOK")) -> OK
B9: S04 | C9: =IF(ELISA!B10="","",ELISA!B10) -> 2502335 | D9: =IF('450 nm - 600 nm'!B17="","",IF(ABS(1-('450 nm - 600 nm'!B17/'450 nm - 600 nm'!E17))<($C$2/100),"OK","NOK")) -> OK
B10: S05 | C10: =IF(ELISA!B11="","",ELISA!B11) -> 2502352 | D10: =IF('450 nm - 600 nm'!B18="","",IF(ABS(1-('450 nm - 600 nm'!B18/'450 nm - 600 nm'!E18))<($C$2/100),"OK","NOK")) -> OK
B11: S06 | C11: =IF(ELISA!B12="","",ELISA!B12) -> 2502337 | D11: =IF('450 nm - 600 nm'!B19="","",IF(ABS(1-('450 nm - 600 nm'!B19/'450 nm - 600 nm'!E19))<($C$2/100),"OK","NOK")) -> OK
B12: S07 | C12: =IF(ELISA!B13="","",ELISA!B13) -> 2500731 | D12: =IF('450 nm - 600 nm'!B20="","",IF(ABS(1-('450 nm - 600 nm'!B20/'450 nm - 600 nm'!E20))<($C$2/100),"OK","NOK")) -> OK
B13: S08 | C13: =IF(ELISA!B14="","",ELISA!B14) -> 2502288 | D13: =IF('450 nm - 600 nm'!B21="","",IF(ABS(1-('450 nm - 600 nm'!B21/'450 nm - 600 nm'!E21))<($C$2/100),"OK","NOK")) -> OK
B14: S09 | C14: =IF(ELISA!B15="","",ELISA!B15) -> 2500729 | D14: =IF('450 nm - 600 nm'!C14="","",IF(ABS(1-('450 nm - 600 nm'!C14/'450 nm - 600 nm'!F14))<($C$2/100),"OK","NOK")) -> OK
B15: S10 | C15: =IF(ELISA!B16="","",ELISA!B16) -> 2500727 | D15: =IF('450 nm - 600 nm'!C15="","",IF(ABS(1-('450 nm - 600 nm'!C15/'450 nm - 600 nm'!F15))<($C$2/100),"OK","NOK")) -> OK
B16: S11 | C16: =IF(ELISA!B17="","",ELISA!B17) -> 2500728 | D16: =IF('450 nm - 600 nm'!C16="","",IF(ABS(1-('450 nm - 600 nm'!C16/'450 nm - 600 nm'!F16))<($C$2/100),"OK","NOK")) -> OK
B17: S12 | C17: =IF(ELISA!B18="","",ELISA!B18) -> 2500720 | D17: =IF('450 nm - 600 nm'!C17="","",IF(ABS(1-('450 nm - 600 nm'!C17/'450 nm - 600 nm'!F17))<($C$2/100),"OK","NOK")) -> OK
B18: S13 | C18: =IF(ELISA!B19="","",ELISA!B19) -> 2501117 | D18: =IF('450 nm - 600 nm'!C18="","",IF(ABS(1-('450 nm - 600 nm'!C18/'450 nm - 600 nm'!F18))<($C$2/100),"OK","NOK")) -> OK
B19: S14 | C19: =IF(ELISA!B20="","",ELISA!B20) -> 2501098 | D19: =IF('450 nm - 600 nm'!C19="","",IF(ABS(1-('450 nm - 600 nm'!C19/'450 nm - 600 nm'!F19))<($C$2/100),"OK","NOK")) -> OK
B20: S15 | C20: =IF(ELISA!B21="","",ELISA!B21) -> 2501111 | D20: =IF('450 nm - 600 nm'!C20="","",IF(ABS(1-('450 nm - 600 nm'!C20/'450 nm - 600 nm'!F20))<($C$2/100),"OK","NOK")) -> NOK
B21: S16 | C21: =IF(ELISA!B22="","",ELISA!B22) -> 2502366 | D21: =IF('450 nm - 600 nm'!C21="","",IF(ABS(1-('450 nm - 600 nm'!C21/'450 nm - 600 nm'!F21))<($C$2/100),"OK","NOK")) -> NOK
B22: S17 | C22: =IF(ELISA!B23="","",ELISA!B23) -> 2502373 | D22: =IF('450 nm - 600 nm'!D14="","",IF(ABS(1-('450 nm - 600 nm'!D14/'450 nm - 600 nm'!G14))<($C$2/100),"OK","NOK")) -> OK
B23: S18 | C23: =IF(ELISA!B24="","",ELISA!B24) -> 2503088 | D23: =IF('450 nm - 600 nm'!D15="","",IF(ABS(1-('450 nm - 600 nm'!D15/'450 nm - 600 nm'!G15))<($C$2/100),"OK","NOK")) -> OK
B24: S19 | C24: =IF(ELISA!B25="","",ELISA!B25) -> 2503083 | D24: =IF('450 nm - 600 nm'!D16="","",IF(ABS(1-('450 nm - 600 nm'!D16/'450 nm - 600 nm'!G16))<($C$2/100),"OK","NOK")) -> OK
B25: S20 | C25: =IF(ELISA!B26="","",ELISA!B26) -> 250271 | D25: =IF('450 nm - 600 nm'!D17="","",IF(ABS(1-('450 nm - 600 nm'!D17/'450 nm - 600 nm'!G17))<($C$2/100),"OK","NOK")) -> OK
B26: S21 | C26: =IF(ELISA!B27="","",ELISA!B27) -> 2502744 | D26: =IF('450 nm - 600 nm'!D18="","",IF(ABS(1-('450 nm - 600 nm'!D18/'450 nm - 600 nm'!G18))<($C$2/100),"OK","NOK")) -> OK
B27: CP | C27: =IF(ELISA!B29="","",ELISA!B29) -> CP | D27: =IF('450 nm - 600 nm'!D20="","",IF(ABS(1-('450 nm - 600 nm'!D20/'450 nm - 600 nm'!G20))<($C$2/100),"OK","NOK")) -> OK
B28: S22 | C28: =IF(ELISA!F7="","",ELISA!F7) -> 2502740 | D28: =IF('450 nm - 600 nm'!B26="","",IF(ABS(1-('450 nm - 600 nm'!B26/'450 nm - 600 nm'!E26))<($C$2/100),"OK","NOK")) -> OK
B29: S23 | C29: =IF(ELISA!F8="","",ELISA!F8) -> 2502743 | D29: =IF('450 nm - 600 nm'!B27="","",IF(ABS(1-('450 nm - 600 nm'!B27/'450 nm - 600 nm'!E27))<($C$2/100),"OK","NOK")) -> OK
B30: S24 | C30: =IF(ELISA!F9="","",ELISA!F9) -> 250274 | D30: =IF('450 nm - 600 nm'!B28="","",IF(ABS(1-('450 nm - 600 nm'!B28/'450 nm - 600 nm'!E28))<($C$2/100),"OK","NOK")) -> OK
B31: S25 | C31: =IF(ELISA!F10="","",ELISA!F10) -> 2500725 | D31: =IF('450 nm - 600 nm'!B29="","",IF(ABS(1-('450 nm - 600 nm'!B29/'450 nm - 600 nm'!E29))<($C$2/100),"OK","NOK")) -> OK
B32: S26 | C32: =IF(ELISA!F11="","",ELISA!F11) -> 2500730 | D32: =IF('450 nm - 600 nm'!B30="","",IF(ABS(1-('450 nm - 600 nm'!B30/'450 nm - 600 nm'!E30))<($C$2/100),"OK","NOK")) -> OK
B33: S27 | C33: =IF(ELISA!F12="","",ELISA!F12) -> 2500136 | D33: =IF('450 nm - 600 nm'!B31="","",IF(ABS(1-('450 nm - 600 nm'!B31/'450 nm - 600 nm'!E31))<($C$2/100),"OK","NOK")) -> OK
B34: S28 | C34: =IF(ELISA!F13="","",ELISA!F13) -> 2500127 | D34: =IF('450 nm - 600 nm'!B32="","",IF(ABS(1-('450 nm - 600 nm'!B32/'450 nm - 600 nm'!E32))<($C$2/100),"OK","NOK")) -> OK
B35: S29 | C35: =IF(ELISA!F14="","",ELISA!F14) -> 2500133 | D35: =IF('450 nm - 600 nm'!B33="","",IF(ABS(1-('450 nm - 600 nm'!B33/'450 nm - 600 nm'!E33))<($C$2/100),"OK","NOK")) -> NOK
B36: S30 | C36: =IF(ELISA!F15="","",ELISA!F15) -> 2500131 | D36: =IF('450 nm - 600 nm'!C26="","",IF(ABS(1-('450 nm - 600 nm'!C26/'450 nm - 600 nm'!F26))<($C$2/100),"OK","NOK")) -> OK
B37: S31 | C37: =IF(ELISA!F16="","",ELISA!F16) -> 2502305 | D37: =IF('450 nm - 600 nm'!C27="","",IF(ABS(1-('450 nm - 600 nm'!C27/'450 nm - 600 nm'!F27))<($C$2/100),"OK","NOK")) -> OK
B38: S32 | C38: =IF(ELISA!F17="","",ELISA!F17) -> 2502081 | D38: =IF('450 nm - 600 nm'!C28="","",IF(ABS(1-('450 nm - 600 nm'!C28/'450 nm - 600 nm'!F28))<($C$2/100),"OK","NOK")) -> OK
B39: S33 | C39: =IF(ELISA!F18="","",ELISA!F18) -> 2502328 | D39: =IF('450 nm - 600 nm'!C29="","",IF(ABS(1-('450 nm - 600 nm'!C29/'450 nm - 600 nm'!F29))<($C$2/100),"OK","NOK")) -> OK
B40: S34 | C40: =IF(ELISA!F19="","",ELISA!F19) -> 2502313 | D40: =IF('450 nm - 600 nm'!C30="","",IF(ABS(1-('450 nm - 600 nm'!C30/'450 nm - 600 nm'!F30))<($C$2/100),"OK","NOK")) -> OK
B41: S35 | C41: =IF(ELISA!F20="","",ELISA!F20) -> 2501067 | D41: =IF('450 nm - 600 nm'!C31="","",IF(ABS(1-('450 nm - 600 nm'!C31/'450 nm - 600 nm'!F31))<($C$2/100),"OK","NOK")) -> OK
B42: S36 | C42: =IF(ELISA!F21="","",ELISA!F21) -> 2501068 | D42: =IF('450 nm - 600 nm'!C32="","",IF(ABS(1-('450 nm - 600 nm'!C32/'450 nm - 600 nm'!F32))<($C$2/100),"OK","NOK")) -> OK
...
